Workbook
Name DTY紙管: [1]清單!$S$2:$S$100
Name DTY紙管: [2]清單!$S$2:$S$100
Name DTY紙管: [3]清單!$S$2:$S$100
Name DTY紙管: [3]清單!$S$2:$S$100
Name DTY紙管: 清單!$S$2:$S$100
Name FADIS: [4]清單!$AQ$2:$AQ$10
Name FADIS: [2]清單!$AQ$2:$AQ$10
Name FADIS: [3]清單!$AQ$2:$AQ$10
Name FADIS: [3]清單!$AQ$2:$AQ$10
Name FADIS: 清單!$AQ$2:$AQ$10
Name KEY_IN: 清單!$L$2:$L$4
Name Slicer_日期: #N/A
Name 工程師: [4]清單!$V$1:$Z$1
Name 工程師: [2]清單!$V$1:$Z$1
Name 工程師: [3]清單!$V$1:$Z$1
Name 工程師: [3]清單!$V$1:$Z$1
Name 工程師: 清單!$V$1:$Z$1
Name 包裝員: [4]清單!$H$2:$H$35
Name 包裝員: [2]清單!$H$2:$H$35
Name 包裝員: [3]清單!$H$2:$H$35
Name 包裝員: [3]清單!$H$2:$H$35
Name 包裝員: 清單!$H$2:$H$35
Name 包裝項目: [4]清單!$N$2:$N$7
Name 包裝項目: [2]清單!$N$2:$N$7
Name 包裝項目: [3]清單!$N$2:$N$7
Name 包裝項目: [3]清單!$N$2:$N$7
Name 包裝項目: 清單!$N$2:$N$7
Name 外勞處理方式: [4]清單!$AN$2:$AN$7
Name 外勞處理方式: [2]清單!$AN$2:$AN$7
Name 外勞處理方式: [3]清單!$AN$2:$AN$7
Name 外勞處理方式: [3]清單!$AN$2:$AN$7
Name 外勞處理方式: 清單!$AN$2:$AN$7
Name 外觀: [4]清單!$I$2:$I$35
Name 外觀: [2]清單!$I$2:$I$35
Name 外觀: [3]清單!$I$2:$I$35
Name 外觀: [3]清單!$I$2:$I$35
Name 外觀: 清單!$I$2:$I$35
Name 生產項目: [5]清單!$M$2:$M$36
Name 生產項目: [2]清單!$M$2:$M$36
Name 生產項目: [3]清單!$M$2:$M$36
Name 生產項目: [3]清單!$M$2:$M$36
Name 生產項目: 清單!$M$2:$M$36
Name 交代人員: [4]清單!$Q$2:$Q$15
Name 交代人員: [2]清單!$Q$2:$Q$15
Name 交代人員: [3]清單!$Q$2:$Q$15
Name 交代人員: [3]清單!$Q$2:$Q$15
Name 交代人員: 清單!$Q$2:$Q$15
Name 交代項目: [4]清單!$AB$2:$AB$9
Name 交代項目: [2]清單!$AB$2:$AB$9
Name 交代項目: [3]清單!$AB$2:$AB$9
Name 交代項目: [3]清單!$AB$2:$AB$9
Name 交代項目: 清單!$AB$2:$AB$9
Name 交代類別: 清單!$AR$2:$AR$10
Name 其他: 清單!$O$1:$O$14
Name 值車員A: [6]清單!$E$2:$E$27
Name 值車員A: [2]清單!$E$2:$E$45
Name 值車員A: [3]清單!$E$2:$E$45
Name 值車員A: [3]清單!$E$2:$E$45
Name 值車員A: 清單!$E$2:$E$45
Name 值車員J: [6]清單!$F$2:$F$12

Sheet １生產資訊
B1: 早班 08:00~16:00 | G1: 中班 16:00~24:00 | L1: 夜班 24:00~08:00
A2: 日期 | B2: 資料 | C2: 類別 | D2: 項目 | E2: 序 | F2: 說明&時間 | G2: 資料 | H2: 類別 | I2: 項目 | J2: 序 | K2: 說明&時間 | L2: 資料 | M2: 類別 | N2: 項目 | O2: 序 | P2: 說明&時間
A3: ='１１直送'!A3 -> 46174 | B3: 值班主管 | C3: 生產狀況 | D3: 停機 | E3: 1 | F3: F02、S01 sec1-3.7-12、J07、J09、A07、A08、A09、A10、A12、A14、A16、A17、A18、A19、A20、A21、A22、A23、A24、T01L、T02、T06L | G3: 值班主管 | H3: 生產狀況 | I3: 停機 | J3: 1 | K3: F02、S01 sec1-3.7-12、J07、J09、A07、A08、A09、A10、A14、A16、A17、A18、A19、A20、A21、A22、A23、A24、T01、T02、T05L | L3: 值班主管 | M3: 生產狀況 | N3: 停機 | O3: 1 | P3: F02、S01 sec1-3.7-12、J07、J09、A07、A08、A09、A10(清車)、A14、A17、A18、A20、A21、A22、A23、A24、T05L、J08
B4: 賴增倫 | D4: 生產中機台 | E4: 2 | F4: A11、A13、A15、S01 sec4-6、J08、T03、T04L、T05 | G4: 洪春福 | I4: 生產中機台 | J4: 2 | K4: A11、A12、A13、A15、S01 sec4-6、J08、T03、T04、T05R、T06 | L4: 張彥誠 | N4: 改紡停機 | O4: 2 | P4: A19、A16、T01、T02、T04L(了機中)
D5: 改紡停機 | E5: 3 | F5: A12、A16、T04R、T06R、T01R | I5: 改紡停機 | J5: 3 | K5: A12、A16、T04R、T06、T01、T02 | N5: 了機 | O5: 3 | P5: T05R、T04L(3SEC)、S01 sec4-6
B6: 隨保 | D6: 了機 | E6: 4 | F6: T05、J08、T04L(3SEC)、S01 sec4-6 | G6: 隨保 | I6: 了機 | J6: 4 | K6: T05R、J08、T04L(3SEC)、S01 sec4-6 | L6: 隨保 | N6: 清車 | O6: 4 | P6: 改紡檢修
B7: CHELO | D7: 清車 | E7: 5 | F7: NA | G7: CHELO | I7: 清車 | J7: 5 | K7: 改紡檢修 | L7: NA | N7: 明清車 | O7: 5 | P7: A10 停機
D8: 明清車 | E8: 6 | F8: 改紡檢修 | I8: 明清車 | J8: 6 | K8: A10已停機 | N8: 絲開發 | O8: 6 | P8: S02 sec1 2FM3G2 50/72SDFFR，需M紗1.0KG*6顆，請續作業。
D9: 絲開發 | E9: 7.1 | F9: S02 sec1 2FM3G2 50/72SDFFR，需M紗1.0KG*6顆，請中續作業。 | I9: 絲開發 | J9: 7.1 | K9: S02 sec1 2FM3G2 50/72SDFFR，需M紗1.0KG*6顆，請續作業。 | O9: 6.1 | P9: S02 sec2 2FM4S2 75/72PFBR，需M紗1.0KG*36顆，POY吃完，請續作業。
E10: 7.2 | F10: S02 sec3.4 2FM4R3 375/168BKCTR，需M紗5.0KG*96顆，請中續作業。 | J10: 7.2 | K10: S02 sec2 2FM4S2 75/72PFBR，需M紗1.0KG*36顆，POY吃完，請續作業。 | O10: 6.2 | P10: S02 sec3.4 2FM4R3 375/168BKCTR，需M紗5.0KG*96顆，請續作業。
D11: 絲開發 | E11: 7.1 | F11: S02 sec1 2FM3G2 50/72SDFFR，需M紗1.0KG*6顆，請中續作業。 | J11: 7.3 | K11: S02 sec3.4 2FM4R3 375/168BKCTR，需M紗5.0KG*96顆，請續作業。 | O11: 6.3 | P11: S02 sec5 20:00已停，POY，DTY勿動待絲開發。
D12: FADIS | E12: 8.1 | F12: F01: sec1-6 2F42J2-R: sec7-10 2F28C2-R---加開1節生產2F9VH2S生產1.0KG*36顆，預計中班完成。 | J12: 7.4 | K12: S02 sec5 20:00已停，POY，DTY勿動待絲開發。 | N12: FADIS | O12: 7 | P12: F01: sec2-6 2F42J2-R: sec7-10 2F28C2-R---sec1 2F9VH2-S 待明早班改回 2F42J2-R。
B13: B區溫度 | E13: 8.2 | F13: F02：NA | G13: B區溫度 | I13: FADIS | J13: 8.1 | K13: F01: sec1-6 2F42J2-R: sec7-10 2F28C2-R---sec1帶改回2F42I2。 | L13: B區溫度 | O13: 7.1 | P13: F02：NA
B14: 30.2 | E14: 8.3 | F14: F01 29.30.35.36錠 PT CRADLE ARM 已掛紅卡停錠 | G14: 31.4 | J14: 8.2 | K14: F02：NA | L14: 30.5 | O14: 7.2 | P14: F01 29.30.35.36錠 PT CRADLE ARM 已掛紅卡停錠
D15: 其他 | E15: 9.1 | F15: 早班效率差機台(低於80%):J08 | J15: 8.3 | K15: F01 29.30.35.36錠 PT CRADLE ARM 已掛紅卡停錠 | O15: 7.3 | P15: F01 sec1生產2F9VH2S生產1.0KG*36顆紗，中已推出60顆已AK，夜包裝完成。
E16: 9.2 | F16: 早班張力調整機台:NA | J16: 8.4 | K16: F01 sec1生產2F9VH2S生產1.0KG*36顆紗，中已推出60顆已AK，請夜包裝。 | N16: 其他 | O16: 8 | P16: 夜班效率差機台(低於80%):NA
B17: B區濕度 | E17: 9.3 | F17: 斷絲超過4根機台:NA | G17: B區濕度 | I17: 其他 | J17: 9.1 | K17: 中班效率差機台(低於80%):NA | L17: B區濕度 | O17: 8.1 | P17: 夜班張力調整機台:T06
B18: 71.1 | E18: 9.4 | F18: 早班抽檢派紗員紙箱隔板回收作業，作業正常，堆疊未超過2層。10:00 OK | G18: 69.9 | J18: 9.2 | K18: 中班張力調整機台:T04R | L18: 75.8 | O18: 8.2 | P18: 斷絲超過4根機台:NA
E19: 9.5 | F19: 絲八通知 5/31直送22顆FP01433R溫度異常不能使用，已從CS down load該22顆並圍住禁用。 | J19: 9.3 | K19: 斷絲超過4根機台:NA | O19: 8.3 | P19: 夜班抽檢派紗員紙箱隔板回收作業，作業正常，堆疊未超過2層。1:00
D20: 待檢修 | E20: 10 | F20: A21 sec8、11 溫度異常，儀電通知待備品。 | J20: 9.4 | K20: 中班抽檢派紗員紙箱隔板回收作業，作業正常，堆疊未超過2層。20:00 OK | O20: 8.4 | P20: 絲八通知 5/31直送22顆FP01433R溫度異常不能使用，已從CS down load該22顆並圍住禁用。
B21: 出勤人數 | D21: Sample | E21: 11.1 | F21: G1 2F9VG2，50/72BSD3，1.0KG，白黃十字，生產至5/31夜班，需M紗200PCS請續作業，已停機，編染完成暫不包裝，待製程通知。 | G21: 出勤人數 | J21: 9.5 | K21: 絲八通知 5/31直送22顆FP01433R溫度異常不能使用，已從CS down load該22顆並圍住禁用。 | L21: 出勤人數 | N21: 待檢修 | O21: 9 | P21: A21 sec8、11 溫度異常，儀電通知待備品。
E22: 11.2 | F22: T04L sec4-9 2F9VH2，75/72/2PFBR，4.0KG，紫色，FP01432R，120/72PFBR---POY數量不足，續生產不停機，請加強生產定重紗。 | I22: 待檢修 | J22: 10 | K22: A21 sec8、11 溫度異常，儀電通知待備品。 | N22: Sample | O22: 10 | P22: T04L sec4-9 2F9VH2，75/72/2PFBR，4.0KG，紫色，FP01432R，120/72PFBR---POY數量不足，續生產不停機，請加強生產定重紗。
B23: 應到本勞 | D23: 改紡 | E23: 12.1 | F23: A12 改紡2F43R2，75/72/2SDr，5.0KG，白藍三三角，FP81390R，125/72SDR---上紗備管完成，待製程交車。 | G23: 應到本勞 | I23: Sample | J23: 11.1 | K23: G1 2F9VG2，50/72BSD3，1.0KG，白黃十字，生產至5/31夜班，需M紗200PCS請續作業，中已包裝完成。 | L23: 應到本勞 | N23: 首落紗徑 | O23: 11 | P23: A12 2F43R2，75/72/2SDr，5.0KG，白藍三三角，FP81390R，125/72SDR。請值車員擦拭BOWL--首落紗徑:69.8CM 紗重:5028G 已調整W4:-4.48→-4.39 WT:514→515
E24: 12.2 | F24: A16 改紡2F08S2，50/36SDr，4.0KG，白黑角，FP80148R，80/36SDR---備管完成，待通知POY是否可以上紗。 | J24: 11.2 | K24: T04L sec4-9 2F9VH2，75/72/2PFBR，4.0KG，紫色，FP01432R，120/72PFBR---POY數量不足，續生產不停機，請加強生產定重紗。 | O24: 11.1 | P24: T04R 2F7E03(k)，225/72/2SDr，5.5KG，灰色，FP83024R*2，340/72SDR。優先開車--首落紗徑:70.2CM 紗重:5575G 已調整OF3:-1.38→-1.51 WT:03:40→03:38
B25: 4 | E25: 12.3 | F25: T04R 改紡2F7E03(k)，225/72/2SDr，5.5KG，灰色，FP83024R*2，340/72SDR---上紗備管完成，待製程交車。 | G25: 4 | I25: 改紡 | J25: 12.1 | K25: A12 2F43R2，75/72/2SDr，5.0KG，白藍三三角，FP81390R，125/72SDR。請值車員擦拭BOWL--已開車OK，請夜測量紗徑重02:20 | L25: 4 | O25: 11.2 | P25: T06 2F6IM2(K)，150/48/2SDr，5.5KG，黃綠條紋，FP82177R*2，255/48SDR。T06先開，T01後續再開，夜續開車完成，首落紗徑:69.5CM 紗重:5541G 已調整OF3:-0.60→-0.64
E26: 12.4 | F26: T01 改紡2F6IK2(K)，150/48/2SDr，5.5KG，白綠星，FP82177R*2，255/48SDR---備管中，待直送POY，請中續作業。 | J26: 12.2 | K26: A16 2F08S2，50/36SDr，4.0KG，白黑條，FP80148R，80/36SDR。延至6/2開車，協助sec9生頭 --已生頭DTY畫紅線，待上POY與更換紙管。 | N26: 明改紡 | O26: 12 | P26: T02 2F6IL2(K)，150/48/2SDr，5.5KG，黃綠星，FP82175R*2，255/48SDR。夜班備管完成，L邊已上紗，未穿紗，R邊待上紗穿紗。
B27: 實到本勞 | E27: 12.5 | F27: T06 改紡2F6IM2(K)，150/48/2SDr，5.5KG，黃綠條紋，FP82177R*2，255/48SDR---備管中，待直送POY，請中續作業。 | G27: 實到本勞 | J27: 12.3 | K27: T04R 2F7E03(k)，225/72/2SDr，5.5KG，灰色，FP83024R*2，340/72SDR。優先開車--開車OK，請夜測量紗徑重00:00。 | L27: 實到本勞 | O27: 12.3 | P27: A16 2F08S2，50/36SDr，4.0KG，白黑條，FP80148R，80/36SDR。延至6/2開車，協助sec9生頭 --已生頭DTY畫紅線，待上POY與更換紙管。夜班管色更換完成，試驗紗還在跑，待上紗穿紗。
E28: 12.6 | F28: T02 改紡2F6IL2(K)，150/48/2SDr，5.5KG，黃綠星，FP82175R*2，255/48SDR---備管中，待直送POY，請中續作業。 | J28: 12.4 | K28: T01 2F6IK2(K)，150/48/2SDr，5.5KG，白綠星，FP82177R*2，255/48SDR。T06先開，T01後續再開--待上紗備管。 | O28: 12.4 | P28: T01 2F6IK2(K)，150/48/2SDr，5.5KG，白綠星，FP82177R*2，255/48SDR。T06先開，T01後續再開--夜班備管完成待上紗穿紗。
B29: 4 | D29: 了機移紗 | E29: 13.1 | F29: J08 SEC05~18 紙管與POY移SEC1~4續了機，陸續移紗中，請中續作業。 | G29: 4 | J29: 12.5 | K29: T02 2F6IL2(K)，150/48/2SDr，5.5KG，黃綠星，FP82175R*2，255/48SDR。T02優先開，L邊已上紗，未穿紗，R邊待上紗，全台待備管。 | L29: 4 | O29: 12.5 | P29: A19 2F43S2，150/48SDr，5.0kg，藍白十字，FP82179R(255/48SDR)。夜班上紗備管完成，待穿紗。
E30: 13.2 | F30: T05L 紙管已清，陸續移紗T05R，請中續作業。 | J30: 12.6 | K30: T06 2F6IM2(K)，150/48/2SDr，5.5KG，黃綠條紋，FP82177R*2，255/48SDR。T06先開，T01後續再開，中已上紗穿紗OK，開車中，請續作業， | N30: FINAL | O30: 13 | P30: J08夜班已設FINAL，紙管已收，已停機結批，溫度壓力已關，POY已降。
B31: 應到外勞 | G31: 應到外勞 | L31: 應到外勞
B33: 23 | G33: 15 | L33: 11
B35: 實到外勞 | G35: 實到外勞 | L35: 實到外勞
B37: 23 | G37: 15 | L37: 11
B39: 缺勤人員 | G39: 缺勤人員 | L39: 缺勤人員
G41: BERT | L41: NA
G42: DENDEN
A43: =TEXT(A3,"AAAA") -> 星期一 | C43: 其他 | E43: 1 | F43: 廢水沉降槽+汙水處理槽(值班室後面)每班檢查一次，確認有無溢出，有溢出請通知隨保檢修-4:00 | G43: 16-20/OT | H43: 其他 | J43: 1 | K43: 廢水沉降槽+汙水處理槽(值班室後面)每班檢查一次，確認有無溢出，有溢出請通知隨保檢修-18:00 | M43: 其他 | O43: 1 | P43: 廢水沉降槽+汙水處理槽(值班室後面)每班檢查一次，確認有無溢出，有溢出請通知隨保檢修-5:00
E44: 2 | F44: 車道下方棧板區及釘櫃區每兩小時巡檢一次: 2:00 3:00 6:00 | J44: 2 | K44: 車道下方棧板區及釘櫃區每兩小時巡檢一次: 18:00 21:00 23:00 | O44: 2 | P44: 車道下方棧板區及釘櫃區每兩小時巡檢一次: 1:00 3:00 5:00
E45: 3 | F45: 各班記錄3區的溫度: 7:00 A區: 25.5 B區: 29.7 C區: 28.8 冷凍水 設定：0/0/0 | J45: 3 | K45: 各班記錄3區的溫度: 18:00 A區: 26.8 B區: 31.2 C區: 30.3 冷凍水 設定：0/0/0 | O45: 3 | P45: 各班記錄3區的溫度: 6:00 A區: 26.8 B區: 30.5 C區: 30.3 冷凍水 設定：0/0/0
...

Sheet ２斷絲.IAD.效率
A1: 日期 | B1: 機台 | C1: 批號 | D1: 字尾 | E1: 規格 | F1: POY | G1: 車速 | H1: 管色 | I1: 定重 | J1: 早班斷絲 | K1: 早班IAD | L1: 早班效率 | M1: 早班效率 | N1: 中班斷絲 | O1: 中班IAD | P1: 中班效率 | Q1: 中班效率 | R1: 中後斷絲 | S1: 中後IAD | T1: 中後效率 | U1: 中後效率 | V1: 夜班斷絲 | W1: 夜班IAD | X1: 夜班效率 | Y1: 夜班效率 | Z1: 落數 | AA1: 斷絲(班) | AB1: IAD | AC1: 效率平均 | AD1: 斷絲(H) | AE1: 斷絲扣IAD | AF1: 機型 | AG1: MPS節數 | AH1: 早班 值車員 | AI1: 中班 值車員 | AJ1: 中後 值車員 | AK1: 夜班 值車員 | AL1: POY線別(L) | AM1: POY使用日期1 | AN1: POY使用日期2 | AO1: POY使用日期3 | AP1: POY使用日期4 | AQ1: POY使用日期5 | AR1: 其他POY | AS1: 單/雙 | AT1: 台 | AU1: 單根丹尼 | AV1: 實際產量T/日
A2: 46174 | B2: A07 | C2: 停機 | E2: =IF(ISNA(VLOOKUP(C2,條件!$A$1:$G$1021,5,0)),"",(VLOOKUP(C2,條件!$A$1:$G$1021,5,0))) | F2: =IF(ISNA(VLOOKUP(C2,條件!$A$1:$G$1021,6,0)),"",(VLOOKUP(C2,條件!$A$1:$G$1021,6,0))) | G2: =IF(ISNA(VLOOKUP(C2,條件!$A$1:$G$1021,7,0)),"",(VLOOKUP(C2,條件!$A$1:$G$1021,7,0))) | H2: =IF(ISNA(VLOOKUP(C2,條件!$A$1:$K$1021,11,0)),"",(VLOOKUP(C2,條件!$A$1:$K$1021,11,0))) | I2: =IF(ISNA(VLOOKUP(C2,條件!$A$1:$L$1021,12,0)),"",(VLOOKUP(C2,條件!$A$1:$L$1021,12,0))) | L2: 停機 | P2: 停機 | T2: 停機 | X2: 停機 | Z2: =IFERROR(VLOOKUP(C2, 條件!$A:$L, 3, 0), "") | AA2: =IF(OR(L2={"改紡","檢修","了機","清車","FINAL","停機","SAMPLE","TEST","絲開發","待料","跳車"}), L2, IFERROR(IF(C2="", "", (SUM(J2, N2, R2, V2)/3 * AG2) * IF(AND(AF2="S", AS2="雙"), 0.5, 1)), "")) -> 停機 | AB2: =IF(K2="","",IF(ISERROR(1-(SUM(K2,O2,S2,W2)/208/Z2)),"",(1-(SUM(K2,O2,S2,W2)/208/Z2)))) | AC2: =IF(OR(L2={"改紡","檢修","了機","清車","FINAL","停機","SAMPLE","TEST"}), "", IFERROR(IF(C2="", "", AVERAGE(L2:M2, P2:Q2, T2:U2, X2:Y2)/100), "")) | AD2: =IF(ISERROR(AA2/8),"",(AA2/8)) | AE2: =IF(OR(L2="改紡", L2="檢修", L2="了機"), "", IF(AND(C2<>"", J2<>""), IFERROR((SUM(J2, N2, R2, V2) - SUM(K2, O2, S2, W2))/24 * AG2, ""), "") ) | AF2: =LEFT(B2,1) -> A | AG2: 1 | AH2: NA | AI2: NA | AJ2: NA | AK2: NA | AS2: =IF(TEXT(RIGHT(F2,2),) = "×2","雙","單") -> 單 | AT2: =IF(OR(AF2="J", AF2="T", AF2="M"), IF(AG2=1, "全", "半"), IF(AF2="A", IF(AG2=0.5, IF(AS2="雙", "全", ""), IF(AG2=1, IF(AS2="雙", "半", "全"), IF(AG2=2, "半", "") ) ), IF(AF2="S", TEXT(AG2 & "sec", "text"), "") )) -> 全 | AU2: =IF(MID(E2,3,1)="/",LEFT(E2,2),LEFT(E2,3)) | AV2: =IF(ISERROR((IF(AF2="S",AG2*AU2*G2*AC2/18*0.03456/100/1000, AU2*G2*AC2* (IF(OR(AND(AS2="單",AT2="全",OR(AF2="A",AF2="M")),AND(AS2="單",AT2="全",OR(AF2="T",AF2="J"))),1,0)+ IF(OR(AND(AS2="雙",AT2="全",OR(AF2="A",AF2="M")),AND(AS2="雙",AT2="半",OR(AF2="T",AF2="J"))),1,0)+ IF(AND(AS2="雙",AT2="全",OR(AF2="T",AF2="J")),2,0)+ IF(AND(AS2="單",AT2="半",OR(AF2="A",AF2="M")),0.5,0)+ IF(OR(AND(AS2="雙",AT2="半",OR(AF2="A",AF2="M")),AND(AS2="單",AT2="半",OR(AF2="T",AF2="J"))),0.5,0) )*0.03456/100/1000 ))),"",((IF(AF2="S",AG2*AU2*G2*AC2/18*0.03456/100/1000, AU2*G2*AC2* (IF(OR(AND(AS2="單",AT2="全",OR(AF2="A",AF2="M")),AND(AS2="單",AT2="全",OR(AF2="T",AF2="J"))),1,0)+ IF(OR(AND(AS2="雙",AT2="全",OR(AF2="A",AF2="M")),AND(AS2="雙",AT2="半",OR(AF2="T",AF2="J"))),1,0)+ IF(AND(AS2="雙",AT2="全",OR(AF2="T",AF2="J")),2,0)+ IF(AND(AS2="單",AT2="半",OR(AF2="A",AF2="M")),0.5,0)+ IF(OR(AND(AS2="雙",AT2="半",OR(AF2="A",AF2="M")),AND(AS2="單",AT2="半",OR(AF2="T",AF2="J"))),0.5,0) )*0.03456/100/1000 ))))
A3: =A2 -> 46174 | B3: A08 | C3: 停機 | E3: =IF(ISNA(VLOOKUP(C3,條件!$A$1:$G$1021,5,0)),"",(VLOOKUP(C3,條件!$A$1:$G$1021,5,0))) | F3: =IF(ISNA(VLOOKUP(C3,條件!$A$1:$G$1021,6,0)),"",(VLOOKUP(C3,條件!$A$1:$G$1021,6,0))) | G3: =IF(ISNA(VLOOKUP(C3,條件!$A$1:$G$1021,7,0)),"",(VLOOKUP(C3,條件!$A$1:$G$1021,7,0))) | H3: =IF(ISNA(VLOOKUP(C3,條件!$A$1:$K$1021,11,0)),"",(VLOOKUP(C3,條件!$A$1:$K$1021,11,0))) | I3: =IF(ISNA(VLOOKUP(C3,條件!$A$1:$L$1021,12,0)),"",(VLOOKUP(C3,條件!$A$1:$L$1021,12,0))) | L3: 停機 | P3: 停機 | T3: 停機 | X3: 停機 | Z3: =IFERROR(VLOOKUP(C3, 條件!$A:$L, 3, 0), "") | AA3: =IF(OR(L3={"改紡","檢修","了機","清車","FINAL","停機","SAMPLE","TEST","絲開發","待料","跳車"}), L3, IFERROR(IF(C3="", "", (SUM(J3, N3, R3, V3)/3 * AG3) * IF(AND(AF3="S", AS3="雙"), 0.5, 1)), "")) -> 停機 | AB3: =IF(K3="","",IF(ISERROR(1-(SUM(K3,O3,S3,W3)/208/Z3)),"",(1-(SUM(K3,O3,S3,W3)/208/Z3)))) | AC3: =IF(OR(L3={"改紡","檢修","了機","清車","FINAL","停機","SAMPLE","TEST"}), "", IFERROR(IF(C3="", "", AVERAGE(L3:M3, P3:Q3, T3:U3, X3:Y3)/100), "")) | AD3: =IF(ISERROR(AA3/8),"",(AA3/8)) | AE3: =IF(OR(L3="改紡", L3="檢修", L3="了機"), "", IF(AND(C3<>"", J3<>""), IFERROR((SUM(J3, N3, R3, V3) - SUM(K3, O3, S3, W3))/24 * AG3, ""), "") ) | AF3: =LEFT(B3,1) -> A | AG3: 1 | AH3: NA | AI3: NA | AJ3: NA | AK3: NA | AS3: =IF(TEXT(RIGHT(F3,2),) = "×2","雙","單") -> 單 | AT3: =IF(OR(AF3="J", AF3="T", AF3="M"), IF(AG3=1, "全", "半"), IF(AF3="A", IF(AG3=0.5, IF(AS3="雙", "全", ""), IF(AG3=1, IF(AS3="雙", "半", "全"), IF(AG3=2, "半", "") ) ), IF(AF3="S", TEXT(AG3 & "sec", "text"), "") )) -> 全 | AU3: =IF(MID(E3,3,1)="/",LEFT(E3,2),LEFT(E3,3)) | AV3: =IF(ISERROR((IF(AF3="S",AG3*AU3*G3*AC3/18*0.03456/100/1000, AU3*G3*AC3* (IF(OR(AND(AS3="單",AT3="全",OR(AF3="A",AF3="M")),AND(AS3="單",AT3="全",OR(AF3="T",AF3="J"))),1,0)+ IF(OR(AND(AS3="雙",AT3="全",OR(AF3="A",AF3="M")),AND(AS3="雙",AT3="半",OR(AF3="T",AF3="J"))),1,0)+ IF(AND(AS3="雙",AT3="全",OR(AF3="T",AF3="J")),2,0)+ IF(AND(AS3="單",AT3="半",OR(AF3="A",AF3="M")),0.5,0)+ IF(OR(AND(AS3="雙",AT3="半",OR(AF3="A",AF3="M")),AND(AS3="單",AT3="半",OR(AF3="T",AF3="J"))),0.5,0) )*0.03456/100/1000 ))),"",((IF(AF3="S",AG3*AU3*G3*AC3/18*0.03456/100/1000, AU3*G3*AC3* (IF(OR(AND(AS3="單",AT3="全",OR(AF3="A",AF3="M")),AND(AS3="單",AT3="全",OR(AF3="T",AF3="J"))),1,0)+ IF(OR(AND(AS3="雙",AT3="全",OR(AF3="A",AF3="M")),AND(AS3="雙",AT3="半",OR(AF3="T",AF3="J"))),1,0)+ IF(AND(AS3="雙",AT3="全",OR(AF3="T",AF3="J")),2,0)+ IF(AND(AS3="單",AT3="半",OR(AF3="A",AF3="M")),0.5,0)+ IF(OR(AND(AS3="雙",AT3="半",OR(AF3="A",AF3="M")),AND(AS3="單",AT3="半",OR(AF3="T",AF3="J"))),0.5,0) )*0.03456/100/1000 ))))
A4: =A3 -> 46174 | B4: A09 | C4: 停機 | E4: =IF(ISNA(VLOOKUP(C4,條件!$A$1:$G$1021,5,0)),"",(VLOOKUP(C4,條件!$A$1:$G$1021,5,0))) | F4: =IF(ISNA(VLOOKUP(C4,條件!$A$1:$G$1021,6,0)),"",(VLOOKUP(C4,條件!$A$1:$G$1021,6,0))) | G4: =IF(ISNA(VLOOKUP(C4,條件!$A$1:$G$1021,7,0)),"",(VLOOKUP(C4,條件!$A$1:$G$1021,7,0))) | H4: =IF(ISNA(VLOOKUP(C4,條件!$A$1:$K$1021,11,0)),"",(VLOOKUP(C4,條件!$A$1:$K$1021,11,0))) | I4: =IF(ISNA(VLOOKUP(C4,條件!$A$1:$L$1021,12,0)),"",(VLOOKUP(C4,條件!$A$1:$L$1021,12,0))) | L4: 停機 | P4: 停機 | T4: 停機 | X4: 停機 | Z4: =IFERROR(VLOOKUP(C4, 條件!$A:$L, 3, 0), "") | AA4: =IF(OR(L4={"改紡","檢修","了機","清車","FINAL","停機","SAMPLE","TEST","絲開發","待料","跳車"}), L4, IFERROR(IF(C4="", "", (SUM(J4, N4, R4, V4)/3 * AG4) * IF(AND(AF4="S", AS4="雙"), 0.5, 1)), "")) -> 停機 | AB4: =IF(K4="","",IF(ISERROR(1-(SUM(K4,O4,S4,W4)/208/Z4)),"",(1-(SUM(K4,O4,S4,W4)/208/Z4)))) | AC4: =IF(OR(L4={"改紡","檢修","了機","清車","FINAL","停機","SAMPLE","TEST"}), "", IFERROR(IF(C4="", "", AVERAGE(L4:M4, P4:Q4, T4:U4, X4:Y4)/100), "")) | AD4: =IF(ISERROR(AA4/8),"",(AA4/8)) | AE4: =IF(OR(L4="改紡", L4="檢修", L4="了機"), "", IF(AND(C4<>"", J4<>""), IFERROR((SUM(J4, N4, R4, V4) - SUM(K4, O4, S4, W4))/24 * AG4, ""), "") ) | AF4: =LEFT(B4,1) -> A | AG4: 1 | AH4: NA | AI4: NA | AJ4: NA | AK4: NA | AS4: =IF(TEXT(RIGHT(F4,2),) = "×2","雙","單") -> 單 | AT4: =IF(OR(AF4="J", AF4="T", AF4="M"), IF(AG4=1, "全", "半"), IF(AF4="A", IF(AG4=0.5, IF(AS4="雙", "全", ""), IF(AG4=1, IF(AS4="雙", "半", "全"), IF(AG4=2, "半", "") ) ), IF(AF4="S", TEXT(AG4 & "sec", "text"), "") )) -> 全 | AU4: =IF(MID(E4,3,1)="/",LEFT(E4,2),LEFT(E4,3)) | AV4: =IF(ISERROR((IF(AF4="S",AG4*AU4*G4*AC4/18*0.03456/100/1000, AU4*G4*AC4* (IF(OR(AND(AS4="單",AT4="全",OR(AF4="A",AF4="M")),AND(AS4="單",AT4="全",OR(AF4="T",AF4="J"))),1,0)+ IF(OR(AND(AS4="雙",AT4="全",OR(AF4="A",AF4="M")),AND(AS4="雙",AT4="半",OR(AF4="T",AF4="J"))),1,0)+ IF(AND(AS4="雙",AT4="全",OR(AF4="T",AF4="J")),2,0)+ IF(AND(AS4="單",AT4="半",OR(AF4="A",AF4="M")),0.5,0)+ IF(OR(AND(AS4="雙",AT4="半",OR(AF4="A",AF4="M")),AND(AS4="單",AT4="半",OR(AF4="T",AF4="J"))),0.5,0) )*0.03456/100/1000 ))),"",((IF(AF4="S",AG4*AU4*G4*AC4/18*0.03456/100/1000, AU4*G4*AC4* (IF(OR(AND(AS4="單",AT4="全",OR(AF4="A",AF4="M")),AND(AS4="單",AT4="全",OR(AF4="T",AF4="J"))),1,0)+ IF(OR(AND(AS4="雙",AT4="全",OR(AF4="A",AF4="M")),AND(AS4="雙",AT4="半",OR(AF4="T",AF4="J"))),1,0)+ IF(AND(AS4="雙",AT4="全",OR(AF4="T",AF4="J")),2,0)+ IF(AND(AS4="單",AT4="半",OR(AF4="A",AF4="M")),0.5,0)+ IF(OR(AND(AS4="雙",AT4="半",OR(AF4="A",AF4="M")),AND(AS4="單",AT4="半",OR(AF4="T",AF4="J"))),0.5,0) )*0.03456/100/1000 ))))
A5: =A4 -> 46174 | B5: A10 | C5: 停機 | E5: =IF(ISNA(VLOOKUP(C5,條件!$A$1:$G$1021,5,0)),"",(VLOOKUP(C5,條件!$A$1:$G$1021,5,0))) | F5: =IF(ISNA(VLOOKUP(C5,條件!$A$1:$G$1021,6,0)),"",(VLOOKUP(C5,條件!$A$1:$G$1021,6,0))) | G5: =IF(ISNA(VLOOKUP(C5,條件!$A$1:$G$1021,7,0)),"",(VLOOKUP(C5,條件!$A$1:$G$1021,7,0))) | H5: =IF(ISNA(VLOOKUP(C5,條件!$A$1:$K$1021,11,0)),"",(VLOOKUP(C5,條件!$A$1:$K$1021,11,0))) | I5: =IF(ISNA(VLOOKUP(C5,條件!$A$1:$L$1021,12,0)),"",(VLOOKUP(C5,條件!$A$1:$L$1021,12,0))) | L5: 停機 | P5: 停機 | T5: 停機 | X5: 停機 | Z5: =IFERROR(VLOOKUP(C5, 條件!$A:$L, 3, 0), "") | AA5: =IF(OR(L5={"改紡","檢修","了機","清車","FINAL","停機","SAMPLE","TEST","絲開發","待料","跳車"}), L5, IFERROR(IF(C5="", "", (SUM(J5, N5, R5, V5)/3 * AG5) * IF(AND(AF5="S", AS5="雙"), 0.5, 1)), "")) -> 停機 | AB5: =IF(K5="","",IF(ISERROR(1-(SUM(K5,O5,S5,W5)/208/Z5)),"",(1-(SUM(K5,O5,S5,W5)/208/Z5)))) | AC5: =IF(OR(L5={"改紡","檢修","了機","清車","FINAL","停機","SAMPLE","TEST"}), "", IFERROR(IF(C5="", "", AVERAGE(L5:M5, P5:Q5, T5:U5, X5:Y5)/100), "")) | AD5: =IF(ISERROR(AA5/8),"",(AA5/8)) | AE5: =IF(OR(L5="改紡", L5="檢修", L5="了機"), "", IF(AND(C5<>"", J5<>""), IFERROR((SUM(J5, N5, R5, V5) - SUM(K5, O5, S5, W5))/24 * AG5, ""), "") ) | AF5: =LEFT(B5,1) -> A | AG5: 1 | AH5: NA | AI5: NA | AJ5: NA | AK5: NA | AS5: =IF(TEXT(RIGHT(F5,2),) = "×2","雙","單") -> 單 | AT5: =IF(OR(AF5="J", AF5="T", AF5="M"), IF(AG5=1, "全", "半"), IF(AF5="A", IF(AG5=0.5, IF(AS5="雙", "全", ""), IF(AG5=1, IF(AS5="雙", "半", "全"), IF(AG5=2, "半", "") ) ), IF(AF5="S", TEXT(AG5 & "sec", "text"), "") )) -> 全 | AU5: =IF(MID(E5,3,1)="/",LEFT(E5,2),LEFT(E5,3)) | AV5: =IF(ISERROR((IF(AF5="S",AG5*AU5*G5*AC5/18*0.03456/100/1000, AU5*G5*AC5* (IF(OR(AND(AS5="單",AT5="全",OR(AF5="A",AF5="M")),AND(AS5="單",AT5="全",OR(AF5="T",AF5="J"))),1,0)+ IF(OR(AND(AS5="雙",AT5="全",OR(AF5="A",AF5="M")),AND(AS5="雙",AT5="半",OR(AF5="T",AF5="J"))),1,0)+ IF(AND(AS5="雙",AT5="全",OR(AF5="T",AF5="J")),2,0)+ IF(AND(AS5="單",AT5="半",OR(AF5="A",AF5="M")),0.5,0)+ IF(OR(AND(AS5="雙",AT5="半",OR(AF5="A",AF5="M")),AND(AS5="單",AT5="半",OR(AF5="T",AF5="J"))),0.5,0) )*0.03456/100/1000 ))),"",((IF(AF5="S",AG5*AU5*G5*AC5/18*0.03456/100/1000, AU5*G5*AC5* (IF(OR(AND(AS5="單",AT5="全",OR(AF5="A",AF5="M")),AND(AS5="單",AT5="全",OR(AF5="T",AF5="J"))),1,0)+ IF(OR(AND(AS5="雙",AT5="全",OR(AF5="A",AF5="M")),AND(AS5="雙",AT5="半",OR(AF5="T",AF5="J"))),1,0)+ IF(AND(AS5="雙",AT5="全",OR(AF5="T",AF5="J")),2,0)+ IF(AND(AS5="單",AT5="半",OR(AF5="A",AF5="M")),0.5,0)+ IF(OR(AND(AS5="雙",AT5="半",OR(AF5="A",AF5="M")),AND(AS5="單",AT5="半",OR(AF5="T",AF5="J"))),0.5,0) )*0.03456/100/1000 ))))
A6: =A5 -> 46174 | B6: A11 | C6: 2FA062 | E6: =IF(ISNA(VLOOKUP(C6,條件!$A$1:$G$1021,5,0)),"",(VLOOKUP(C6,條件!$A$1:$G$1021,5,0))) -> 75/72SRR5 | F6: =IF(ISNA(VLOOKUP(C6,條件!$A$1:$G$1021,6,0)),"",(VLOOKUP(C6,條件!$A$1:$G$1021,6,0))) -> FP81631R | G6: =IF(ISNA(VLOOKUP(C6,條件!$A$1:$G$1021,7,0)),"",(VLOOKUP(C6,條件!$A$1:$G$1021,7,0))) -> 600 | H6: =IF(ISNA(VLOOKUP(C6,條件!$A$1:$K$1021,11,0)),"",(VLOOKUP(C6,條件!$A$1:$K$1021,11,0))) -> 白藍條 | I6: =IF(ISNA(VLOOKUP(C6,條件!$A$1:$L$1021,12,0)),"",(VLOOKUP(C6,條件!$A$1:$L$1021,12,0))) -> 4 | J6: 21 | K6: 0 | L6: 9320 | M6: 9340 | R6: 34 | S6: 0 | T6: 8744 | U6: 9144 | V6: 37 | W6: 1 | X6: 9379 | Y6: 9244 | Z6: =IFERROR(VLOOKUP(C6, 條件!$A:$L, 3, 0), "") -> 1.7625459 | AA6: =IF(OR(L6={"改紡","檢修","了機","清車","FINAL","停機","SAMPLE","TEST","絲開發","待料","跳車"}), L6, IFERROR(IF(C6="", "", (SUM(J6, N6, R6, V6)/3 * AG6) * IF(AND(AF6="S", AS6="雙"), 0.5, 1)), "")) -> 30.666667 | AB6: =IF(K6="","",IF(ISERROR(1-(SUM(K6,O6,S6,W6)/208/Z6)),"",(1-(SUM(K6,O6,S6,W6)/208/Z6)))) -> 0.9972723 | AC6: =IF(OR(L6={"改紡","檢修","了機","清車","FINAL","停機","SAMPLE","TEST"}), "", IFERROR(IF(C6="", "", AVERAGE(L6:M6, P6:Q6, T6:U6, X6:Y6)/100), "")) -> 91.951667 | AD6: =IF(ISERROR(AA6/8),"",(AA6/8)) -> 3.8333333 | AE6: =IF(OR(L6="改紡", L6="檢修", L6="了機"), "", IF(AND(C6<>"", J6<>""), IFERROR((SUM(J6, N6, R6, V6) - SUM(K6, O6, S6, W6))/24 * AG6, ""), "") ) -> 3.7916667 | AF6: =LEFT(B6,1) -> A | AG6: 1 | AH6: JOHNDEL | AI6: DENNIS | AJ6: DENNIS | AK6: CHALS | AL6: 54 | AM6: 46049 | AN6: 46050 | AO6: 46051 | AP6: 46052 | AQ6: 46053 | AS6: =IF(TEXT(RIGHT(F6,2),) = "×2","雙","單") -> 單 | AT6: =IF(OR(AF6="J", AF6="T", AF6="M"), IF(AG6=1, "全", "半"), IF(AF6="A", IF(AG6=0.5, IF(AS6="雙", "全", ""), IF(AG6=1, IF(AS6="雙", "半", "全"), IF(AG6=2, "半", "") ) ), IF(AF6="S", TEXT(AG6 & "sec", "text"), "") )) -> 全 | AU6: =IF(MID(E6,3,1)="/",LEFT(E6,2),LEFT(E6,3)) -> 75 | AV6: =IF(ISERROR((IF(AF6="S",AG6*AU6*G6*AC6/18*0.03456/100/1000, AU6*G6*AC6* (IF(OR(AND(AS6="單",AT6="全",OR(AF6="A",AF6="M")),AND(AS6="單",AT6="全",OR(AF6="T",AF6="J"))),1,0)+ IF(OR(AND(AS6="雙",AT6="全",OR(AF6="A",AF6="M")),AND(AS6="雙",AT6="半",OR(AF6="T",AF6="J"))),1,0)+ IF(AND(AS6="雙",AT6="全",OR(AF6="T",AF6="J")),2,0)+ IF(AND(AS6="單",AT6="半",OR(AF6="A",AF6="M")),0.5,0)+ IF(OR(AND(AS6="雙",AT6="半",OR(AF6="A",AF6="M")),AND(AS6="單",AT6="半",OR(AF6="T",AF6="J"))),0.5,0) )*0.03456/100/1000 ))),"",((IF(AF6="S",AG6*AU6*G6*AC6/18*0.03456/100/1000, AU6*G6*AC6* (IF(OR(AND(AS6="單",AT6="全",OR(AF6="A",AF6="M")),AND(AS6="單",AT6="全",OR(AF6="T",AF6="J"))),1,0)+ IF(OR(AND(AS6="雙",AT6="全",OR(AF6="A",AF6="M")),AND(AS6="雙",AT6="半",OR(AF6="T",AF6="J"))),1,0)+ IF(AND(AS6="雙",AT6="全",OR(AF6="T",AF6="J")),2,0)+ IF(AND(AS6="單",AT6="半",OR(AF6="A",AF6="M")),0.5,0)+ IF(OR(AND(AS6="雙",AT6="半",OR(AF6="A",AF6="M")),AND(AS6="單",AT6="半",OR(AF6="T",AF6="J"))),0.5,0) )*0.03456/100/1000 )))) -> 1.4300323
A7: =A6 -> 46174 | B7: A12 | C7: 2F43R2 | E7: =IF(ISNA(VLOOKUP(C7,條件!$A$1:$G$1021,5,0)),"",(VLOOKUP(C7,條件!$A$1:$G$1021,5,0))) -> 75/72/2SDr | F7: =IF(ISNA(VLOOKUP(C7,條件!$A$1:$G$1021,6,0)),"",(VLOOKUP(C7,條件!$A$1:$G$1021,6,0))) -> FP81390R×2 | G7: =IF(ISNA(VLOOKUP(C7,條件!$A$1:$G$1021,7,0)),"",(VLOOKUP(C7,條件!$A$1:$G$1021,7,0))) -> 600 | H7: =IF(ISNA(VLOOKUP(C7,條件!$A$1:$K$1021,11,0)),"",(VLOOKUP(C7,條件!$A$1:$K$1021,11,0))) -> 白底藍三角 | I7: =IF(ISNA(VLOOKUP(C7,條件!$A$1:$L$1021,12,0)),"",(VLOOKUP(C7,條件!$A$1:$L$1021,12,0))) -> 5 | L7: 改紡 | P7: 改紡 | R7: 60 | S7: 0 | T7: 6795 | U7: 6557 | V7: 40 | W7: 2 | X7: 9365 | Y7: 9816 | Z7: =IFERROR(VLOOKUP(C7, 條件!$A:$L, 3, 0), "") -> 2.8015564 | AA7: =IF(OR(L7={"改紡","檢修","了機","清車","FINAL","停機","SAMPLE","TEST","絲開發","待料","跳車"}), L7, IFERROR(IF(C7="", "", (SUM(J7, N7, R7, V7)/3 * AG7) * IF(AND(AF7="S", AS7="雙"), 0.5, 1)), "")) -> 改紡 | AB7: =IF(K7="","",IF(ISERROR(1-(SUM(K7,O7,S7,W7)/208/Z7)),"",(1-(SUM(K7,O7,S7,W7)/208/Z7)))) | AC7: =IF(OR(L7={"改紡","檢修","了機","清車","FINAL","停機","SAMPLE","TEST"}), "", IFERROR(IF(C7="", "", AVERAGE(L7:M7, P7:Q7, T7:U7, X7:Y7)/100), "")) | AD7: =IF(ISERROR(AA7/8),"",(AA7/8)) | AE7: =IF(OR(L7="改紡", L7="檢修", L7="了機"), "", IF(AND(C7<>"", J7<>""), IFERROR((SUM(J7, N7, R7, V7) - SUM(K7, O7, S7, W7))/24 * AG7, ""), "") ) | AF7: =LEFT(B7,1) -> A | AG7: 1 | AH7: JOHNDEL | AI7: DENNIS | AJ7: DENNIS | AK7: CHALS | AL7: 53 | AM7: 46118 | AN7: 46119 | AO7: 46120 | AR7: FP81390R | AS7: =IF(TEXT(RIGHT(F7,2),) = "×2","雙","單") -> 雙 | AT7: =IF(OR(AF7="J", AF7="T", AF7="M"), IF(AG7=1, "全", "半"), IF(AF7="A", IF(AG7=0.5, IF(AS7="雙", "全", ""), IF(AG7=1, IF(AS7="雙", "半", "全"), IF(AG7=2, "半", "") ) ), IF(AF7="S", TEXT(AG7 & "sec", "text"), "") )) -> 半 | AU7: =IF(MID(E7,3,1)="/",LEFT(E7,2),LEFT(E7,3)) -> 75 | AV7: =IF(ISERROR((IF(AF7="S",AG7*AU7*G7*AC7/18*0.03456/100/1000, AU7*G7*AC7* (IF(OR(AND(AS7="單",AT7="全",OR(AF7="A",AF7="M")),AND(AS7="單",AT7="全",OR(AF7="T",AF7="J"))),1,0)+ IF(OR(AND(AS7="雙",AT7="全",OR(AF7="A",AF7="M")),AND(AS7="雙",AT7="半",OR(AF7="T",AF7="J"))),1,0)+ IF(AND(AS7="雙",AT7="全",OR(AF7="T",AF7="J")),2,0)+ IF(AND(AS7="單",AT7="半",OR(AF7="A",AF7="M")),0.5,0)+ IF(OR(AND(AS7="雙",AT7="半",OR(AF7="A",AF7="M")),AND(AS7="單",AT7="半",OR(AF7="T",AF7="J"))),0.5,0) )*0.03456/100/1000 ))),"",((IF(AF7="S",AG7*AU7*G7*AC7/18*0.03456/100/1000, AU7*G7*AC7* (IF(OR(AND(AS7="單",AT7="全",OR(AF7="A",AF7="M")),AND(AS7="單",AT7="全",OR(AF7="T",AF7="J"))),1,0)+ IF(OR(AND(AS7="雙",AT7="全",OR(AF7="A",AF7="M")),AND(AS7="雙",AT7="半",OR(AF7="T",AF7="J"))),1,0)+ IF(AND(AS7="雙",AT7="全",OR(AF7="T",AF7="J")),2,0)+ IF(AND(AS7="單",AT7="半",OR(AF7="A",AF7="M")),0.5,0)+ IF(OR(AND(AS7="雙",AT7="半",OR(AF7="A",AF7="M")),AND(AS7="單",AT7="半",OR(AF7="T",AF7="J"))),0.5,0) )*0.03456/100/1000 ))))
A8: =A7 -> 46174 | B8: A13 | C8: 2F08R2 | D8: G | E8: =IF(ISNA(VLOOKUP(C8,條件!$A$1:$G$1021,5,0)),"",(VLOOKUP(C8,條件!$A$1:$G$1021,5,0))) -> 50/72BSD3 | F8: =IF(ISNA(VLOOKUP(C8,條件!$A$1:$G$1021,6,0)),"",(VLOOKUP(C8,條件!$A$1:$G$1021,6,0))) -> FP80141 | G8: =IF(ISNA(VLOOKUP(C8,條件!$A$1:$G$1021,7,0)),"",(VLOOKUP(C8,條件!$A$1:$G$1021,7,0))) -> 630 | H8: =IF(ISNA(VLOOKUP(C8,條件!$A$1:$K$1021,11,0)),"",(VLOOKUP(C8,條件!$A$1:$K$1021,11,0))) -> 洋綠色 | I8: =IF(ISNA(VLOOKUP(C8,條件!$A$1:$L$1021,12,0)),"",(VLOOKUP(C8,條件!$A$1:$L$1021,12,0))) -> 2 | J8: 33 | K8: 0 | L8: 9023 | M8: 9022 | R8: 22 | S8: 0 | T8: 8748 | U8: 9254 | V8: 25 | W8: 0 | X8: 9135 | Y8: 9335 | Z8: =IFERROR(VLOOKUP(C8, 條件!$A:$L, 3, 0), "") -> 2.4615385 | AA8: =IF(OR(L8={"改紡","檢修","了機","清車","FINAL","停機","SAMPLE","TEST","絲開發","待料","跳車"}), L8, IFERROR(IF(C8="", "", (SUM(J8, N8, R8, V8)/3 * AG8) * IF(AND(AF8="S", AS8="雙"), 0.5, 1)), "")) -> 26.666667 | AB8: =IF(K8="","",IF(ISERROR(1-(SUM(K8,O8,S8,W8)/208/Z8)),"",(1-(SUM(K8,O8,S8,W8)/208/Z8)))) -> 1 | AC8: =IF(OR(L8={"改紡","檢修","了機","清車","FINAL","停機","SAMPLE","TEST"}), "", IFERROR(IF(C8="", "", AVERAGE(L8:M8, P8:Q8, T8:U8, X8:Y8)/100), "")) -> 90.861667 | AD8: =IF(ISERROR(AA8/8),"",(AA8/8)) -> 3.3333333 | AE8: =IF(OR(L8="改紡", L8="檢修", L8="了機"), "", IF(AND(C8<>"", J8<>""), IFERROR((SUM(J8, N8, R8, V8) - SUM(K8, O8, S8, W8))/24 * AG8, ""), "") ) -> 3.3333333 | AF8: =LEFT(B8,1) -> A | AG8: 1 | AH8: JOHNDEL | AI8: DENNIS | AJ8: DENNIS | AK8: CHALS | AL8: 57 | AM8: 46093 | AN8: 46094 | AS8: =IF(TEXT(RIGHT(F8,2),) = "×2","雙","單") -> 單 | AT8: =IF(OR(AF8="J", AF8="T", AF8="M"), IF(AG8=1, "全", "半"), IF(AF8="A", IF(AG8=0.5, IF(AS8="雙", "全", ""), IF(AG8=1, IF(AS8="雙", "半", "全"), IF(AG8=2, "半", "") ) ), IF(AF8="S", TEXT(AG8 & "sec", "text"), "") )) -> 全 | AU8: =IF(MID(E8,3,1)="/",LEFT(E8,2),LEFT(E8,3)) -> 50 | AV8: =IF(ISERROR((IF(AF8="S",AG8*AU8*G8*AC8/18*0.03456/100/1000, AU8*G8*AC8* (IF(OR(AND(AS8="單",AT8="全",OR(AF8="A",AF8="M")),AND(AS8="單",AT8="全",OR(AF8="T",AF8="J"))),1,0)+ IF(OR(AND(AS8="雙",AT8="全",OR(AF8="A",AF8="M")),AND(AS8="雙",AT8="半",OR(AF8="T",AF8="J"))),1,0)+ IF(AND(AS8="雙",AT8="全",OR(AF8="T",AF8="J")),2,0)+ IF(AND(AS8="單",AT8="半",OR(AF8="A",AF8="M")),0.5,0)+ IF(OR(AND(AS8="雙",AT8="半",OR(AF8="A",AF8="M")),AND(AS8="單",AT8="半",OR(AF8="T",AF8="J"))),0.5,0) )*0.03456/100/1000 ))),"",((IF(AF8="S",AG8*AU8*G8*AC8/18*0.03456/100/1000, AU8*G8*AC8* (IF(OR(AND(AS8="單",AT8="全",OR(AF8="A",AF8="M")),AND(AS8="單",AT8="全",OR(AF8="T",AF8="J"))),1,0)+ IF(OR(AND(AS8="雙",AT8="全",OR(AF8="A",AF8="M")),AND(AS8="雙",AT8="半",OR(AF8="T",AF8="J"))),1,0)+ IF(AND(AS8="雙",AT8="全",OR(AF8="T",AF8="J")),2,0)+ IF(AND(AS8="單",AT8="半",OR(AF8="A",AF8="M")),0.5,0)+ IF(OR(AND(AS8="雙",AT8="半",OR(AF8="A",AF8="M")),AND(AS8="單",AT8="半",OR(AF8="T",AF8="J"))),0.5,0) )*0.03456/100/1000 )))) -> 0.98915645
A9: =A8 -> 46174 | B9: A14 | C9: 停機 | E9: =IF(ISNA(VLOOKUP(C9,條件!$A$1:$G$1021,5,0)),"",(VLOOKUP(C9,條件!$A$1:$G$1021,5,0))) | F9: =IF(ISNA(VLOOKUP(C9,條件!$A$1:$G$1021,6,0)),"",(VLOOKUP(C9,條件!$A$1:$G$1021,6,0))) | G9: =IF(ISNA(VLOOKUP(C9,條件!$A$1:$G$1021,7,0)),"",(VLOOKUP(C9,條件!$A$1:$G$1021,7,0))) | H9: =IF(ISNA(VLOOKUP(C9,條件!$A$1:$K$1021,11,0)),"",(VLOOKUP(C9,條件!$A$1:$K$1021,11,0))) | I9: =IF(ISNA(VLOOKUP(C9,條件!$A$1:$L$1021,12,0)),"",(VLOOKUP(C9,條件!$A$1:$L$1021,12,0))) | L9: 停機 | P9: 停機 | T9: 停機 | X9: 停機 | Z9: =IFERROR(VLOOKUP(C9, 條件!$A:$L, 3, 0), "") | AA9: =IF(OR(L9={"改紡","檢修","了機","清車","FINAL","停機","SAMPLE","TEST","絲開發","待料","跳車"}), L9, IFERROR(IF(C9="", "", (SUM(J9, N9, R9, V9)/3 * AG9) * IF(AND(AF9="S", AS9="雙"), 0.5, 1)), "")) -> 停機 | AB9: =IF(K9="","",IF(ISERROR(1-(SUM(K9,O9,S9,W9)/208/Z9)),"",(1-(SUM(K9,O9,S9,W9)/208/Z9)))) | AC9: =IF(OR(L9={"改紡","檢修","了機","清車","FINAL","停機","SAMPLE","TEST"}), "", IFERROR(IF(C9="", "", AVERAGE(L9:M9, P9:Q9, T9:U9, X9:Y9)/100), "")) | AD9: =IF(ISERROR(AA9/8),"",(AA9/8)) | AE9: =IF(OR(L9="改紡", L9="檢修", L9="了機"), "", IF(AND(C9<>"", J9<>""), IFERROR((SUM(J9, N9, R9, V9) - SUM(K9, O9, S9, W9))/24 * AG9, ""), "") ) | AF9: =LEFT(B9,1) -> A | AG9: 1 | AH9: NA | AI9: NA | AJ9: NA | AK9: NA | AS9: =IF(TEXT(RIGHT(F9,2),) = "×2","雙","單") -> 單 | AT9: =IF(OR(AF9="J", AF9="T", AF9="M"), IF(AG9=1, "全", "半"), IF(AF9="A", IF(AG9=0.5, IF(AS9="雙", "全", ""), IF(AG9=1, IF(AS9="雙", "半", "全"), IF(AG9=2, "半", "") ) ), IF(AF9="S", TEXT(AG9 & "sec", "text"), "") )) -> 全 | AU9: =IF(MID(E9,3,1)="/",LEFT(E9,2),LEFT(E9,3)) | AV9: =IF(ISERROR((IF(AF9="S",AG9*AU9*G9*AC9/18*0.03456/100/1000, AU9*G9*AC9* (IF(OR(AND(AS9="單",AT9="全",OR(AF9="A",AF9="M")),AND(AS9="單",AT9="全",OR(AF9="T",AF9="J"))),1,0)+ IF(OR(AND(AS9="雙",AT9="全",OR(AF9="A",AF9="M")),AND(AS9="雙",AT9="半",OR(AF9="T",AF9="J"))),1,0)+ IF(AND(AS9="雙",AT9="全",OR(AF9="T",AF9="J")),2,0)+ IF(AND(AS9="單",AT9="半",OR(AF9="A",AF9="M")),0.5,0)+ IF(OR(AND(AS9="雙",AT9="半",OR(AF9="A",AF9="M")),AND(AS9="單",AT9="半",OR(AF9="T",AF9="J"))),0.5,0) )*0.03456/100/1000 ))),"",((IF(AF9="S",AG9*AU9*G9*AC9/18*0.03456/100/1000, AU9*G9*AC9* (IF(OR(AND(AS9="單",AT9="全",OR(AF9="A",AF9="M")),AND(AS9="單",AT9="全",OR(AF9="T",AF9="J"))),1,0)+ IF(OR(AND(AS9="雙",AT9="全",OR(AF9="A",AF9="M")),AND(AS9="雙",AT9="半",OR(AF9="T",AF9="J"))),1,0)+ IF(AND(AS9="雙",AT9="全",OR(AF9="T",AF9="J")),2,0)+ IF(AND(AS9="單",AT9="半",OR(AF9="A",AF9="M")),0.5,0)+ IF(OR(AND(AS9="雙",AT9="半",OR(AF9="A",AF9="M")),AND(AS9="單",AT9="半",OR(AF9="T",AF9="J"))),0.5,0) )*0.03456/100/1000 ))))
A10: =A9 -> 46174 | B10: A15 | C10: 2F43P2 | E10: =IF(ISNA(VLOOKUP(C10,條件!$A$1:$G$1021,5,0)),"",(VLOOKUP(C10,條件!$A$1:$G$1021,5,0))) -> 150/48CDR | F10: =IF(ISNA(VLOOKUP(C10,條件!$A$1:$G$1021,6,0)),"",(VLOOKUP(C10,條件!$A$1:$G$1021,6,0))) -> FP82781 | G10: =IF(ISNA(VLOOKUP(C10,條件!$A$1:$G$1021,7,0)),"",(VLOOKUP(C10,條件!$A$1:$G$1021,7,0))) -> 600 | H10: =IF(ISNA(VLOOKUP(C10,條件!$A$1:$K$1021,11,0)),"",(VLOOKUP(C10,條件!$A$1:$K$1021,11,0))) -> 綠藍雙色 | I10: =IF(ISNA(VLOOKUP(C10,條件!$A$1:$L$1021,12,0)),"",(VLOOKUP(C10,條件!$A$1:$L$1021,12,0))) -> 5 | J10: 11 | K10: 3 | L10: 9210 | M10: 8831 | R10: 8 | S10: 0 | T10: 9265 | U10: 8866 | V10: 17 | W10: 2 | X10: 9261 | Y10: 8916 | Z10: =IFERROR(VLOOKUP(C10, 條件!$A:$L, 3, 0), "") -> 2.8685259 | AA10: =IF(OR(L10={"改紡","檢修","了機","清車","FINAL","停機","SAMPLE","TEST","絲開發","待料","跳車"}), L10, IFERROR(IF(C10="", "", (SUM(J10, N10, R10, V10)/3 * AG10) * IF(AND(AF10="S", AS10="雙"), 0.5, 1)), "")) -> 12 | AB10: =IF(K10="","",IF(ISERROR(1-(SUM(K10,O10,S10,W10)/208/Z10)),"",(1-(SUM(K10,O10,S10,W10)/208/Z10)))) -> 0.99161993 | AC10: =IF(OR(L10={"改紡","檢修","了機","清車","FINAL","停機","SAMPLE","TEST"}), "", IFERROR(IF(C10="", "", AVERAGE(L10:M10, P10:Q10, T10:U10, X10:Y10)/100), "")) -> 90.581667 | AD10: =IF(ISERROR(AA10/8),"",(AA10/8)) -> 1.5 | AE10: =IF(OR(L10="改紡", L10="檢修", L10="了機"), "", IF(AND(C10<>"", J10<>""), IFERROR((SUM(J10, N10, R10, V10) - SUM(K10, O10, S10, W10))/24 * AG10, ""), "") ) -> 1.2916667 | AF10: =LEFT(B10,1) -> A | AG10: 1 | AH10: JOHNDEL | AI10: DENNIS | AJ10: DENNIS | AK10: CHALS | AL10: 54 | AM10: 46160 | AN10: 46161 | AO10: 46162 | AS10: =IF(TEXT(RIGHT(F10,2),) = "×2","雙","單") -> 單 | AT10: =IF(OR(AF10="J", AF10="T", AF10="M"), IF(AG10=1, "全", "半"), IF(AF10="A", IF(AG10=0.5, IF(AS10="雙", "全", ""), IF(AG10=1, IF(AS10="雙", "半", "全"), IF(AG10=2, "半", "") ) ), IF(AF10="S", TEXT(AG10 & "sec", "text"), "") )) -> 全 | AU10: =IF(MID(E10,3,1)="/",LEFT(E10,2),LEFT(E10,3)) -> 150 | AV10: =IF(ISERROR((IF(AF10="S",AG10*AU10*G10*AC10/18*0.03456/100/1000, AU10*G10*AC10* (IF(OR(AND(AS10="單",AT10="全",OR(AF10="A",AF10="M")),AND(AS10="單",AT10="全",OR(AF10="T",AF10="J"))),1,0)+ IF(OR(AND(AS10="雙",AT10="全",OR(AF10="A",AF10="M")),AND(AS10="雙",AT10="半",OR(AF10="T",AF10="J"))),1,0)+ IF(AND(AS10="雙",AT10="全",OR(AF10="T",AF10="J")),2,0)+ IF(AND(AS10="單",AT10="半",OR(AF10="A",AF10="M")),0.5,0)+ IF(OR(AND(AS10="雙",AT10="半",OR(AF10="A",AF10="M")),AND(AS10="單",AT10="半",OR(AF10="T",AF10="J"))),0.5,0) )*0.03456/100/1000 ))),"",((IF(AF10="S",AG10*AU10*G10*AC10/18*0.03456/100/1000, AU10*G10*AC10* (IF(OR(AND(AS10="單",AT10="全",OR(AF10="A",AF10="M")),AND(AS10="單",AT10="全",OR(AF10="T",AF10="J"))),1,0)+ IF(OR(AND(AS10="雙",AT10="全",OR(AF10="A",AF10="M")),AND(AS10="雙",AT10="半",OR(AF10="T",AF10="J"))),1,0)+ IF(AND(AS10="雙",AT10="全",OR(AF10="T",AF10="J")),2,0)+ IF(AND(AS10="單",AT10="半",OR(AF10="A",AF10="M")),0.5,0)+ IF(OR(AND(AS10="雙",AT10="半",OR(AF10="A",AF10="M")),AND(AS10="單",AT10="半",OR(AF10="T",AF10="J"))),0.5,0) )*0.03456/100/1000 )))) -> 2.8174522
A11: =A10 -> 46174 | B11: A16 | C11: 停機 | E11: =IF(ISNA(VLOOKUP(C11,條件!$A$1:$G$1021,5,0)),"",(VLOOKUP(C11,條件!$A$1:$G$1021,5,0))) | F11: =IF(ISNA(VLOOKUP(C11,條件!$A$1:$G$1021,6,0)),"",(VLOOKUP(C11,條件!$A$1:$G$1021,6,0))) | G11: =IF(ISNA(VLOOKUP(C11,條件!$A$1:$G$1021,7,0)),"",(VLOOKUP(C11,條件!$A$1:$G$1021,7,0))) | H11: =IF(ISNA(VLOOKUP(C11,條件!$A$1:$K$1021,11,0)),"",(VLOOKUP(C11,條件!$A$1:$K$1021,11,0))) | I11: =IF(ISNA(VLOOKUP(C11,條件!$A$1:$L$1021,12,0)),"",(VLOOKUP(C11,條件!$A$1:$L$1021,12,0))) | L11: 停機 | P11: 停機 | T11: 停機 | X11: 停機 | Z11: =IFERROR(VLOOKUP(C11, 條件!$A:$L, 3, 0), "") | AA11: =IF(OR(L11={"改紡","檢修","了機","清車","FINAL","停機","SAMPLE","TEST","絲開發","待料","跳車"}), L11, IFERROR(IF(C11="", "", (SUM(J11, N11, R11, V11)/3 * AG11) * IF(AND(AF11="S", AS11="雙"), 0.5, 1)), "")) -> 停機 | AB11: =IF(K11="","",IF(ISERROR(1-(SUM(K11,O11,S11,W11)/208/Z11)),"",(1-(SUM(K11,O11,S11,W11)/208/Z11)))) | AC11: =IF(OR(L11={"改紡","檢修","了機","清車","FINAL","停機","SAMPLE","TEST"}), "", IFERROR(IF(C11="", "", AVERAGE(L11:M11, P11:Q11, T11:U11, X11:Y11)/100), "")) | AD11: =IF(ISERROR(AA11/8),"",(AA11/8)) | AE11: =IF(OR(L11="改紡", L11="檢修", L11="了機"), "", IF(AND(C11<>"", J11<>""), IFERROR((SUM(J11, N11, R11, V11) - SUM(K11, O11, S11, W11))/24 * AG11, ""), "") ) | AF11: =LEFT(B11,1) -> A | AG11: 1 | AH11: JOHNDEL | AI11: DENNIS | AJ11: DENNIS | AK11: NA | AL11: 57 | AM11: 46173 | AN11: 46174 | AS11: =IF(TEXT(RIGHT(F11,2),) = "×2","雙","單") -> 單 | AT11: =IF(OR(AF11="J", AF11="T", AF11="M"), IF(AG11=1, "全", "半"), IF(AF11="A", IF(AG11=0.5, IF(AS11="雙", "全", ""), IF(AG11=1, IF(AS11="雙", "半", "全"), IF(AG11=2, "半", "") ) ), IF(AF11="S", TEXT(AG11 & "sec", "text"), "") )) -> 全 | AU11: =IF(MID(E11,3,1)="/",LEFT(E11,2),LEFT(E11,3)) | AV11: =IF(ISERROR((IF(AF11="S",AG11*AU11*G11*AC11/18*0.03456/100/1000, AU11*G11*AC11* (IF(OR(AND(AS11="單",AT11="全",OR(AF11="A",AF11="M")),AND(AS11="單",AT11="全",OR(AF11="T",AF11="J"))),1,0)+ IF(OR(AND(AS11="雙",AT11="全",OR(AF11="A",AF11="M")),AND(AS11="雙",AT11="半",OR(AF11="T",AF11="J"))),1,0)+ IF(AND(AS11="雙",AT11="全",OR(AF11="T",AF11="J")),2,0)+ IF(AND(AS11="單",AT11="半",OR(AF11="A",AF11="M")),0.5,0)+ IF(OR(AND(AS11="雙",AT11="半",OR(AF11="A",AF11="M")),AND(AS11="單",AT11="半",OR(AF11="T",AF11="J"))),0.5,0) )*0.03456/100/1000 ))),"",((IF(AF11="S",AG11*AU11*G11*AC11/18*0.03456/100/1000, AU11*G11*AC11* (IF(OR(AND(AS11="單",AT11="全",OR(AF11="A",AF11="M")),AND(AS11="單",AT11="全",OR(AF11="T",AF11="J"))),1,0)+ IF(OR(AND(AS11="雙",AT11="全",OR(AF11="A",AF11="M")),AND(AS11="雙",AT11="半",OR(AF11="T",AF11="J"))),1,0)+ IF(AND(AS11="雙",AT11="全",OR(AF11="T",AF11="J")),2,0)+ IF(AND(AS11="單",AT11="半",OR(AF11="A",AF11="M")),0.5,0)+ IF(OR(AND(AS11="雙",AT11="半",OR(AF11="A",AF11="M")),AND(AS11="單",AT11="半",OR(AF11="T",AF11="J"))),0.5,0) )*0.03456/100/1000 ))))
A12: =A11 -> 46174 | B12: A17 | C12: 停機 | E12: =IF(ISNA(VLOOKUP(C12,條件!$A$1:$G$1021,5,0)),"",(VLOOKUP(C12,條件!$A$1:$G$1021,5,0))) | F12: =IF(ISNA(VLOOKUP(C12,條件!$A$1:$G$1021,6,0)),"",(VLOOKUP(C12,條件!$A$1:$G$1021,6,0))) | G12: =IF(ISNA(VLOOKUP(C12,條件!$A$1:$G$1021,7,0)),"",(VLOOKUP(C12,條件!$A$1:$G$1021,7,0))) | H12: =IF(ISNA(VLOOKUP(C12,條件!$A$1:$K$1021,11,0)),"",(VLOOKUP(C12,條件!$A$1:$K$1021,11,0))) | I12: =IF(ISNA(VLOOKUP(C12,條件!$A$1:$L$1021,12,0)),"",(VLOOKUP(C12,條件!$A$1:$L$1021,12,0))) | L12: 停機 | P12: 停機 | T12: 停機 | X12: 停機 | Z12: =IFERROR(VLOOKUP(C12, 條件!$A:$L, 3, 0), "") | AA12: =IF(OR(L12={"改紡","檢修","了機","清車","FINAL","停機","SAMPLE","TEST","絲開發","待料","跳車"}), L12, IFERROR(IF(C12="", "", (SUM(J12, N12, R12, V12)/3 * AG12) * IF(AND(AF12="S", AS12="雙"), 0.5, 1)), "")) -> 停機 | AB12: =IF(K12="","",IF(ISERROR(1-(SUM(K12,O12,S12,W12)/208/Z12)),"",(1-(SUM(K12,O12,S12,W12)/208/Z12)))) | AC12: =IF(OR(L12={"改紡","檢修","了機","清車","FINAL","停機","SAMPLE","TEST"}), "", IFERROR(IF(C12="", "", AVERAGE(L12:M12, P12:Q12, T12:U12, X12:Y12)/100), "")) | AD12: =IF(ISERROR(AA12/8),"",(AA12/8)) | AE12: =IF(OR(L12="改紡", L12="檢修", L12="了機"), "", IF(AND(C12<>"", J12<>""), IFERROR((SUM(J12, N12, R12, V12) - SUM(K12, O12, S12, W12))/24 * AG12, ""), "") ) | AF12: =LEFT(B12,1) -> A | AG12: 1 | AH12: NA | AI12: NA | AJ12: NA | AK12: NA | AS12: =IF(TEXT(RIGHT(F12,2),) = "×2","雙","單") -> 單 | AT12: =IF(OR(AF12="J", AF12="T", AF12="M"), IF(AG12=1, "全", "半"), IF(AF12="A", IF(AG12=0.5, IF(AS12="雙", "全", ""), IF(AG12=1, IF(AS12="雙", "半", "全"), IF(AG12=2, "半", "") ) ), IF(AF12="S", TEXT(AG12 & "sec", "text"), "") )) -> 全 | AU12: =IF(MID(E12,3,1)="/",LEFT(E12,2),LEFT(E12,3)) | AV12: =IF(ISERROR((IF(AF12="S",AG12*AU12*G12*AC12/18*0.03456/100/1000, AU12*G12*AC12* (IF(OR(AND(AS12="單",AT12="全",OR(AF12="A",AF12="M")),AND(AS12="單",AT12="全",OR(AF12="T",AF12="J"))),1,0)+ IF(OR(AND(AS12="雙",AT12="全",OR(AF12="A",AF12="M")),AND(AS12="雙",AT12="半",OR(AF12="T",AF12="J"))),1,0)+ IF(AND(AS12="雙",AT12="全",OR(AF12="T",AF12="J")),2,0)+ IF(AND(AS12="單",AT12="半",OR(AF12="A",AF12="M")),0.5,0)+ IF(OR(AND(AS12="雙",AT12="半",OR(AF12="A",AF12="M")),AND(AS12="單",AT12="半",OR(AF12="T",AF12="J"))),0.5,0) )*0.03456/100/1000 ))),"",((IF(AF12="S",AG12*AU12*G12*AC12/18*0.03456/100/1000, AU12*G12*AC12* (IF(OR(AND(AS12="單",AT12="全",OR(AF12="A",AF12="M")),AND(AS12="單",AT12="全",OR(AF12="T",AF12="J"))),1,0)+ IF(OR(AND(AS12="雙",AT12="全",OR(AF12="A",AF12="M")),AND(AS12="雙",AT12="半",OR(AF12="T",AF12="J"))),1,0)+ IF(AND(AS12="雙",AT12="全",OR(AF12="T",AF12="J")),2,0)+ IF(AND(AS12="單",AT12="半",OR(AF12="A",AF12="M")),0.5,0)+ IF(OR(AND(AS12="雙",AT12="半",OR(AF12="A",AF12="M")),AND(AS12="單",AT12="半",OR(AF12="T",AF12="J"))),0.5,0) )*0.03456/100/1000 ))))
A13: =A12 -> 46174 | B13: A18 | C13: 停機 | E13: =IF(ISNA(VLOOKUP(C13,條件!$A$1:$G$1021,5,0)),"",(VLOOKUP(C13,條件!$A$1:$G$1021,5,0))) | F13: =IF(ISNA(VLOOKUP(C13,條件!$A$1:$G$1021,6,0)),"",(VLOOKUP(C13,條件!$A$1:$G$1021,6,0))) | G13: =IF(ISNA(VLOOKUP(C13,條件!$A$1:$G$1021,7,0)),"",(VLOOKUP(C13,條件!$A$1:$G$1021,7,0))) | H13: =IF(ISNA(VLOOKUP(C13,條件!$A$1:$K$1021,11,0)),"",(VLOOKUP(C13,條件!$A$1:$K$1021,11,0))) | I13: =IF(ISNA(VLOOKUP(C13,條件!$A$1:$L$1021,12,0)),"",(VLOOKUP(C13,條件!$A$1:$L$1021,12,0))) | L13: 停機 | P13: 停機 | T13: 停機 | X13: 停機 | Z13: =IFERROR(VLOOKUP(C13, 條件!$A:$L, 3, 0), "") | AA13: =IF(OR(L13={"改紡","檢修","了機","清車","FINAL","停機","SAMPLE","TEST","絲開發","待料","跳車"}), L13, IFERROR(IF(C13="", "", (SUM(J13, N13, R13, V13)/3 * AG13) * IF(AND(AF13="S", AS13="雙"), 0.5, 1)), "")) -> 停機 | AB13: =IF(K13="","",IF(ISERROR(1-(SUM(K13,O13,S13,W13)/208/Z13)),"",(1-(SUM(K13,O13,S13,W13)/208/Z13)))) | AC13: =IF(OR(L13={"改紡","檢修","了機","清車","FINAL","停機","SAMPLE","TEST"}), "", IFERROR(IF(C13="", "", AVERAGE(L13:M13, P13:Q13, T13:U13, X13:Y13)/100), "")) | AD13: =IF(ISERROR(AA13/8),"",(AA13/8)) | AE13: =IF(OR(L13="改紡", L13="檢修", L13="了機"), "", IF(AND(C13<>"", J13<>""), IFERROR((SUM(J13, N13, R13, V13) - SUM(K13, O13, S13, W13))/24 * AG13, ""), "") ) | AF13: =LEFT(B13,1) -> A | AG13: 1 | AH13: NA | AI13: NA | AJ13: NA | AK13: NA | AS13: =IF(TEXT(RIGHT(F13,2),) = "×2","雙","單") -> 單 | AT13: =IF(OR(AF13="J", AF13="T", AF13="M"), IF(AG13=1, "全", "半"), IF(AF13="A", IF(AG13=0.5, IF(AS13="雙", "全", ""), IF(AG13=1, IF(AS13="雙", "半", "全"), IF(AG13=2, "半", "") ) ), IF(AF13="S", TEXT(AG13 & "sec", "text"), "") )) -> 全 | AU13: =IF(MID(E13,3,1)="/",LEFT(E13,2),LEFT(E13,3)) | AV13: =IF(ISERROR((IF(AF13="S",AG13*AU13*G13*AC13/18*0.03456/100/1000, AU13*G13*AC13* (IF(OR(AND(AS13="單",AT13="全",OR(AF13="A",AF13="M")),AND(AS13="單",AT13="全",OR(AF13="T",AF13="J"))),1,0)+ IF(OR(AND(AS13="雙",AT13="全",OR(AF13="A",AF13="M")),AND(AS13="雙",AT13="半",OR(AF13="T",AF13="J"))),1,0)+ IF(AND(AS13="雙",AT13="全",OR(AF13="T",AF13="J")),2,0)+ IF(AND(AS13="單",AT13="半",OR(AF13="A",AF13="M")),0.5,0)+ IF(OR(AND(AS13="雙",AT13="半",OR(AF13="A",AF13="M")),AND(AS13="單",AT13="半",OR(AF13="T",AF13="J"))),0.5,0) )*0.03456/100/1000 ))),"",((IF(AF13="S",AG13*AU13*G13*AC13/18*0.03456/100/1000, AU13*G13*AC13* (IF(OR(AND(AS13="單",AT13="全",OR(AF13="A",AF13="M")),AND(AS13="單",AT13="全",OR(AF13="T",AF13="J"))),1,0)+ IF(OR(AND(AS13="雙",AT13="全",OR(AF13="A",AF13="M")),AND(AS13="雙",AT13="半",OR(AF13="T",AF13="J"))),1,0)+ IF(AND(AS13="雙",AT13="全",OR(AF13="T",AF13="J")),2,0)+ IF(AND(AS13="單",AT13="半",OR(AF13="A",AF13="M")),0.5,0)+ IF(OR(AND(AS13="雙",AT13="半",OR(AF13="A",AF13="M")),AND(AS13="單",AT13="半",OR(AF13="T",AF13="J"))),0.5,0) )*0.03456/100/1000 ))))
A14: =A13 -> 46174 | B14: A19 | C14: 停機 | E14: =IF(ISNA(VLOOKUP(C14,條件!$A$1:$G$1021,5,0)),"",(VLOOKUP(C14,條件!$A$1:$G$1021,5,0))) | F14: =IF(ISNA(VLOOKUP(C14,條件!$A$1:$G$1021,6,0)),"",(VLOOKUP(C14,條件!$A$1:$G$1021,6,0))) | G14: =IF(ISNA(VLOOKUP(C14,條件!$A$1:$G$1021,7,0)),"",(VLOOKUP(C14,條件!$A$1:$G$1021,7,0))) | H14: =IF(ISNA(VLOOKUP(C14,條件!$A$1:$K$1021,11,0)),"",(VLOOKUP(C14,條件!$A$1:$K$1021,11,0))) | I14: =IF(ISNA(VLOOKUP(C14,條件!$A$1:$L$1021,12,0)),"",(VLOOKUP(C14,條件!$A$1:$L$1021,12,0))) | L14: 停機 | P14: 停機 | T14: 停機 | X14: 停機 | Z14: =IFERROR(VLOOKUP(C14, 條件!$A:$L, 3, 0), "") | AA14: =IF(OR(L14={"改紡","檢修","了機","清車","FINAL","停機","SAMPLE","TEST","絲開發","待料","跳車"}), L14, IFERROR(IF(C14="", "", (SUM(J14, N14, R14, V14)/3 * AG14) * IF(AND(AF14="S", AS14="雙"), 0.5, 1)), "")) -> 停機 | AB14: =IF(K14="","",IF(ISERROR(1-(SUM(K14,O14,S14,W14)/208/Z14)),"",(1-(SUM(K14,O14,S14,W14)/208/Z14)))) | AC14: =IF(OR(L14={"改紡","檢修","了機","清車","FINAL","停機","SAMPLE","TEST"}), "", IFERROR(IF(C14="", "", AVERAGE(L14:M14, P14:Q14, T14:U14, X14:Y14)/100), "")) | AD14: =IF(ISERROR(AA14/8),"",(AA14/8)) | AE14: =IF(OR(L14="改紡", L14="檢修", L14="了機"), "", IF(AND(C14<>"", J14<>""), IFERROR((SUM(J14, N14, R14, V14) - SUM(K14, O14, S14, W14))/24 * AG14, ""), "") ) | AF14: =LEFT(B14,1) -> A | AG14: 1 | AH14: NA | AI14: NA | AJ14: NA | AK14: NA | AS14: =IF(TEXT(RIGHT(F14,2),) = "×2","雙","單") -> 單 | AT14: =IF(OR(AF14="J", AF14="T", AF14="M"), IF(AG14=1, "全", "半"), IF(AF14="A", IF(AG14=0.5, IF(AS14="雙", "全", ""), IF(AG14=1, IF(AS14="雙", "半", "全"), IF(AG14=2, "半", "") ) ), IF(AF14="S", TEXT(AG14 & "sec", "text"), "") )) -> 全 | AU14: =IF(MID(E14,3,1)="/",LEFT(E14,2),LEFT(E14,3)) | AV14: =IF(ISERROR((IF(AF14="S",AG14*AU14*G14*AC14/18*0.03456/100/1000, AU14*G14*AC14* (IF(OR(AND(AS14="單",AT14="全",OR(AF14="A",AF14="M")),AND(AS14="單",AT14="全",OR(AF14="T",AF14="J"))),1,0)+ IF(OR(AND(AS14="雙",AT14="全",OR(AF14="A",AF14="M")),AND(AS14="雙",AT14="半",OR(AF14="T",AF14="J"))),1,0)+ IF(AND(AS14="雙",AT14="全",OR(AF14="T",AF14="J")),2,0)+ IF(AND(AS14="單",AT14="半",OR(AF14="A",AF14="M")),0.5,0)+ IF(OR(AND(AS14="雙",AT14="半",OR(AF14="A",AF14="M")),AND(AS14="單",AT14="半",OR(AF14="T",AF14="J"))),0.5,0) )*0.03456/100/1000 ))),"",((IF(AF14="S",AG14*AU14*G14*AC14/18*0.03456/100/1000, AU14*G14*AC14* (IF(OR(AND(AS14="單",AT14="全",OR(AF14="A",AF14="M")),AND(AS14="單",AT14="全",OR(AF14="T",AF14="J"))),1,0)+ IF(OR(AND(AS14="雙",AT14="全",OR(AF14="A",AF14="M")),AND(AS14="雙",AT14="半",OR(AF14="T",AF14="J"))),1,0)+ IF(AND(AS14="雙",AT14="全",OR(AF14="T",AF14="J")),2,0)+ IF(AND(AS14="單",AT14="半",OR(AF14="A",AF14="M")),0.5,0)+ IF(OR(AND(AS14="雙",AT14="半",OR(AF14="A",AF14="M")),AND(AS14="單",AT14="半",OR(AF14="T",AF14="J"))),0.5,0) )*0.03456/100/1000 ))))
A15: =A14 -> 46174 | B15: A20 | C15: 停機 | E15: =IF(ISNA(VLOOKUP(C15,條件!$A$1:$G$1021,5,0)),"",(VLOOKUP(C15,條件!$A$1:$G$1021,5,0))) | F15: =IF(ISNA(VLOOKUP(C15,條件!$A$1:$G$1021,6,0)),"",(VLOOKUP(C15,條件!$A$1:$G$1021,6,0))) | G15: =IF(ISNA(VLOOKUP(C15,條件!$A$1:$G$1021,7,0)),"",(VLOOKUP(C15,條件!$A$1:$G$1021,7,0))) | H15: =IF(ISNA(VLOOKUP(C15,條件!$A$1:$K$1021,11,0)),"",(VLOOKUP(C15,條件!$A$1:$K$1021,11,0))) | I15: =IF(ISNA(VLOOKUP(C15,條件!$A$1:$L$1021,12,0)),"",(VLOOKUP(C15,條件!$A$1:$L$1021,12,0))) | L15: 停機 | P15: 停機 | T15: 停機 | X15: 停機 | Z15: =IFERROR(VLOOKUP(C15, 條件!$A:$L, 3, 0), "") | AA15: =IF(OR(L15={"改紡","檢修","了機","清車","FINAL","停機","SAMPLE","TEST","絲開發","待料","跳車"}), L15, IFERROR(IF(C15="", "", (SUM(J15, N15, R15, V15)/3 * AG15) * IF(AND(AF15="S", AS15="雙"), 0.5, 1)), "")) -> 停機 | AB15: =IF(K15="","",IF(ISERROR(1-(SUM(K15,O15,S15,W15)/208/Z15)),"",(1-(SUM(K15,O15,S15,W15)/208/Z15)))) | AC15: =IF(OR(L15={"改紡","檢修","了機","清車","FINAL","停機","SAMPLE","TEST"}), "", IFERROR(IF(C15="", "", AVERAGE(L15:M15, P15:Q15, T15:U15, X15:Y15)/100), "")) | AD15: =IF(ISERROR(AA15/8),"",(AA15/8)) | AE15: =IF(OR(L15="改紡", L15="檢修", L15="了機"), "", IF(AND(C15<>"", J15<>""), IFERROR((SUM(J15, N15, R15, V15) - SUM(K15, O15, S15, W15))/24 * AG15, ""), "") ) | AF15: =LEFT(B15,1) -> A | AG15: 1 | AH15: NA | AI15: NA | AJ15: NA | AK15: NA | AS15: =IF(TEXT(RIGHT(F15,2),) = "×2","雙","單") -> 單 | AT15: =IF(OR(AF15="J", AF15="T", AF15="M"), IF(AG15=1, "全", "半"), IF(AF15="A", IF(AG15=0.5, IF(AS15="雙", "全", ""), IF(AG15=1, IF(AS15="雙", "半", "全"), IF(AG15=2, "半", "") ) ), IF(AF15="S", TEXT(AG15 & "sec", "text"), "") )) -> 全 | AU15: =IF(MID(E15,3,1)="/",LEFT(E15,2),LEFT(E15,3)) | AV15: =IF(ISERROR((IF(AF15="S",AG15*AU15*G15*AC15/18*0.03456/100/1000, AU15*G15*AC15* (IF(OR(AND(AS15="單",AT15="全",OR(AF15="A",AF15="M")),AND(AS15="單",AT15="全",OR(AF15="T",AF15="J"))),1,0)+ IF(OR(AND(AS15="雙",AT15="全",OR(AF15="A",AF15="M")),AND(AS15="雙",AT15="半",OR(AF15="T",AF15="J"))),1,0)+ IF(AND(AS15="雙",AT15="全",OR(AF15="T",AF15="J")),2,0)+ IF(AND(AS15="單",AT15="半",OR(AF15="A",AF15="M")),0.5,0)+ IF(OR(AND(AS15="雙",AT15="半",OR(AF15="A",AF15="M")),AND(AS15="單",AT15="半",OR(AF15="T",AF15="J"))),0.5,0) )*0.03456/100/1000 ))),"",((IF(AF15="S",AG15*AU15*G15*AC15/18*0.03456/100/1000, AU15*G15*AC15* (IF(OR(AND(AS15="單",AT15="全",OR(AF15="A",AF15="M")),AND(AS15="單",AT15="全",OR(AF15="T",AF15="J"))),1,0)+ IF(OR(AND(AS15="雙",AT15="全",OR(AF15="A",AF15="M")),AND(AS15="雙",AT15="半",OR(AF15="T",AF15="J"))),1,0)+ IF(AND(AS15="雙",AT15="全",OR(AF15="T",AF15="J")),2,0)+ IF(AND(AS15="單",AT15="半",OR(AF15="A",AF15="M")),0.5,0)+ IF(OR(AND(AS15="雙",AT15="半",OR(AF15="A",AF15="M")),AND(AS15="單",AT15="半",OR(AF15="T",AF15="J"))),0.5,0) )*0.03456/100/1000 ))))
A16: =A15 -> 46174 | B16: A21 | C16: 停機 | E16: =IF(ISNA(VLOOKUP(C16,條件!$A$1:$G$1021,5,0)),"",(VLOOKUP(C16,條件!$A$1:$G$1021,5,0))) | F16: =IF(ISNA(VLOOKUP(C16,條件!$A$1:$G$1021,6,0)),"",(VLOOKUP(C16,條件!$A$1:$G$1021,6,0))) | G16: =IF(ISNA(VLOOKUP(C16,條件!$A$1:$G$1021,7,0)),"",(VLOOKUP(C16,條件!$A$1:$G$1021,7,0))) | H16: =IF(ISNA(VLOOKUP(C16,條件!$A$1:$K$1021,11,0)),"",(VLOOKUP(C16,條件!$A$1:$K$1021,11,0))) | I16: =IF(ISNA(VLOOKUP(C16,條件!$A$1:$L$1021,12,0)),"",(VLOOKUP(C16,條件!$A$1:$L$1021,12,0))) | L16: 停機 | P16: 停機 | T16: 停機 | X16: 停機 | Z16: =IFERROR(VLOOKUP(C16, 條件!$A:$L, 3, 0), "") | AA16: =IF(OR(L16={"改紡","檢修","了機","清車","FINAL","停機","SAMPLE","TEST","絲開發","待料","跳車"}), L16, IFERROR(IF(C16="", "", (SUM(J16, N16, R16, V16)/3 * AG16) * IF(AND(AF16="S", AS16="雙"), 0.5, 1)), "")) -> 停機 | AB16: =IF(K16="","",IF(ISERROR(1-(SUM(K16,O16,S16,W16)/208/Z16)),"",(1-(SUM(K16,O16,S16,W16)/208/Z16)))) | AC16: =IF(OR(L16={"改紡","檢修","了機","清車","FINAL","停機","SAMPLE","TEST"}), "", IFERROR(IF(C16="", "", AVERAGE(L16:M16, P16:Q16, T16:U16, X16:Y16)/100), "")) | AD16: =IF(ISERROR(AA16/8),"",(AA16/8)) | AE16: =IF(OR(L16="改紡", L16="檢修", L16="了機"), "", IF(AND(C16<>"", J16<>""), IFERROR((SUM(J16, N16, R16, V16) - SUM(K16, O16, S16, W16))/24 * AG16, ""), "") ) | AF16: =LEFT(B16,1) -> A | AG16: 1 | AH16: NA | AI16: NA | AJ16: NA | AK16: NA | AS16: =IF(TEXT(RIGHT(F16,2),) = "×2","雙","單") -> 單 | AT16: =IF(OR(AF16="J", AF16="T", AF16="M"), IF(AG16=1, "全", "半"), IF(AF16="A", IF(AG16=0.5, IF(AS16="雙", "全", ""), IF(AG16=1, IF(AS16="雙", "半", "全"), IF(AG16=2, "半", "") ) ), IF(AF16="S", TEXT(AG16 & "sec", "text"), "") )) -> 全 | AU16: =IF(MID(E16,3,1)="/",LEFT(E16,2),LEFT(E16,3)) | AV16: =IF(ISERROR((IF(AF16="S",AG16*AU16*G16*AC16/18*0.03456/100/1000, AU16*G16*AC16* (IF(OR(AND(AS16="單",AT16="全",OR(AF16="A",AF16="M")),AND(AS16="單",AT16="全",OR(AF16="T",AF16="J"))),1,0)+ IF(OR(AND(AS16="雙",AT16="全",OR(AF16="A",AF16="M")),AND(AS16="雙",AT16="半",OR(AF16="T",AF16="J"))),1,0)+ IF(AND(AS16="雙",AT16="全",OR(AF16="T",AF16="J")),2,0)+ IF(AND(AS16="單",AT16="半",OR(AF16="A",AF16="M")),0.5,0)+ IF(OR(AND(AS16="雙",AT16="半",OR(AF16="A",AF16="M")),AND(AS16="單",AT16="半",OR(AF16="T",AF16="J"))),0.5,0) )*0.03456/100/1000 ))),"",((IF(AF16="S",AG16*AU16*G16*AC16/18*0.03456/100/1000, AU16*G16*AC16* (IF(OR(AND(AS16="單",AT16="全",OR(AF16="A",AF16="M")),AND(AS16="單",AT16="全",OR(AF16="T",AF16="J"))),1,0)+ IF(OR(AND(AS16="雙",AT16="全",OR(AF16="A",AF16="M")),AND(AS16="雙",AT16="半",OR(AF16="T",AF16="J"))),1,0)+ IF(AND(AS16="雙",AT16="全",OR(AF16="T",AF16="J")),2,0)+ IF(AND(AS16="單",AT16="半",OR(AF16="A",AF16="M")),0.5,0)+ IF(OR(AND(AS16="雙",AT16="半",OR(AF16="A",AF16="M")),AND(AS16="單",AT16="半",OR(AF16="T",AF16="J"))),0.5,0) )*0.03456/100/1000 ))))
A17: =A16 -> 46174 | B17: A22 | C17: 停機 | E17: =IF(ISNA(VLOOKUP(C17,條件!$A$1:$G$1021,5,0)),"",(VLOOKUP(C17,條件!$A$1:$G$1021,5,0))) | F17: =IF(ISNA(VLOOKUP(C17,條件!$A$1:$G$1021,6,0)),"",(VLOOKUP(C17,條件!$A$1:$G$1021,6,0))) | G17: =IF(ISNA(VLOOKUP(C17,條件!$A$1:$G$1021,7,0)),"",(VLOOKUP(C17,條件!$A$1:$G$1021,7,0))) | H17: =IF(ISNA(VLOOKUP(C17,條件!$A$1:$K$1021,11,0)),"",(VLOOKUP(C17,條件!$A$1:$K$1021,11,0))) | I17: =IF(ISNA(VLOOKUP(C17,條件!$A$1:$L$1021,12,0)),"",(VLOOKUP(C17,條件!$A$1:$L$1021,12,0))) | L17: 停機 | P17: 停機 | T17: 停機 | X17: 停機 | Z17: =IFERROR(VLOOKUP(C17, 條件!$A:$L, 3, 0), "") | AA17: =IF(OR(L17={"改紡","檢修","了機","清車","FINAL","停機","SAMPLE","TEST","絲開發","待料","跳車"}), L17, IFERROR(IF(C17="", "", (SUM(J17, N17, R17, V17)/3 * AG17) * IF(AND(AF17="S", AS17="雙"), 0.5, 1)), "")) -> 停機 | AB17: =IF(K17="","",IF(ISERROR(1-(SUM(K17,O17,S17,W17)/208/Z17)),"",(1-(SUM(K17,O17,S17,W17)/208/Z17)))) | AC17: =IF(OR(L17={"改紡","檢修","了機","清車","FINAL","停機","SAMPLE","TEST"}), "", IFERROR(IF(C17="", "", AVERAGE(L17:M17, P17:Q17, T17:U17, X17:Y17)/100), "")) | AD17: =IF(ISERROR(AA17/8),"",(AA17/8)) | AE17: =IF(OR(L17="改紡", L17="檢修", L17="了機"), "", IF(AND(C17<>"", J17<>""), IFERROR((SUM(J17, N17, R17, V17) - SUM(K17, O17, S17, W17))/24 * AG17, ""), "") ) | AF17: =LEFT(B17,1) -> A | AG17: 1 | AH17: NA | AI17: NA | AJ17: NA | AK17: NA | AS17: =IF(TEXT(RIGHT(F17,2),) = "×2","雙","單") -> 單 | AT17: =IF(OR(AF17="J", AF17="T", AF17="M"), IF(AG17=1, "全", "半"), IF(AF17="A", IF(AG17=0.5, IF(AS17="雙", "全", ""), IF(AG17=1, IF(AS17="雙", "半", "全"), IF(AG17=2, "半", "") ) ), IF(AF17="S", TEXT(AG17 & "sec", "text"), "") )) -> 全 | AU17: =IF(MID(E17,3,1)="/",LEFT(E17,2),LEFT(E17,3)) | AV17: =IF(ISERROR((IF(AF17="S",AG17*AU17*G17*AC17/18*0.03456/100/1000, AU17*G17*AC17* (IF(OR(AND(AS17="單",AT17="全",OR(AF17="A",AF17="M")),AND(AS17="單",AT17="全",OR(AF17="T",AF17="J"))),1,0)+ IF(OR(AND(AS17="雙",AT17="全",OR(AF17="A",AF17="M")),AND(AS17="雙",AT17="半",OR(AF17="T",AF17="J"))),1,0)+ IF(AND(AS17="雙",AT17="全",OR(AF17="T",AF17="J")),2,0)+ IF(AND(AS17="單",AT17="半",OR(AF17="A",AF17="M")),0.5,0)+ IF(OR(AND(AS17="雙",AT17="半",OR(AF17="A",AF17="M")),AND(AS17="單",AT17="半",OR(AF17="T",AF17="J"))),0.5,0) )*0.03456/100/1000 ))),"",((IF(AF17="S",AG17*AU17*G17*AC17/18*0.03456/100/1000, AU17*G17*AC17* (IF(OR(AND(AS17="單",AT17="全",OR(AF17="A",AF17="M")),AND(AS17="單",AT17="全",OR(AF17="T",AF17="J"))),1,0)+ IF(OR(AND(AS17="雙",AT17="全",OR(AF17="A",AF17="M")),AND(AS17="雙",AT17="半",OR(AF17="T",AF17="J"))),1,0)+ IF(AND(AS17="雙",AT17="全",OR(AF17="T",AF17="J")),2,0)+ IF(AND(AS17="單",AT17="半",OR(AF17="A",AF17="M")),0.5,0)+ IF(OR(AND(AS17="雙",AT17="半",OR(AF17="A",AF17="M")),AND(AS17="單",AT17="半",OR(AF17="T",AF17="J"))),0.5,0) )*0.03456/100/1000 ))))
A18: =A17 -> 46174 | B18: A23 | C18: 停機 | E18: =IF(ISNA(VLOOKUP(C18,條件!$A$1:$G$1021,5,0)),"",(VLOOKUP(C18,條件!$A$1:$G$1021,5,0))) | F18: =IF(ISNA(VLOOKUP(C18,條件!$A$1:$G$1021,6,0)),"",(VLOOKUP(C18,條件!$A$1:$G$1021,6,0))) | G18: =IF(ISNA(VLOOKUP(C18,條件!$A$1:$G$1021,7,0)),"",(VLOOKUP(C18,條件!$A$1:$G$1021,7,0))) | H18: =IF(ISNA(VLOOKUP(C18,條件!$A$1:$K$1021,11,0)),"",(VLOOKUP(C18,條件!$A$1:$K$1021,11,0))) | I18: =IF(ISNA(VLOOKUP(C18,條件!$A$1:$L$1021,12,0)),"",(VLOOKUP(C18,條件!$A$1:$L$1021,12,0))) | L18: 停機 | P18: 停機 | T18: 停機 | X18: 停機 | Z18: =IFERROR(VLOOKUP(C18, 條件!$A:$L, 3, 0), "") | AA18: =IF(OR(L18={"改紡","檢修","了機","清車","FINAL","停機","SAMPLE","TEST","絲開發","待料","跳車"}), L18, IFERROR(IF(C18="", "", (SUM(J18, N18, R18, V18)/3 * AG18) * IF(AND(AF18="S", AS18="雙"), 0.5, 1)), "")) -> 停機 | AB18: =IF(K18="","",IF(ISERROR(1-(SUM(K18,O18,S18,W18)/208/Z18)),"",(1-(SUM(K18,O18,S18,W18)/208/Z18)))) | AC18: =IF(OR(L18={"改紡","檢修","了機","清車","FINAL","停機","SAMPLE","TEST"}), "", IFERROR(IF(C18="", "", AVERAGE(L18:M18, P18:Q18, T18:U18, X18:Y18)/100), "")) | AD18: =IF(ISERROR(AA18/8),"",(AA18/8)) | AE18: =IF(OR(L18="改紡", L18="檢修", L18="了機"), "", IF(AND(C18<>"", J18<>""), IFERROR((SUM(J18, N18, R18, V18) - SUM(K18, O18, S18, W18))/24 * AG18, ""), "") ) | AF18: =LEFT(B18,1) -> A | AG18: 1 | AH18: NA | AI18: NA | AJ18: NA | AK18: NA | AS18: =IF(TEXT(RIGHT(F18,2),) = "×2","雙","單") -> 單 | AT18: =IF(OR(AF18="J", AF18="T", AF18="M"), IF(AG18=1, "全", "半"), IF(AF18="A", IF(AG18=0.5, IF(AS18="雙", "全", ""), IF(AG18=1, IF(AS18="雙", "半", "全"), IF(AG18=2, "半", "") ) ), IF(AF18="S", TEXT(AG18 & "sec", "text"), "") )) -> 全 | AU18: =IF(MID(E18,3,1)="/",LEFT(E18,2),LEFT(E18,3)) | AV18: =IF(ISERROR((IF(AF18="S",AG18*AU18*G18*AC18/18*0.03456/100/1000, AU18*G18*AC18* (IF(OR(AND(AS18="單",AT18="全",OR(AF18="A",AF18="M")),AND(AS18="單",AT18="全",OR(AF18="T",AF18="J"))),1,0)+ IF(OR(AND(AS18="雙",AT18="全",OR(AF18="A",AF18="M")),AND(AS18="雙",AT18="半",OR(AF18="T",AF18="J"))),1,0)+ IF(AND(AS18="雙",AT18="全",OR(AF18="T",AF18="J")),2,0)+ IF(AND(AS18="單",AT18="半",OR(AF18="A",AF18="M")),0.5,0)+ IF(OR(AND(AS18="雙",AT18="半",OR(AF18="A",AF18="M")),AND(AS18="單",AT18="半",OR(AF18="T",AF18="J"))),0.5,0) )*0.03456/100/1000 ))),"",((IF(AF18="S",AG18*AU18*G18*AC18/18*0.03456/100/1000, AU18*G18*AC18* (IF(OR(AND(AS18="單",AT18="全",OR(AF18="A",AF18="M")),AND(AS18="單",AT18="全",OR(AF18="T",AF18="J"))),1,0)+ IF(OR(AND(AS18="雙",AT18="全",OR(AF18="A",AF18="M")),AND(AS18="雙",AT18="半",OR(AF18="T",AF18="J"))),1,0)+ IF(AND(AS18="雙",AT18="全",OR(AF18="T",AF18="J")),2,0)+ IF(AND(AS18="單",AT18="半",OR(AF18="A",AF18="M")),0.5,0)+ IF(OR(AND(AS18="雙",AT18="半",OR(AF18="A",AF18="M")),AND(AS18="單",AT18="半",OR(AF18="T",AF18="J"))),0.5,0) )*0.03456/100/1000 ))))
A19: =A18 -> 46174 | B19: A24 | C19: 停機 | E19: =IF(ISNA(VLOOKUP(C19,條件!$A$1:$G$1021,5,0)),"",(VLOOKUP(C19,條件!$A$1:$G$1021,5,0))) | F19: =IF(ISNA(VLOOKUP(C19,條件!$A$1:$G$1021,6,0)),"",(VLOOKUP(C19,條件!$A$1:$G$1021,6,0))) | G19: =IF(ISNA(VLOOKUP(C19,條件!$A$1:$G$1021,7,0)),"",(VLOOKUP(C19,條件!$A$1:$G$1021,7,0))) | H19: =IF(ISNA(VLOOKUP(C19,條件!$A$1:$K$1021,11,0)),"",(VLOOKUP(C19,條件!$A$1:$K$1021,11,0))) | I19: =IF(ISNA(VLOOKUP(C19,條件!$A$1:$L$1021,12,0)),"",(VLOOKUP(C19,條件!$A$1:$L$1021,12,0))) | L19: 停機 | P19: 停機 | T19: 停機 | X19: 停機 | Z19: =IFERROR(VLOOKUP(C19, 條件!$A:$L, 3, 0), "") | AA19: =IF(OR(L19={"改紡","檢修","了機","清車","FINAL","停機","SAMPLE","TEST","絲開發","待料","跳車"}), L19, IFERROR(IF(C19="", "", (SUM(J19, N19, R19, V19)/3 * AG19) * IF(AND(AF19="S", AS19="雙"), 0.5, 1)), "")) -> 停機 | AB19: =IF(K19="","",IF(ISERROR(1-(SUM(K19,O19,S19,W19)/208/Z19)),"",(1-(SUM(K19,O19,S19,W19)/208/Z19)))) | AC19: =IF(OR(L19={"改紡","檢修","了機","清車","FINAL","停機","SAMPLE","TEST"}), "", IFERROR(IF(C19="", "", AVERAGE(L19:M19, P19:Q19, T19:U19, X19:Y19)/100), "")) | AD19: =IF(ISERROR(AA19/8),"",(AA19/8)) | AE19: =IF(OR(L19="改紡", L19="檢修", L19="了機"), "", IF(AND(C19<>"", J19<>""), IFERROR((SUM(J19, N19, R19, V19) - SUM(K19, O19, S19, W19))/24 * AG19, ""), "") ) | AF19: =LEFT(B19,1) -> A | AG19: 1 | AH19: NA | AI19: NA | AJ19: NA | AK19: NA | AS19: =IF(TEXT(RIGHT(F19,2),) = "×2","雙","單") -> 單 | AT19: =IF(OR(AF19="J", AF19="T", AF19="M"), IF(AG19=1, "全", "半"), IF(AF19="A", IF(AG19=0.5, IF(AS19="雙", "全", ""), IF(AG19=1, IF(AS19="雙", "半", "全"), IF(AG19=2, "半", "") ) ), IF(AF19="S", TEXT(AG19 & "sec", "text"), "") )) -> 全 | AU19: =IF(MID(E19,3,1)="/",LEFT(E19,2),LEFT(E19,3)) | AV19: =IF(ISERROR((IF(AF19="S",AG19*AU19*G19*AC19/18*0.03456/100/1000, AU19*G19*AC19* (IF(OR(AND(AS19="單",AT19="全",OR(AF19="A",AF19="M")),AND(AS19="單",AT19="全",OR(AF19="T",AF19="J"))),1,0)+ IF(OR(AND(AS19="雙",AT19="全",OR(AF19="A",AF19="M")),AND(AS19="雙",AT19="半",OR(AF19="T",AF19="J"))),1,0)+ IF(AND(AS19="雙",AT19="全",OR(AF19="T",AF19="J")),2,0)+ IF(AND(AS19="單",AT19="半",OR(AF19="A",AF19="M")),0.5,0)+ IF(OR(AND(AS19="雙",AT19="半",OR(AF19="A",AF19="M")),AND(AS19="單",AT19="半",OR(AF19="T",AF19="J"))),0.5,0) )*0.03456/100/1000 ))),"",((IF(AF19="S",AG19*AU19*G19*AC19/18*0.03456/100/1000, AU19*G19*AC19* (IF(OR(AND(AS19="單",AT19="全",OR(AF19="A",AF19="M")),AND(AS19="單",AT19="全",OR(AF19="T",AF19="J"))),1,0)+ IF(OR(AND(AS19="雙",AT19="全",OR(AF19="A",AF19="M")),AND(AS19="雙",AT19="半",OR(AF19="T",AF19="J"))),1,0)+ IF(AND(AS19="雙",AT19="全",OR(AF19="T",AF19="J")),2,0)+ IF(AND(AS19="單",AT19="半",OR(AF19="A",AF19="M")),0.5,0)+ IF(OR(AND(AS19="雙",AT19="半",OR(AF19="A",AF19="M")),AND(AS19="單",AT19="半",OR(AF19="T",AF19="J"))),0.5,0) )*0.03456/100/1000 ))))
