Workbook

Sheet Jul
A1: 機台 | B1: DTY批號 | D1: 邊 | E1: DTY規格 | F1: 排產日期 | G1: 天數 | H1: T / D | I1: POY批號 | J1: POY規格 | K1: 期初 | L1: 預產 | M1: 調撥 | N1: 虹妤 | O1: 連新 | P1: YKK | Q1: 樺德 | R1: 紹容 | S1: 合計 | T1: 期末
A2: A07x | K2: =SUMIF(庫!$B$2:$B$2999,B2,庫!$L$2:$L$2999)/1000 -> 0 | L2: =G2*H2 -> 0 | S2: =SUM(M2:R2) -> 0 | T2: =K2+L2-S2 -> 0
A3: A08x | K3: =SUMIF(庫!$B$2:$B$2999,B3,庫!$L$2:$L$2999)/1000 -> 0 | L3: =G3*H3 -> 0 | S3: =SUM(M3:R3) -> 0 | T3: =K3+L3-S3 -> 0
A4: A09x | B4: FD2F43U3 | C4: 12T AW | D4: Clare | E4: 150/144 FCT | F4: 7/3-7/12X | G4: 9 | H4: 1.5 | I4: FP81858+81360R | J4: 125/72HC+125/72FDR | K4: =SUMIF(庫!$B$2:$B$2999,B4,庫!$L$2:$L$2999)/1000 -> 0 | L4: =G4*H4 -> 13.5 | R4: 12 | S4: =SUM(M4:R4) -> 12 | T4: =K4+L4-S4 -> 1.5
K5: =SUMIF(庫!$B$2:$B$2999,B5,庫!$L$2:$L$2999)/1000 -> 0 | L5: =G5*H5 -> 0 | S5: =SUM(M5:R5) -> 0 | T5: =K5+L5-S5 -> 0
A6: A10 (BK) | K6: =SUMIF(庫!$B$2:$B$2999,B6,庫!$L$2:$L$2999)/1000 -> 0 | L6: =G6*H6 -> 0 | S6: =SUM(M6:R6) -> 0 | T6: =K6+L6-S6 -> 0
B7: FD2F6GQ3 like | C7: PV, 4.5% | D7: A | E7: 150/48/2 FBKR, 4.5% | F7: 7/17-7/27X | G7: 10 | H7: 1.2 | I7: FP02423R | J7: 250/48 FBKR | K7: =SUMIF(庫!$B$2:$B$2999,B7,庫!$L$2:$L$2999)/1000 -> 0 | L7: =G7*H7 -> 12 | Q7: 10 | S7: =SUM(M7:R7) -> 10 | T7: =K7+L7-S7 -> 2
B8: FD2F40V1 like | C8: AW 5T, Andy | D8: B | E8: 150/48 KR5 | F8: 7/17-7/31 | G8: 13 | H8: 1.2 | I8: FP82661 | J8: 260/48 KR5 | K8: =SUMIF(庫!$B$2:$B$2999,B8,庫!$L$2:$L$2999)/1000 -> 0 | L8: =G8*H8 -> 15.6 | Q8: 5 | S8: =SUM(M8:R8) -> 5 | T8: =K8+L8-S8 -> 10.6
A9: A11 | B9: FD2FA072 | C9: 9180kg/組, JH, 倒筒不加R | D9: AL | E9: 75/72 SR6 | F9: 6/8-6/30X | H9: 1.2 | I9: FP81631R | J9: 120/72 SRR5,41T | K9: =SUMIF(庫!$B$2:$B$2999,B9,庫!$L$2:$L$2999)/1000 -> 9.9 | L9: =G9*H9 -> 0 | S9: =SUM(M9:R9) -> 0 | T9: =K9+L9-S9 -> 9.9
B10: FD2FA102 | C10: 5T AW | E10: 75/48 SDr | F10: 7/7-7/17X | G10: 10 | H10: 1.5 | I10: FP81388R | J10: 125/48 SDR2 | K10: =SUMIF(庫!$B$2:$B$2999,B10,庫!$L$2:$L$2999)/1000 -> 0 | L10: =G10*H10 -> 15 | Q10: 5 | S10: =SUM(M10:R10) -> 5 | T10: =K10+L10-S10 -> 10
B11: FD2F29H2G like | C11: AW38T | D11: AL | E11: 100/72 PFR(Petal | F11: 7/20-8/5 | G11: 15 | H11: 2 | I11: FP81387R | J11: 165/72 PFR | K11: =SUMIF(庫!$B$2:$B$2999,B11,庫!$L$2:$L$2999)/1000 -> 0 | L11: =G11*H11 -> 30 | Q11: 38 | S11: =SUM(M11:R11) -> 38 | T11: =K11+L11-S11 -> -8
A12: A12 | B12: FD2F43R2 | C12: 織染JH | D12: JH | E12: 75/72/2 SDR | F12: 6/1-7/31 | G12: 30 | H12: 1.5 | I12: FP81390R, 114T | J12: 125/72 SDR | K12: =SUMIF(庫!$B$2:$B$2999,B12,庫!$L$2:$L$2999)/1000 -> 22.65 | L12: =G12*H12 -> 45 | M12: 20 | S12: =SUM(M12:R12) -> 20 | T12: =K12+L12-S12 -> 47.65
A13: A13x | B13: FD2F08R2G | D13: Clare | E13: 50/72 BSD3 | F13: 5/4-6/30 | H13: 0.8 | I13: FP80141(L57,32T | J13: 80/72 BSD3 | K13: =SUMIF(庫!$B$2:$B$2999,B13,庫!$L$2:$L$2999)/1000 -> 7.92 | L13: =G13*H13 -> 0 | S13: =SUM(M13:R13) -> 0 | T13: =K13+L13-S13 -> 7.92
A14: A14x | K14: =SUMIF(庫!$B$2:$B$2999,B14,庫!$L$2:$L$2999)/1000 -> 0 | L14: =G14*H14 -> 0 | S14: =SUM(M14:R14) -> 0 | T14: =K14+L14-S14 -> 0
B15: FD2FA112 | C15: A+AX 40T | D15: Gloria | E15: 75/72 SRR5* | F15: 7/8-8/13 | G15: 35 | H15: 1.2 | I15: FP81630R | J15: 120/72 SR6* | K15: =SUMIF(庫!$B$2:$B$2999,B15,庫!$L$2:$L$2999)/1000 -> 0 | L15: =G15*H15 -> 42 | O15: 20 | S15: =SUM(M15:R15) -> 20 | T15: =K15+L15-S15 -> 22
A16: A15x | B16: FD2F43P2 | C16: 2580kg/組 | D16: Gloria | E16: 150/48 CDR* | F16: 4/29-6/10X | H16: 2 | I16: FP82781 | J16: 250/48 HC* | K16: =SUMIF(庫!$B$2:$B$2999,B16,庫!$L$2:$L$2999)/1000 -> 76.11 | L16: =G16*H16 -> 0 | O16: 30 | S16: =SUM(M16:R16) -> 30 | T16: =K16+L16-S16 -> 46.11
S17: =SUM(M17:R17) -> 0 | T17: =K17+L17-S17 -> 0
A18: A16 | B18: FD2F08S2 | D18: JH | E18: 50/36 SDR | F18: 6/1-6/10X | H18: 1 | I18: FP80148R(L57) | J18: 85/36 SDR | K18: =SUMIF(庫!$B$2:$B$2999,B18,庫!$L$2:$L$2999)/1000 -> 6.864 | L18: =G18*H18 -> 0 | M18: 2 | S18: =SUM(M18:R18) -> 2 | T18: =K18+L18-S18 -> 4.864
B19: FD2F08T2G | C19: 7T AW挑G | D19: Clare | E19: 50/72 F2FC | F19: 6/22-7/2X | G19: 2 | H19: 1 | I19: FP00413(52D | J19: 85/72 F2FC | K19: =SUMIF(庫!$B$2:$B$2999,B19,庫!$L$2:$L$2999)/1000 -> 1.2 | L19: =G19*H19 -> 2 | R19: 7 | S19: =SUM(M19:R19) -> 7 | T19: =K19+L19-S19 -> -3.8
K20: =SUMIF(庫!$B$2:$B$2999,B20,庫!$L$2:$L$2999)/1000 -> 0 | L20: =G20*H20 -> 0 | S20: =SUM(M20:R20) -> 0 | T20: =K20+L20-S20 -> 0
A21: A17 | B21: FD2FA092G | C21: 20T AW挑G, Clare | D21: A | E21: 75/72 F2FC | F21: 6/22-7/31X | G21: 30 | H21: 0.7 | I21: FP01436(52D | J21: 125/72 F2FC | K21: =SUMIF(庫!$B$2:$B$2999,B21,庫!$L$2:$L$2999)/1000 -> 2.4 | L21: =G21*H21 -> 21 | R21: 20 | S21: =SUM(M21:R21) -> 20 | T21: =K21+L21-S21 -> 3.4
B22: FD2FA122 | C22: AW4050kg,Linda | D22: B | E22: 75/72 PDR(Petal | F22: 7/10-7/17 | G22: 7 | H22: 0.7 | I22: FP81365R(52D | J22: 120/72 PDR | L22: =G22*H22 -> 4.9 | M22: 4.05 | S22: =SUM(M22:R22) -> 4.05 | T22: =K22+L22-S22 -> 0.85
D23: B
A24: A18 | B24: FD2F7E31 | C24: A+AX14T,AL緯 | D24: AL | E24: 165/48/2 SR6 | F24: 6/17-6/24X | H24: 2 | I24: FP82659 | J24: 275/48 SR6 | K24: =SUMIF(庫!$B$2:$B$2999,B24,庫!$L$2:$L$2999)/1000 -> 10.17 | L24: =G24*H24 -> 0 | S24: =SUM(M24:R24) -> 0 | T24: =K24+L24-S24 -> 10.17
B25: FD2F6EK3 like | D25: Gloria | E25: 150/48/2 SR6 | F25: 7/25-8/10X | G25: 5 | H25: 2.3 | I25: FP82xxx | J25: 250/48 SR6 | K25: =SUMIF(庫!$B$2:$B$2999,B25,庫!$L$2:$L$2999)/1000 -> 0 | L25: =G25*H25 -> 11.5 | O25: 20 | Q25: 5 | S25: =SUM(M25:R25) -> 25 | T25: =K25+L25-S25 -> -13.5
A26: A19x | B26: FD2F43S2 | C26: 中噴, 共用 | D26: Clare | E26: 150/48 SDr | F26: 6/3-6/20X | H26: 2.5 | I26: FP82169R | J26: 255/48 SDR | K26: =SUMIF(庫!$B$2:$B$2999,B26,庫!$L$2:$L$2999)/1000 -> 25.41 | L26: =G26*H26 -> 0 | Q26: 10 | R26: 8.4 | S26: =SUM(M26:R26) -> 18.4 | T26: =K26+L26-S26 -> 7.01
K27: =SUMIF(庫!$B$2:$B$2999,B27,庫!$L$2:$L$2999)/1000 -> 0 | L27: =G27*H27 -> 0 | S27: =SUM(M27:R27) -> 0 | T27: =K27+L27-S27 -> 0
A28: A20x | K28: =SUMIF(庫!$B$2:$B$2999,B28,庫!$L$2:$L$2999)/1000 -> 0 | L28: =G28*H28 -> 0 | S28: =SUM(M28:R28) -> 0 | T28: =K28+L28-S28 -> 0
A29: A21x
B30: FD2F29I1 like | C30: OIA | D30: Gloria | E30: 100/36 SDr | F30: 7/17-8/2 | G30: 13 | H30: 2 | I30: FP81384R吃空 | J30: 170/36 SDR | K30: =SUMIF(庫!$B$2:$B$2999,B30,庫!$L$2:$L$2999)/1000 -> 0 | L30: =G30*H30 -> 26 | M30: 2 | O30: 20 | Q30: 10 | S30: =SUM(M30:R30) -> 32 | T30: =K30+L30-S30 -> -6
A31: A22 | B31: FD2F6IQ2 | C31: 20TA+AX? | D31: AL | E31: 150/48/2 CE | F31: 6/8-6/18X | H31: 2 | I31: FP02312 | J31: 250/48 CE | K31: =SUMIF(庫!$B$2:$B$2999,B31,庫!$L$2:$L$2999)/1000 -> 19.95 | L31: =G31*H31 -> 0 | S31: =SUM(M31:R31) -> 0 | T31: =K31+L31-S31 -> 19.95
B32: FD2F6IX1 | C32: AW28T, Clare | D32: Gloria | E32: 150/48/2 HC | F32: 6/25-7/15X | G32: 15 | H32: 2.3 | I32: FP82781 | J32: 250/48 HC | K32: =SUMIF(庫!$B$2:$B$2999,B32,庫!$L$2:$L$2999)/1000 -> 5.445 | L32: =G32*H32 -> 34.5 | O32: 20 | R32: 8 | S32: =SUM(M32:R32) -> 28 | T32: =K32+L32-S32 -> 11.945
A34: A23 | B34: FD2F43I1 | C34: Jimmy，冠齊純set中立包 | D34: B | E34: 150/48 SDR3 | F34: 4/21-4/30 | I34: FP82167R(L48 | J34: 255/48 SDR | K34: =SUMIF(庫!$B$2:$B$2999,B34,庫!$L$2:$L$2999)/1000 -> 2.1 | L34: =G34*H34 -> 0 | S34: =SUM(M34:R34) -> 0 | T34: =K34+L34-S34 -> 2.1
B36: FD2F6ID2 like | C36: wooly中噴W:5kg | D36: Gloria | E36: 150/48/2 SDR | F36: 7/16-7/31 | G36: 15 | H36: 2.5 | I36: FP82179R | J36: 255/48 SDR | L36: =G36*H36 -> 37.5 | S36: =SUM(M36:R36) -> 0 | T36: =K36+L36-S36 -> 37.5
A37: A24 色紗 | L37: =G37*H37 -> 0 | S37: =SUM(M37:R37) -> 0 | T37: =K37+L37-S37 -> 0
K38: =SUMIF(庫!$B$2:$B$2999,B38,庫!$L$2:$L$2999)/1000 -> 0 | L38: =G38*H38 -> 0 | S38: =SUM(M38:R38) -> 0 | T38: =K38+L38-S38 -> 0
A39: J07x | B39: X | K39: =SUMIF(庫!$B$2:$B$2999,B39,庫!$L$2:$L$2999)/1000 -> 0 | L39: =G39*H39 -> 0 | S39: =SUM(M39:R39) -> 0 | T39: =K39+L39-S39 -> 0
A40: J08 | B40: FD2F6IN2K | C40: YKK/80D外銷 | D40: YKK | E40: 150/48/2 SDr | F40: 6/3-6/21X | H40: 3.5 | I40: FP82175R(55B | J40: 255/48 SDR | K40: =SUMIF(庫!$B$2:$B$2999,B40,庫!$L$2:$L$2999)/1000 -> 14.091 | L40: =G40*H40 -> 0 | S40: =SUM(M40:R40) -> 0 | T40: =K40+L40-S40 -> 14.091
B41: FD2F6IV2K | C41: YKK/80D外銷 | D41: YKK | E41: 150/48/2 SDr | F41: 6/22-7/31 | G41: 30 | H41: 3.5 | I41: FP82180R(55B | J41: 255/48 SDR | K41: =SUMIF(庫!$B$2:$B$2999,B41,庫!$L$2:$L$2999)/1000 -> 31.68 | L41: =G41*H41 -> 105 | P41: 130 | S41: =SUM(M41:R41) -> 130 | T41: =K41+L41-S41 -> 6.68
A42: J09x | B42: X | K42: =SUMIF(庫!$B$2:$B$2999,B42,庫!$L$2:$L$2999)/1000 -> 0 | L42: =G42*H42 -> 0 | S42: =SUM(M42:R42) -> 0 | T42: =K42+L42-S42 -> 0
...

Sheet H
L1: 45968
A2: 案號 | B2: 訂單量(A、A1) | C2: 已訂未交量 | D2: POY批號 | E2: 開機日 | F2: 批號 | G2: 規格 | H2: 機號 | I2: 台數 | J2: 日產量(KG) | K2: 11/7庫存(KG) | L2: POY 庫存(KG) | M2: R
A3: F2566029 | B3: 50000 | C3: A級 :45,440.00 | D3: FP80119R | E3: 8/24停 | F3: FD2FZ7440 | G3: 50/72 SDR | H3: -- | I3: -- | J3: --- | K3: 19872 | L3: --- | M3: 828
F4: FD2G6ZA2 | K4: A1級: 779.03
C5: 45440- 9/5取消 25568 = 19872 (待出)
L9: 45968
A10: 案號 | B10: 訂單量(A、A1) | C10: 已訂未交量 | D10: POY批號 | E10: 開機日 | F10: 批號 | G10: 規格 | H10: 機號 | I10: 台數 | J10: 日產量(KG) | K10: 11/7庫存(KG) | L10: POY 庫存(KG) | M10: R+T
A11: F2576063 | B11: 150000 | C11: A級: 4,020.00 | D11: E00Q101 | E11: 7/15開 | F11: FD2F1ZI1 | G11: 75/144 SDR | H11: TMT | I11: 0.5 | J11: 800 | K11: 5913.71 | L11: 1680 | M11: 7+86
C12: AX級: 6,896.42 | F12: FD2G6ZA2 | K12: A1級: 779.03
L17: 45968
A18: 案號 | B18: 訂單量(A、A1) | C18: 已訂未交量 | D18: POY批號 | E18: 開機日 | F18: 批號 | G18: 規格 | H18: 機號 | I18: 台數 | J18: 日產量(KG) | K18: 11/7庫存(KG) | L18: POY 庫存(KG) | M18: R
A19: F24X6057 | B19: 120000 | C19: A級: 43,650.00 | D19: FP81234R | E19: 12/5 停 | F19: FD2FZ8010 | G19: 75/96/2 SDR | H19: -- | I19: -- | J19: --- | K19: 22440 | L19: --- | M19: 434+314
F20: FD2G6ZA2 | K20: A1級: 779.03
C21: 庫存 22440 出完,餘量再結案

Sheet R
A1: 遠東開機明細
L2: 46038
A3: 案號 | B3: 訂單量(A、A1) | C3: 已訂未交量 | D3: POY 數量 | E3: 預計開機日 | F3: 批號 | G3: 規格 | H3: 機號 | I3: 生產台數 | J3: 日產量(KG) | K3: 1/16庫存(KG) | L3: 備註
A4: F25X6008 | B4: 70000 | C4: A級:6176KG | D4: 代工 | E4: 11/28開 12/25停 | F4: FD2F1TC3X | G4: 75/36/1IBK | K4: 6816 | L4: 結批
C6: A級:23696KG | D6: 代工 | E6: 10/15開 11/30停 | F6: FD2F1MX1G | G6: 75/36/1ABK | K6: 0 | L6: 結批
E8: 合計 | K8: =SUM(K4:K7) -> 6816

Sheet 業
A1: sales | B1: DTY規格 | C1: DTY批號 | D1: 特性 | E1: 客戶 | F1: 用途 | G1: AX出貨 | H1: 倒筒 | I1: 包裝方式 | J1: Jul出貨需求 | K1: Aug出貨需求 | L1: Sep出貨需求
A2: AL | B2: 150/48/2 SDR | E2: YKK | J2: 800
A3: AL | B3: 75/24/2 SDR | C3: FD2F42T2K | E3: YKK | J3: 57
A4: AL | B4: 225/72/2 SDR | C4: FD2F7E03K | E4: YKK | J4: 37
A5: AL
A6: AL | B6: 150/48 SDR | C6: FD2F43A1 | E6: 內銷 | I6: 小包裝 | J6: 15
A7: AL | B7: 150/48 SDR | C7: FD2F43S2 | E7: 內銷 | I7: 小包裝 | J7: 10
A8: AL | B8: 150/48/2 SDR | C8: FD2F6IB1 | E8: 內銷 | I8: 小包裝 | J8: 10
A9: AL | B9: 150/48/2 SDR | C9: FD2F6ID2 | E9: 內銷 | I9: 小包裝 | J9: 15
A10: AL | B10: 150/48 SR6 | C10: FD2F41S3 | E10: 內銷 | I10: 小包裝 | J10: 5
A11: AL | B11: 150/48/2 SR6 | C11: FD2F6FJ3 | E11: 內銷 | I11: 小包裝 | J11: 5
A12: AL | B12: 150/48/2 FBKR | C12: FD2F6GQ3 | E12: 內銷 | I12: 小包裝 | J12: 5
A13: JH | B13: 100/72 PFR | C13: FD2F28R2G | E13: 調撥觀音 | F13: 針織 | G13: 無 | J13: 12 | K13: 3 | L13: 3
A14: JH | B14: 100/36 SDR | C14: FD2F28S1 | E14: 調撥觀音 | F14: 針織 | G14: 無 | J14: 1 | K14: 1 | L14: 1
A15: JH | B15: 150/48 SDR | C15: FD2F42Q1 | E15: 調撥觀音 | F15: 針織 | G15: 無 | J15: 2 | K15: 1 | L15: 1
A16: JH | B16: 150/48/2 SDR | C16: FD2F60181 | E16: 內銷/毅裕 | F16: 平織 | G16: 有 | J16: 10 | K16: 10 | L16: 10
A17: JH | B17: 50/36 SDR | C17: FD2F08G2 | E17: 調撥觀音 | F17: 針織 | G17: 無 | J17: 1 | K17: 0 | L17: 0
A18: JH | B18: 50/72 SDR | C18: FD2F20152 | E18: 調撥觀音 | F18: 針織 | G18: 無 | J18: 25 | K18: 20 | L18: 20
A19: JH | B19: 75/36 SDR | C19: FD2F1YQ2 | E19: 調撥觀音 | F19: 針織 | G19: 無 | J19: 3 | K19: 3 | L19: 3
A20: JH | B20: 75/72 SDFFR | C20: FD2F1HT2 | E20: 調撥觀音 | F20: 針織 | G20: 無 | J20: 1 | K20: 1 | L20: 1
A21: JH | B21: 75/72 SDR | C21: FD2F30372 | E21: 調撥觀音 | F21: 針織 | G21: 無 | J21: 40 | K21: 40 | L21: 40
A22: JH | B22: 75/72 SDR | C22: FD2F30372 | E22: 內銷/宏遠 | F22: 平織 | G22: 無
A23: JH | B23: 75/72/2 PDR | C23: FD2F42U2 | E23: 調撥觀音 | F23: 針織 | G23: 無 | J23: 10 | K23: 2 | L23: 2
A24: JH | B24: 75/72/2 SDR | C24: FD2F43R2 | E24: 調撥觀音 | F24: 針織 | G24: 無 | J24: 25 | K24: 20 | L24: 20
A25: Gloria | B25: 150/48 SDR | C25: FD2F40D1 | E25: 總成 | F25: 圓編 | G25: Y | H25: N | I25: 一般小包裝 | J25: 15
A26: Gloria | B26: 100/36 SDR | C26: FD2F28S1 | E26: 隆宏昌 | F26: 圓編 | G26: Y | H26: Y | I26: 一般小包裝 | J26: 20
A27: Gloria | B27: 150/48/2 SDR2 | C27: FD2F6DV2 | E27: 振泰/隆昌 | F27: 平織織帶 | G27: Y | H27: N | I27: 一般小包裝 | J27: 15
A28: Gloria | B28: 150/48 CDR | C28: FD2F41D2 | E28: 利勤 | F28: 經編 | G28: N | H28: Y | I28: 一般小包裝 | J28: 30
A29: Gloria | B29: 150/48/2 SR6 | C29: FD2F6EK3 | E29: Novalfa/Symaco | F29: 平織 | G29: N | H29: N | I29: HC大包裝 | J29: 20
A30: Gloria | B30: 75/72 SRR5 | C30: FD2F7C71 | E30: Toray | F30: 平織 | G30: Y | H30: N | I30: HC大包裝 | J30: 10
A31: Alex | B31: 150/48 SDR | C31: FD2F43M1 | E31: 均一等 | F31: 平 | G31: 出 | H31: 否 | J31: 15 | K31: 15 | L31: 15
A32: Alex | B32: 150/48 SDR | C32: FD2F43A1 | E32: 均一等 | F32: 平 | G32: 出 | H32: 否 | J32: 15 | K32: 15 | L32: 15
A33: Alex | B33: 150/48/2 SDR | C33: FD2F6ID2 | E33: 均一等 | F33: 平 | G33: 出 | H33: 否 | J33: 40 | K33: 40 | L33: 40
A34: Alex | B34: 150/48/2 SDR | C34: FD2F6IB1 | E34: 均一等 | F34: 平 | G34: 出 | H34: 否 | J34: 40 | K34: 40 | L34: 40
A35: Alex | B35: 75/36 BK | C35: FD2F1TC3Y | E35: 久杭 | F35: 平 | J35: 20 | K35: 66T單
A36: Alex | B36: 75/36 BK | C36: FD2F1MX1 | E36: 久杭 | F36: 平 | J36: 20 | K36: 60T單,6月初開始交貨
A37: Alex | B37: 150/48/2 HC | C37: FD2F6FD1 | E37: 久杭 | F37: 平 | G37: 出 | H37: 否 | J37: 20 | K37: 要開
A38: Alex
A39: Alex | B39: 150/48/2 SDR 經用 | C39: FD2F6GC2 | D39: 雙酚A<1PPM | E39: 富泰單 | F39: 平 | G39: 出 | H39: 否 | J39: 285 | K39: 3-6月平均出貨
A40: Alex | B40: 150/48/2 SDR 緯用 | C40: FD2F6FS1 | D40: 雙酚A<1PPM | E40: 富泰單 | F40: 平 | G40: 出 | H40: 否 | J40: 285 | K40: 3-6月平均出貨
...

Sheet 庫
A1: 產品類型 | B1: 成品批號 | C1: 規格 | D1: 等級 | E1: 儲位 | F1: 特性 | G1: 包裝 | H1: 繳庫重量 | I1: 繳庫數量 | J1: 出庫重量 | K1: 出庫數量 | L1: 2026/06/30結存重量(含鎖碼) | M1: 2026/06/30結存數量(含鎖碼)
A2: FD05KP01 | B2: FD2F01G2 | C2: 50d/24f KP | D2: A | E2: 8002 | F2: (ALEX)T結95/35(W:2.0) | G2: 6 | H2: 0 | I2: 0 | J2: 0 | K2: 0 | L2: 7992 | M2: 333
A3: FD05PB03 | B3: FD2F03S2 | C3: 50d/24f BP | D3: A | E3: 8002 | F3: (ANGELA)T結(W:3.0) | G3: 6 | H3: 0 | I3: 0 | J3: 0 | K3: 0 | L3: 1080 | M3: 45
A4: FD05RS05 | B4: FD2F04M1 | C4: 50d/72f SDRT | D4: A | E4: 8002 | F4: (ALEX)T結(W:4.0) | G4: 6 | H4: 0 | I4: 0 | J4: 0 | K4: 0 | L4: 5664 | M4: 236
A5: FD05PB03 | B5: FD2F04X2 | C5: 50d/24f BP | D5: A | E5: 8002 | F5: (ANGELA)T結(W:3.0) | G5: 6 | H5: 0 | I5: 0 | J5: 0 | K5: 0 | L5: 1416 | M5: 59
A6: FD05PB03 | B6: FD2F04X2C | C6: 50d/24f BP | D6: A | E6: 8002 | F6: (ANGELA)T結(W:1.5~2.0KG) | G6: 6 | H6: 0 | I6: 0 | J6: 0 | K6: 0 | L6: 1533 | M6: 73
A7: FD05PB03 | B7: FD2F04X2D | C7: 50d/24f BP | D7: A | E7: 8002 | F7: (ANGELA)T結(W:2.0~2.5KG) | G7: 6 | H7: 0 | I7: 0 | J7: 0 | K7: 0 | L7: 2568 | M7: 107
A8: FD05PB03 | B8: FD2F04X2E | C8: 50d/24f BP | D8: A | E8: 8002 | F8: (ANGELA)T結(W:2.5~3.0KG) | G8: 6 | H8: 0 | I8: 0 | J8: 0 | K8: 0 | L8: 3275 | M8: 131
A9: FD05PB03 | B9: FD2F05H2 | C9: 50d/24f BP | D9: A | E9: 8002 | F9: (ANGELA)T結(W:3.0) | G9: 6 | H9: 0 | I9: 0 | J9: 0 | K9: 0 | L9: 15576 | M9: 649
A10: FD05PB03 | B10: FD2F05P2 | C10: 50d/24f BP | D10: A | E10: 8002 | F10: (ANGELA)T結(W:3.0) | G10: 6 | H10: 0 | I10: 0 | J10: 0 | K10: 0 | L10: 8928 | M10: 372
A11: FD05PB03 | B11: FD2F05V2 | C11: 50d/24f BP | D11: A | E11: 8002 | F11: (ANGELA)T結(W:3.0) | G11: 6 | H11: 0 | I11: 0 | J11: 0 | K11: 0 | L11: 23784 | M11: 991
A12: FD05RC05 | B12: FD2F07A3S | C12: 50d/72f CDR | D12: A | E12: 8002 | F12: (PATTY)(W:2.0) | G12: 6 | H12: 0 | I12: 0 | J12: 0 | K12: 0 | L12: 1512 | M12: 63
A13: FD05RF02 | B13: FD2F07G2G | C13: 50d/72f FDR | D13: A | E13: 8002 | F13: (ANDY-L)T結(W:4.0) | G13: 6 | H13: 0 | I13: 0 | J13: 0 | K13: 0 | L13: 6096 | M13: 254
... A137: FD05F2C2 | B137: FD2F1YY2 | C137: 75d/72f F2FC | D137: A | E137: 8002 | F137: (PATTY)T結(W:3.0) | G137: 6 | H137: 0 | I137: 0 | J137: 288 | K137: 12 | L137: 0 | M137: 0
A138: FD05F2C2 | B138: FD2F1YY2G | C138: 75d/72f F2FC | D138: A | E138: 8001 | G138: 6 | H138: 0 | I138: 0 | J138: 144 | K138: 6 | L138: 0 | M138: 0
A139: FD05F2C2 | B139: FD2F1YY2G | C139: 75d/72f F2FC | D139: A | E139: 8002 | G139: 6 | H139: 0 | I139: 0 | J139: 552 | K139: 23 | L139: 0 | M139: 0
A140: FD05VRS05 | B140: FD2F20152 | C140: 50d/72f SDR | D140: A | E140: 8001 | F140: (W:4.0)PT20152 | G140: 6 | H140: 0 | I140: 0 | J140: 144 | K140: 6 | L140: 0 | M140: 0
A141: FD05VRS05 | B141: FD2F20152 | C141: 50d/72f SDR | D141: A | E141: 8002 | F141: (W:4.0)PT20152 | G141: 6 | H141: 0 | I141: 0 | J141: 20400 | K141: 850 | L141: 7200 | M141: 300
A142: FD05RO10 | B142: FD2F21Z2R | C142: 100d/36f SDRO | D142: A | E142: 8002 | F142: (共用)T結(W:5.0) | G142: 6 | H142: 0 | I142: 0 | J142: 0 | K142: 0 | L142: 3930 | M142: 131
A143: FD05RO10 | B143: FD2F23I2U | C143: 100d/36f SDRO | D143: A | E143: 8002 | F143: (PHILIP)T結(W:5.0)倒筒 | G143: 6 | H143: 0 | I143: 0 | J143: 0 | K143: 0 | L143: 6990 | M143: 233
A144: FD05OC04 | B144: FD2F23K2 | C144: 100d/36f CDRO | D144: A | E144: 8002 | F144: (PHILIP)S結(W:4.0) | G144: 6 | H144: 0 | I144: 0 | J144: 0 | K144: 0 | L144: 8184 | M144: 341
A145: FD05RO10 | B145: FD2F23L2U | C145: 100d/36f SDRO | D145: A | E145: 8002 | F145: (PHILIP)T結(W:5.0)倒筒 | G145: 6 | H145: 0 | I145: 0 | J145: 0 | K145: 0 | L145: 3750 | M145: 125
A146: FD05RSC2 | B146: FD2F24H2 | C146: 100d/144f SCTR | D146: A | E146: 8002 | F146: (KAI)T結(W:3.0) | G146: 6 | H146: 0 | I146: 0 | J146: 0 | K146: 0 | L146: 3672 | M146: 153
A147: FD05RS03 | B147: FD2F24P2 | C147: 100d/96f SDR | D147: A | E147: 8002 | F147: (ANGELA)T結(W:5.0) | G147: 6 | H147: 0 | I147: 0 | J147: 0 | K147: 0 | L147: 3900 | M147: 130
A148: FD05SFR2 | B148: FD2F25R2 | C148: 50d/72f/2 SDFFR | D148: A | E148: 8002 | F148: (織染)T結(W:4.0) | G148: 6 | H148: 0 | I148: 0 | J148: 0 | K148: 0 | L148: 192 | M148: 8
A149: FD05RO10 | B149: FD2F26G2 | C149: 100d/96f SDRO | D149: A | E149: 8002 | F149: (JIMMY)T結(W:5.0) | G149: 6 | H149: 0 | I149: 0 | J149: 0 | K149: 0 | L149: 4110 | M149: 137
A150: FD05RS07 | B150: FD2F26W2G | C150: 50d/72f/2 SDR | D150: A | E150: 8002 | F150: (ANDY-L)T結(W:4.0) | G150: 6 | H150: 0 | I150: 0 | J150: 0 | K150: 0 | L150: 4368 | M150: 182
A151: FD05BS08 | B151: FD2F26Z2 | C151: 100d/36f BSD3 | D151: A | E151: 8002 | F151: (ALEX)T結(W:5.0) | G151: 6 | H151: 0 | I151: 0 | J151: 0 | K151: 0 | L151: 7890 | M151: 263
... A155: FD05PFR1 | B155: FD2F27Q2R | C155: 100d/72f PFR | D155: A | E155: 8002 | F155: (PATTY.織染)S結(W:4.0)倒筒 | G155: 6 | H155: 0 | I155: 0 | J155: 0 | K155: 0 | L155: 4200 | M155: 175
A156: FD05PFR1 | B156: FD2F27X2R | C156: 100d/72f PFR | D156: A | E156: 8002 | G156: 6 | H156: 0 | I156: 0 | J156: 0 | K156: 0 | L156: 3216 | M156: 134
A157: FD05PFR1 | B157: FD2F28A2R | C157: 100d/72f PFR | D157: A | E157: 8002 | F157: (PATTY)T結(W:4.0)倒筒 | G157: 6 | H157: 0 | I157: 0 | J157: 0 | K157: 0 | L157: 7152 | M157: 298
A158: FD05PFR1 | B158: FD2F28A2T | C158: 100d/72f PFR | D158: A | E158: 8002 | F158: (PATTY)T結(W:4.0)倒筒 | G158: 6 | H158: 0 | I158: 0 | J158: 0 | K158: 0 | L158: 5712 | M158: 238
A159: FD05PFR1 | B159: FD2F28C2R | C159: 100d/72f PFR | D159: A | E159: 8002 | F159: (PATTY)T結(W:4.0)倒筒 | G159: 6 | H159: 1968 | I159: 82 | J159: 0 | K159: 0 | L159: 2568 | M159: 107
A160: FD05PFR1 | B160: FD2F28C2S | C160: 100d/72f PFR | D160: A | E160: 8002 | F160: (PATTY)(W:2.0) | G160: 6 | H160: 0 | I160: 0 | J160: 0 | K160: 0 | L160: 3936 | M160: 164
A161: FD05PFR1 | B161: FD2F28C2T | C161: 100d/72f PFR | D161: A | E161: 8002 | F161: (PATTY)T結(W:4.0)倒筒 | G161: 6 | H161: 1200 | I161: 50 | J161: 0 | K161: 0 | L161: 1200 | M161: 50
A162: FD05PFR1 | B162: FD2F28F2R | C162: 100d/72f PFR | D162: A | E162: 8002 | F162: (PATTY)T結(W:4.0)倒筒 | G162: 6 | H162: 0 | I162: 0 | J162: 0 | K162: 0 | L162: 3624 | M162: 151
A163: FD05PFR1 | B163: FD2F28F2T | C163: 100d/72f PFR | D163: A | E163: 8002 | F163: (PATTY)T結(W:4.0)倒筒 | G163: 6 | H163: 0 | I163: 0 | J163: 0 | K163: 0 | L163: 3336 | M163: 139
A164: FD05PFR1 | B164: FD2F28M2R | C164: 100d/72f PFR | D164: A | E164: 8002 | F164: (PATTY)T結(W:4.0)倒筒 | G164: 6 | H164: 0 | I164: 0 | J164: 0 | K164: 0 | L164: 1800 | M164: 75
A165: FD05PFR1 | B165: FD2F28M2T | C165: 100d/72f PFR | D165: A | E165: 8002 | F165: (PATTY)T結(W:4.0)倒筒 | G165: 6 | H165: 0 | I165: 0 | J165: 0 | K165: 0 | L165: 1032 | M165: 43
A166: FD05PFR1 | B166: FD2F28N2R | C166: 100d/72f PFR | D166: A | E166: 8002 | F166: (PATTY)T結(W:4.0)倒筒 | G166: 6 | H166: 0 | I166: 0 | J166: 0 | K166: 0 | L166: 2760 | M166: 115
...

Sheet 配置
D1: 7
D2: 8
D3: 9
A4: AFK | B4: 22 | C4: 16 | D4: 10
B5: 23 | C5: 17 | D5: 11
B6: 24 | C6: 18 | D6: 12
