Workbook
Name DTY紙管: [1]清單!$S$2:$S$100
Name 生產項目: [2]清單!$M$2:$M$36
Name 值車員A: [3]清單!$E$2:$E$27
Name 值車員J: [3]清單!$F$2:$F$12
Name 值車員M_S: [3]清單!$G$2:$G$20
Name 傳閱: 日報表!#REF!
Name 傳閱: [4]日報表!#REF!
Name 傳閱: [5]日報表!#REF!
Name 傳閱: 日報表!#REF!

Sheet M80(20250122封存)
A1: 自2010/11起原絲丹尼÷DR再×1.8% | CY1: ='實驗紗&非當月生產'!P2 -> 886641
C2: 113 | F2: 114 | I2: 115 | L2: 116 | O2: 117 | R2: 118 | U2: 119 | X2: 120 | AA2: 121 | AD2: 122 | AG2: 123 | AJ2: 124 | AM2: 125 | AP2: 126 | AS2: 127 | AV2: 128 | AY2: 129 | BB2: 130 | BE2: 131 | BH2: 132 | BK2: 133 | BN2: 134 | BQ2: 135 | BT2: 136 | BW2: 137 | BZ2: 138 | CC2: 139 | CF2: 140 | CI2: 141 | CL2: 142 | CO2: 143 | CR2: 144 | CU2: 145
A3: Lot no.
A4: Speed
A5: Date | B5: 台數 | C5: 理論 | D5: 實際 | E5: 台數 | F5: 理論 | G5: 實際 | H5: 台數 | I5: 理論 | J5: 實際 | K5: 台數 | L5: 理論 | M5: 實際 | N5: 台數 | O5: 理論 | P5: 實際 | Q5: 台數 | R5: 理論 | S5: 實際 | T5: 台數 | U5: 理論 | V5: 實際 | W5: 台數 | X5: 理論 | Y5: 實際 | Z5: 台數 | AA5: 理論 | AB5: 實際 | AC5: 台數 | AD5: 理論 | AE5: 實際 | AF5: 台數 | AG5: 理論 | AH5: 實際 | AI5: 台數 | AJ5: 理論 | AK5: 實際 | AL5: 台數 | AM5: 理論 | AN5: 實際 | AO5: 台數 | AP5: 理論 | AQ5: 實際 | AR5: 台數 | AS5: 理論 | AT5: 實際 | AU5: 台數 | AV5: 理論 | AW5: 實際 | AX5: 台數 | AY5: 理論 | AZ5: 實際 | BA5: 台數 | BB5: 理論 | BC5: 實際 | BD5: 台數 | BE5: 理論 | BF5: 實際 | BG5: 台數 | BH5: 理論 | BI5: 實際 | BJ5: 台數 | BK5: 理論 | BL5: 實際 | BM5: 台數 | BN5: 理論 | BO5: 實際 | BP5: 台數 | BQ5: 理論 | BR5: 實際 | BS5: 台數 | BT5: 理論 | BU5: 實際 | BV5: 台數 | BW5: 理論 | BX5: 實際 | BY5: 台數 | BZ5: 理論 | CA5: 實際 | CB5: 台數 | CC5: 理論 | CD5: 實際 | CE5: 台數 | CF5: 理論 | CG5: 實際 | CH5: 台數 | CI5: 理論 | CJ5: 實際 | CK5: 台數 | CL5: 理論 | CM5: 實際 | CN5: 台數 | CO5: 理論 | CP5: 實際 | CQ5: 台數 | CR5: 理論 | CS5: 實際 | CT5: 台數 | CU5: 理論 | CV5: 實際
A6: 1 | C6: =D$3*D$4*216*24*60*B6/9000000 -> 0 | F6: =G$3*G$4*216*24*60*E6/9000000 -> 0 | I6: =J$3*J$4*216*24*60*H6/9000000 -> 0 | L6: =M$3*M$4*216*24*60*K6/9000000 -> 0 | O6: =P$3*P$4*216*24*60*N6/9000000 -> 0 | R6: =S$3*S$4*216*24*60*Q6/9000000 -> 0 | U6: =V$3*V$4*216*24*60*T6/9000000 -> 0 | X6: =Y$3*Y$4*216*24*60*W6/9000000 -> 0 | AA6: =AB$3*AB$4*216*24*60*Z6/9000000 -> 0 | AD6: =AE$3*AE$4*216*24*60*AC6/9000000 -> 0 | AG6: =AH$3*AH$4*216*24*60*AF6/9000000 -> 0 | AJ6: =AK$3*AK$4*216*24*60*AI6/9000000 -> 0 | AM6: =AN$3*AN$4*216*24*60*AL6/9000000 -> 0 | AP6: =AQ$3*AQ$4*216*24*60*AO6/9000000 -> 0 | AS6: =AT$3*AT$4*216*24*60*AR6/9000000 -> 0 | AV6: =AW$3*AW$4*216*24*60*AU6/9000000 -> 0 | AY6: =AZ$3*AZ$4*216*24*60*AX6/9000000 -> 0 | BB6: =BC$3*BC$4*216*24*60*BA6/9000000 -> 0 | BE6: =BF$3*BF$4*216*24*60*BD6/9000000 -> 0 | BH6: =BI$3*BI$4*216*24*60*BG6/9000000 -> 0 | BK6: =BL$3*BL$4*216*24*60*BJ6/9000000 -> 0 | BN6: =BO$3*BO$4*216*24*60*BM6/9000000 -> 0 | BQ6: =BR$3*BR$4*216*24*60*BP6/9000000 -> 0 | BT6: =BU$3*BU$4*216*24*60*BS6/9000000 -> 0 | BW6: =BX$3*BX$4*216*24*60*BV6/9000000 -> 0 | BZ6: =CA$3*CA$4*216*24*60*BY6/9000000 -> 0 | CC6: =CD$3*CD$4*216*24*60*CB6/9000000 -> 0 | CF6: =CG$3*CG$4*216*24*60*CE6/9000000 -> 0 | CI6: =CJ$3*CJ$4*216*24*60*CH6/9000000 -> 0 | CL6: =CM$3*CM$4*216*24*60*CK6/9000000 -> 0 | CO6: =CP$3*CP$4*216*24*60*CN6/9000000 -> 0 | CR6: =CS$3*CS$4*216*24*60*CQ6/9000000 -> 0 | CU6: =CV$3*CV$4*216*24*60*CT6/9000000 -> 0 | CX6: =B6+E6+H6+K6+N6+Q6+T6+W6+Z6+AC6+AF6+AI6+AL6+AO6+AR6+AU6+AX6+BA6+BD6+BG6+BJ6+BM6+BP6+BS6+BV6+BY6+CB6+CE6+CH6+CK6+CN6+CQ6+CT6 -> 0
A7: 2 | C7: =D$3*D$4*216*24*60*B7/9000000 -> 0 | F7: =G$3*G$4*216*24*60*E7/9000000 -> 0 | I7: =J$3*J$4*216*24*60*H7/9000000 -> 0 | L7: =M$3*M$4*216*24*60*K7/9000000 -> 0 | O7: =P$3*P$4*216*24*60*N7/9000000 -> 0 | R7: =S$3*S$4*216*24*60*Q7/9000000 -> 0 | U7: =V$3*V$4*216*24*60*T7/9000000 -> 0 | X7: =Y$3*Y$4*216*24*60*W7/9000000 -> 0 | AA7: =AB$3*AB$4*216*24*60*Z7/9000000 -> 0 | AD7: =AE$3*AE$4*216*24*60*AC7/9000000 -> 0 | AG7: =AH$3*AH$4*216*24*60*AF7/9000000 -> 0 | AJ7: =AK$3*AK$4*216*24*60*AI7/9000000 -> 0 | AM7: =AN$3*AN$4*216*24*60*AL7/9000000 -> 0 | AP7: =AQ$3*AQ$4*216*24*60*AO7/9000000 -> 0 | AS7: =AT$3*AT$4*216*24*60*AR7/9000000 -> 0 | AV7: =AW$3*AW$4*216*24*60*AU7/9000000 -> 0 | AY7: =AZ$3*AZ$4*216*24*60*AX7/9000000 -> 0 | BB7: =BC$3*BC$4*216*24*60*BA7/9000000 -> 0 | BE7: =BF$3*BF$4*216*24*60*BD7/9000000 -> 0 | BH7: =BI$3*BI$4*216*24*60*BG7/9000000 -> 0 | BK7: =BL$3*BL$4*216*24*60*BJ7/9000000 -> 0 | BN7: =BO$3*BO$4*216*24*60*BM7/9000000 -> 0 | BQ7: =BR$3*BR$4*216*24*60*BP7/9000000 -> 0 | BT7: =BU$3*BU$4*216*24*60*BS7/9000000 -> 0 | BW7: =BX$3*BX$4*216*24*60*BV7/9000000 -> 0 | BZ7: =CA$3*CA$4*216*24*60*BY7/9000000 -> 0 | CC7: =CD$3*CD$4*216*24*60*CB7/9000000 -> 0 | CF7: =CG$3*CG$4*216*24*60*CE7/9000000 -> 0 | CI7: =CJ$3*CJ$4*216*24*60*CH7/9000000 -> 0 | CL7: =CM$3*CM$4*216*24*60*CK7/9000000 -> 0 | CO7: =CP$3*CP$4*216*24*60*CN7/9000000 -> 0 | CR7: =CS$3*CS$4*216*24*60*CQ7/9000000 -> 0 | CU7: =CV$3*CV$4*216*24*60*CT7/9000000 -> 0 | CX7: =B7+E7+H7+K7+N7+Q7+T7+W7+Z7+AC7+AF7+AI7+AL7+AO7+AR7+AU7+AX7+BA7+BD7+BG7+BJ7+BM7+BP7+BS7+BV7+BY7+CB7+CE7+CH7+CK7+CN7+CQ7+CT7 -> 0
A8: 3 | C8: =D$3*D$4*216*24*60*B8/9000000 -> 0 | F8: =G$3*G$4*216*24*60*E8/9000000 -> 0 | I8: =J$3*J$4*216*24*60*H8/9000000 -> 0 | L8: =M$3*M$4*216*24*60*K8/9000000 -> 0 | O8: =P$3*P$4*216*24*60*N8/9000000 -> 0 | R8: =S$3*S$4*216*24*60*Q8/9000000 -> 0 | U8: =V$3*V$4*216*24*60*T8/9000000 -> 0 | X8: =Y$3*Y$4*216*24*60*W8/9000000 -> 0 | AA8: =AB$3*AB$4*216*24*60*Z8/9000000 -> 0 | AD8: =AE$3*AE$4*216*24*60*AC8/9000000 -> 0 | AG8: =AH$3*AH$4*216*24*60*AF8/9000000 -> 0 | AJ8: =AK$3*AK$4*216*24*60*AI8/9000000 -> 0 | AM8: =AN$3*AN$4*216*24*60*AL8/9000000 -> 0 | AP8: =AQ$3*AQ$4*216*24*60*AO8/9000000 -> 0 | AS8: =AT$3*AT$4*216*24*60*AR8/9000000 -> 0 | AV8: =AW$3*AW$4*216*24*60*AU8/9000000 -> 0 | AY8: =AZ$3*AZ$4*216*24*60*AX8/9000000 -> 0 | BB8: =BC$3*BC$4*216*24*60*BA8/9000000 -> 0 | BE8: =BF$3*BF$4*216*24*60*BD8/9000000 -> 0 | BH8: =BI$3*BI$4*216*24*60*BG8/9000000 -> 0 | BK8: =BL$3*BL$4*216*24*60*BJ8/9000000 -> 0 | BN8: =BO$3*BO$4*216*24*60*BM8/9000000 -> 0 | BQ8: =BR$3*BR$4*216*24*60*BP8/9000000 -> 0 | BT8: =BU$3*BU$4*216*24*60*BS8/9000000 -> 0 | BW8: =BX$3*BX$4*216*24*60*BV8/9000000 -> 0 | BZ8: =CA$3*CA$4*216*24*60*BY8/9000000 -> 0 | CC8: =CD$3*CD$4*216*24*60*CB8/9000000 -> 0 | CF8: =CG$3*CG$4*216*24*60*CE8/9000000 -> 0 | CI8: =CJ$3*CJ$4*216*24*60*CH8/9000000 -> 0 | CL8: =CM$3*CM$4*216*24*60*CK8/9000000 -> 0 | CO8: =CP$3*CP$4*216*24*60*CN8/9000000 -> 0 | CR8: =CS$3*CS$4*216*24*60*CQ8/9000000 -> 0 | CU8: =CV$3*CV$4*216*24*60*CT8/9000000 -> 0 | CX8: =B8+E8+H8+K8+N8+Q8+T8+W8+Z8+AC8+AF8+AI8+AL8+AO8+AR8+AU8+AX8+BA8+BD8+BG8+BJ8+BM8+BP8+BS8+BV8+BY8+CB8+CE8+CH8+CK8+CN8+CQ8+CT8 -> 0
A9: 4 | C9: =D$3*D$4*216*24*60*B9/9000000 -> 0 | F9: =G$3*G$4*216*24*60*E9/9000000 -> 0 | I9: =J$3*J$4*216*24*60*H9/9000000 -> 0 | L9: =M$3*M$4*216*24*60*K9/9000000 -> 0 | O9: =P$3*P$4*216*24*60*N9/9000000 -> 0 | R9: =S$3*S$4*216*24*60*Q9/9000000 -> 0 | U9: =V$3*V$4*216*24*60*T9/9000000 -> 0 | X9: =Y$3*Y$4*216*24*60*W9/9000000 -> 0 | AA9: =AB$3*AB$4*216*24*60*Z9/9000000 -> 0 | AD9: =AE$3*AE$4*216*24*60*AC9/9000000 -> 0 | AG9: =AH$3*AH$4*216*24*60*AF9/9000000 -> 0 | AJ9: =AK$3*AK$4*216*24*60*AI9/9000000 -> 0 | AM9: =AN$3*AN$4*216*24*60*AL9/9000000 -> 0 | AP9: =AQ$3*AQ$4*216*24*60*AO9/9000000 -> 0 | AS9: =AT$3*AT$4*216*24*60*AR9/9000000 -> 0 | AV9: =AW$3*AW$4*216*24*60*AU9/9000000 -> 0 | AY9: =AZ$3*AZ$4*216*24*60*AX9/9000000 -> 0 | BB9: =BC$3*BC$4*216*24*60*BA9/9000000 -> 0 | BE9: =BF$3*BF$4*216*24*60*BD9/9000000 -> 0 | BH9: =BI$3*BI$4*216*24*60*BG9/9000000 -> 0 | BK9: =BL$3*BL$4*216*24*60*BJ9/9000000 -> 0 | BN9: =BO$3*BO$4*216*24*60*BM9/9000000 -> 0 | BQ9: =BR$3*BR$4*216*24*60*BP9/9000000 -> 0 | BT9: =BU$3*BU$4*216*24*60*BS9/9000000 -> 0 | BW9: =BX$3*BX$4*216*24*60*BV9/9000000 -> 0 | BZ9: =CA$3*CA$4*216*24*60*BY9/9000000 -> 0 | CC9: =CD$3*CD$4*216*24*60*CB9/9000000 -> 0 | CF9: =CG$3*CG$4*216*24*60*CE9/9000000 -> 0 | CI9: =CJ$3*CJ$4*216*24*60*CH9/9000000 -> 0 | CL9: =CM$3*CM$4*216*24*60*CK9/9000000 -> 0 | CO9: =CP$3*CP$4*216*24*60*CN9/9000000 -> 0 | CR9: =CS$3*CS$4*216*24*60*CQ9/9000000 -> 0 | CU9: =CV$3*CV$4*216*24*60*CT9/9000000 -> 0 | CX9: =B9+E9+H9+K9+N9+Q9+T9+W9+Z9+AC9+AF9+AI9+AL9+AO9+AR9+AU9+AX9+BA9+BD9+BG9+BJ9+BM9+BP9+BS9+BV9+BY9+CB9+CE9+CH9+CK9+CN9+CQ9+CT9 -> 0
A10: 5 | C10: =D$3*D$4*216*24*60*B10/9000000 -> 0 | F10: =G$3*G$4*216*24*60*E10/9000000 -> 0 | I10: =J$3*J$4*216*24*60*H10/9000000 -> 0 | L10: =M$3*M$4*216*24*60*K10/9000000 -> 0 | O10: =P$3*P$4*216*24*60*N10/9000000 -> 0 | R10: =S$3*S$4*216*24*60*Q10/9000000 -> 0 | U10: =V$3*V$4*216*24*60*T10/9000000 -> 0 | X10: =Y$3*Y$4*216*24*60*W10/9000000 -> 0 | AA10: =AB$3*AB$4*216*24*60*Z10/9000000 -> 0 | AD10: =AE$3*AE$4*216*24*60*AC10/9000000 -> 0 | AG10: =AH$3*AH$4*216*24*60*AF10/9000000 -> 0 | AJ10: =AK$3*AK$4*216*24*60*AI10/9000000 -> 0 | AM10: =AN$3*AN$4*216*24*60*AL10/9000000 -> 0 | AP10: =AQ$3*AQ$4*216*24*60*AO10/9000000 -> 0 | AS10: =AT$3*AT$4*216*24*60*AR10/9000000 -> 0 | AV10: =AW$3*AW$4*216*24*60*AU10/9000000 -> 0 | AY10: =AZ$3*AZ$4*216*24*60*AX10/9000000 -> 0 | BB10: =BC$3*BC$4*216*24*60*BA10/9000000 -> 0 | BE10: =BF$3*BF$4*216*24*60*BD10/9000000 -> 0 | BH10: =BI$3*BI$4*216*24*60*BG10/9000000 -> 0 | BK10: =BL$3*BL$4*216*24*60*BJ10/9000000 -> 0 | BN10: =BO$3*BO$4*216*24*60*BM10/9000000 -> 0 | BQ10: =BR$3*BR$4*216*24*60*BP10/9000000 -> 0 | BT10: =BU$3*BU$4*216*24*60*BS10/9000000 -> 0 | BW10: =BX$3*BX$4*216*24*60*BV10/9000000 -> 0 | BZ10: =CA$3*CA$4*216*24*60*BY10/9000000 -> 0 | CC10: =CD$3*CD$4*216*24*60*CB10/9000000 -> 0 | CF10: =CG$3*CG$4*216*24*60*CE10/9000000 -> 0 | CI10: =CJ$3*CJ$4*216*24*60*CH10/9000000 -> 0 | CL10: =CM$3*CM$4*216*24*60*CK10/9000000 -> 0 | CO10: =CP$3*CP$4*216*24*60*CN10/9000000 -> 0 | CR10: =CS$3*CS$4*216*24*60*CQ10/9000000 -> 0 | CU10: =CV$3*CV$4*216*24*60*CT10/9000000 -> 0 | CX10: =B10+E10+H10+K10+N10+Q10+T10+W10+Z10+AC10+AF10+AI10+AL10+AO10+AR10+AU10+AX10+BA10+BD10+BG10+BJ10+BM10+BP10+BS10+BV10+BY10+CB10+CE10+CH10+CK10+CN10+CQ10+CT10 -> 0
A11: 6 | C11: =D$3*D$4*216*24*60*B11/9000000 -> 0 | F11: =G$3*G$4*216*24*60*E11/9000000 -> 0 | I11: =J$3*J$4*216*24*60*H11/9000000 -> 0 | L11: =M$3*M$4*216*24*60*K11/9000000 -> 0 | O11: =P$3*P$4*216*24*60*N11/9000000 -> 0 | R11: =S$3*S$4*216*24*60*Q11/9000000 -> 0 | U11: =V$3*V$4*216*24*60*T11/9000000 -> 0 | X11: =Y$3*Y$4*216*24*60*W11/9000000 -> 0 | AA11: =AB$3*AB$4*216*24*60*Z11/9000000 -> 0 | AD11: =AE$3*AE$4*216*24*60*AC11/9000000 -> 0 | AG11: =AH$3*AH$4*216*24*60*AF11/9000000 -> 0 | AJ11: =AK$3*AK$4*216*24*60*AI11/9000000 -> 0 | AM11: =AN$3*AN$4*216*24*60*AL11/9000000 -> 0 | AP11: =AQ$3*AQ$4*216*24*60*AO11/9000000 -> 0 | AS11: =AT$3*AT$4*216*24*60*AR11/9000000 -> 0 | AV11: =AW$3*AW$4*216*24*60*AU11/9000000 -> 0 | AY11: =AZ$3*AZ$4*216*24*60*AX11/9000000 -> 0 | BB11: =BC$3*BC$4*216*24*60*BA11/9000000 -> 0 | BE11: =BF$3*BF$4*216*24*60*BD11/9000000 -> 0 | BH11: =BI$3*BI$4*216*24*60*BG11/9000000 -> 0 | BK11: =BL$3*BL$4*216*24*60*BJ11/9000000 -> 0 | BN11: =BO$3*BO$4*216*24*60*BM11/9000000 -> 0 | BQ11: =BR$3*BR$4*216*24*60*BP11/9000000 -> 0 | BT11: =BU$3*BU$4*216*24*60*BS11/9000000 -> 0 | BW11: =BX$3*BX$4*216*24*60*BV11/9000000 -> 0 | BZ11: =CA$3*CA$4*216*24*60*BY11/9000000 -> 0 | CC11: =CD$3*CD$4*216*24*60*CB11/9000000 -> 0 | CF11: =CG$3*CG$4*216*24*60*CE11/9000000 -> 0 | CI11: =CJ$3*CJ$4*216*24*60*CH11/9000000 -> 0 | CL11: =CM$3*CM$4*216*24*60*CK11/9000000 -> 0 | CO11: =CP$3*CP$4*216*24*60*CN11/9000000 -> 0 | CR11: =CS$3*CS$4*216*24*60*CQ11/9000000 -> 0 | CU11: =CV$3*CV$4*216*24*60*CT11/9000000 -> 0 | CX11: =B11+E11+H11+K11+N11+Q11+T11+W11+Z11+AC11+AF11+AI11+AL11+AO11+AR11+AU11+AX11+BA11+BD11+BG11+BJ11+BM11+BP11+BS11+BV11+BY11+CB11+CE11+CH11+CK11+CN11+CQ11+CT11 -> 0
A12: 7 | C12: =D$3*D$4*216*24*60*B12/9000000 -> 0 | F12: =G$3*G$4*216*24*60*E12/9000000 -> 0 | I12: =J$3*J$4*216*24*60*H12/9000000 -> 0 | L12: =M$3*M$4*216*24*60*K12/9000000 -> 0 | O12: =P$3*P$4*216*24*60*N12/9000000 -> 0 | R12: =S$3*S$4*216*24*60*Q12/9000000 -> 0 | U12: =V$3*V$4*216*24*60*T12/9000000 -> 0 | X12: =Y$3*Y$4*216*24*60*W12/9000000 -> 0 | AA12: =AB$3*AB$4*216*24*60*Z12/9000000 -> 0 | AD12: =AE$3*AE$4*216*24*60*AC12/9000000 -> 0 | AG12: =AH$3*AH$4*216*24*60*AF12/9000000 -> 0 | AJ12: =AK$3*AK$4*216*24*60*AI12/9000000 -> 0 | AM12: =AN$3*AN$4*216*24*60*AL12/9000000 -> 0 | AP12: =AQ$3*AQ$4*216*24*60*AO12/9000000 -> 0 | AS12: =AT$3*AT$4*216*24*60*AR12/9000000 -> 0 | AV12: =AW$3*AW$4*216*24*60*AU12/9000000 -> 0 | AY12: =AZ$3*AZ$4*216*24*60*AX12/9000000 -> 0 | BB12: =BC$3*BC$4*216*24*60*BA12/9000000 -> 0 | BE12: =BF$3*BF$4*216*24*60*BD12/9000000 -> 0 | BH12: =BI$3*BI$4*216*24*60*BG12/9000000 -> 0 | BK12: =BL$3*BL$4*216*24*60*BJ12/9000000 -> 0 | BN12: =BO$3*BO$4*216*24*60*BM12/9000000 -> 0 | BQ12: =BR$3*BR$4*216*24*60*BP12/9000000 -> 0 | BT12: =BU$3*BU$4*216*24*60*BS12/9000000 -> 0 | BW12: =BX$3*BX$4*216*24*60*BV12/9000000 -> 0 | BZ12: =CA$3*CA$4*216*24*60*BY12/9000000 -> 0 | CC12: =CD$3*CD$4*216*24*60*CB12/9000000 -> 0 | CF12: =CG$3*CG$4*216*24*60*CE12/9000000 -> 0 | CI12: =CJ$3*CJ$4*216*24*60*CH12/9000000 -> 0 | CL12: =CM$3*CM$4*216*24*60*CK12/9000000 -> 0 | CO12: =CP$3*CP$4*216*24*60*CN12/9000000 -> 0 | CR12: =CS$3*CS$4*216*24*60*CQ12/9000000 -> 0 | CU12: =CV$3*CV$4*216*24*60*CT12/9000000 -> 0 | CX12: =B12+E12+H12+K12+N12+Q12+T12+W12+Z12+AC12+AF12+AI12+AL12+AO12+AR12+AU12+AX12+BA12+BD12+BG12+BJ12+BM12+BP12+BS12+BV12+BY12+CB12+CE12+CH12+CK12+CN12+CQ12+CT12 -> 0
A13: 8 | C13: =D$3*D$4*216*24*60*B13/9000000 -> 0 | F13: =G$3*G$4*216*24*60*E13/9000000 -> 0 | I13: =J$3*J$4*216*24*60*H13/9000000 -> 0 | L13: =M$3*M$4*216*24*60*K13/9000000 -> 0 | O13: =P$3*P$4*216*24*60*N13/9000000 -> 0 | R13: =S$3*S$4*216*24*60*Q13/9000000 -> 0 | U13: =V$3*V$4*216*24*60*T13/9000000 -> 0 | X13: =Y$3*Y$4*216*24*60*W13/9000000 -> 0 | AA13: =AB$3*AB$4*216*24*60*Z13/9000000 -> 0 | AD13: =AE$3*AE$4*216*24*60*AC13/9000000 -> 0 | AG13: =AH$3*AH$4*216*24*60*AF13/9000000 -> 0 | AJ13: =AK$3*AK$4*216*24*60*AI13/9000000 -> 0 | AM13: =AN$3*AN$4*216*24*60*AL13/9000000 -> 0 | AP13: =AQ$3*AQ$4*216*24*60*AO13/9000000 -> 0 | AS13: =AT$3*AT$4*216*24*60*AR13/9000000 -> 0 | AV13: =AW$3*AW$4*216*24*60*AU13/9000000 -> 0 | AY13: =AZ$3*AZ$4*216*24*60*AX13/9000000 -> 0 | BB13: =BC$3*BC$4*216*24*60*BA13/9000000 -> 0 | BE13: =BF$3*BF$4*216*24*60*BD13/9000000 -> 0 | BH13: =BI$3*BI$4*216*24*60*BG13/9000000 -> 0 | BK13: =BL$3*BL$4*216*24*60*BJ13/9000000 -> 0 | BN13: =BO$3*BO$4*216*24*60*BM13/9000000 -> 0 | BQ13: =BR$3*BR$4*216*24*60*BP13/9000000 -> 0 | BT13: =BU$3*BU$4*216*24*60*BS13/9000000 -> 0 | BW13: =BX$3*BX$4*216*24*60*BV13/9000000 -> 0 | BZ13: =CA$3*CA$4*216*24*60*BY13/9000000 -> 0 | CC13: =CD$3*CD$4*216*24*60*CB13/9000000 -> 0 | CF13: =CG$3*CG$4*216*24*60*CE13/9000000 -> 0 | CI13: =CJ$3*CJ$4*216*24*60*CH13/9000000 -> 0 | CL13: =CM$3*CM$4*216*24*60*CK13/9000000 -> 0 | CO13: =CP$3*CP$4*216*24*60*CN13/9000000 -> 0 | CR13: =CS$3*CS$4*216*24*60*CQ13/9000000 -> 0 | CU13: =CV$3*CV$4*216*24*60*CT13/9000000 -> 0 | CX13: =B13+E13+H13+K13+N13+Q13+T13+W13+Z13+AC13+AF13+AI13+AL13+AO13+AR13+AU13+AX13+BA13+BD13+BG13+BJ13+BM13+BP13+BS13+BV13+BY13+CB13+CE13+CH13+CK13+CN13+CQ13+CT13 -> 0
A14: 9 | C14: =D$3*D$4*216*24*60*B14/9000000 -> 0 | F14: =G$3*G$4*216*24*60*E14/9000000 -> 0 | I14: =J$3*J$4*216*24*60*H14/9000000 -> 0 | L14: =M$3*M$4*216*24*60*K14/9000000 -> 0 | O14: =P$3*P$4*216*24*60*N14/9000000 -> 0 | R14: =S$3*S$4*216*24*60*Q14/9000000 -> 0 | U14: =V$3*V$4*216*24*60*T14/9000000 -> 0 | X14: =Y$3*Y$4*216*24*60*W14/9000000 -> 0 | AA14: =AB$3*AB$4*216*24*60*Z14/9000000 -> 0 | AD14: =AE$3*AE$4*216*24*60*AC14/9000000 -> 0 | AG14: =AH$3*AH$4*216*24*60*AF14/9000000 -> 0 | AJ14: =AK$3*AK$4*216*24*60*AI14/9000000 -> 0 | AM14: =AN$3*AN$4*216*24*60*AL14/9000000 -> 0 | AP14: =AQ$3*AQ$4*216*24*60*AO14/9000000 -> 0 | AS14: =AT$3*AT$4*216*24*60*AR14/9000000 -> 0 | AV14: =AW$3*AW$4*216*24*60*AU14/9000000 -> 0 | AY14: =AZ$3*AZ$4*216*24*60*AX14/9000000 -> 0 | BB14: =BC$3*BC$4*216*24*60*BA14/9000000 -> 0 | BE14: =BF$3*BF$4*216*24*60*BD14/9000000 -> 0 | BH14: =BI$3*BI$4*216*24*60*BG14/9000000 -> 0 | BK14: =BL$3*BL$4*216*24*60*BJ14/9000000 -> 0 | BN14: =BO$3*BO$4*216*24*60*BM14/9000000 -> 0 | BQ14: =BR$3*BR$4*216*24*60*BP14/9000000 -> 0 | BT14: =BU$3*BU$4*216*24*60*BS14/9000000 -> 0 | BW14: =BX$3*BX$4*216*24*60*BV14/9000000 -> 0 | BZ14: =CA$3*CA$4*216*24*60*BY14/9000000 -> 0 | CC14: =CD$3*CD$4*216*24*60*CB14/9000000 -> 0 | CF14: =CG$3*CG$4*216*24*60*CE14/9000000 -> 0 | CI14: =CJ$3*CJ$4*216*24*60*CH14/9000000 -> 0 | CL14: =CM$3*CM$4*216*24*60*CK14/9000000 -> 0 | CO14: =CP$3*CP$4*216*24*60*CN14/9000000 -> 0 | CR14: =CS$3*CS$4*216*24*60*CQ14/9000000 -> 0 | CU14: =CV$3*CV$4*216*24*60*CT14/9000000 -> 0 | CX14: =B14+E14+H14+K14+N14+Q14+T14+W14+Z14+AC14+AF14+AI14+AL14+AO14+AR14+AU14+AX14+BA14+BD14+BG14+BJ14+BM14+BP14+BS14+BV14+BY14+CB14+CE14+CH14+CK14+CN14+CQ14+CT14 -> 0
A15: 10 | C15: =D$3*D$4*216*24*60*B15/9000000 -> 0 | F15: =G$3*G$4*216*24*60*E15/9000000 -> 0 | I15: =J$3*J$4*216*24*60*H15/9000000 -> 0 | L15: =M$3*M$4*216*24*60*K15/9000000 -> 0 | O15: =P$3*P$4*216*24*60*N15/9000000 -> 0 | R15: =S$3*S$4*216*24*60*Q15/9000000 -> 0 | U15: =V$3*V$4*216*24*60*T15/9000000 -> 0 | X15: =Y$3*Y$4*216*24*60*W15/9000000 -> 0 | AA15: =AB$3*AB$4*216*24*60*Z15/9000000 -> 0 | AD15: =AE$3*AE$4*216*24*60*AC15/9000000 -> 0 | AG15: =AH$3*AH$4*216*24*60*AF15/9000000 -> 0 | AJ15: =AK$3*AK$4*216*24*60*AI15/9000000 -> 0 | AM15: =AN$3*AN$4*216*24*60*AL15/9000000 -> 0 | AP15: =AQ$3*AQ$4*216*24*60*AO15/9000000 -> 0 | AS15: =AT$3*AT$4*216*24*60*AR15/9000000 -> 0 | AV15: =AW$3*AW$4*216*24*60*AU15/9000000 -> 0 | AY15: =AZ$3*AZ$4*216*24*60*AX15/9000000 -> 0 | BB15: =BC$3*BC$4*216*24*60*BA15/9000000 -> 0 | BE15: =BF$3*BF$4*216*24*60*BD15/9000000 -> 0 | BH15: =BI$3*BI$4*216*24*60*BG15/9000000 -> 0 | BK15: =BL$3*BL$4*216*24*60*BJ15/9000000 -> 0 | BN15: =BO$3*BO$4*216*24*60*BM15/9000000 -> 0 | BQ15: =BR$3*BR$4*216*24*60*BP15/9000000 -> 0 | BT15: =BU$3*BU$4*216*24*60*BS15/9000000 -> 0 | BW15: =BX$3*BX$4*216*24*60*BV15/9000000 -> 0 | BZ15: =CA$3*CA$4*216*24*60*BY15/9000000 -> 0 | CC15: =CD$3*CD$4*216*24*60*CB15/9000000 -> 0 | CF15: =CG$3*CG$4*216*24*60*CE15/9000000 -> 0 | CI15: =CJ$3*CJ$4*216*24*60*CH15/9000000 -> 0 | CL15: =CM$3*CM$4*216*24*60*CK15/9000000 -> 0 | CO15: =CP$3*CP$4*216*24*60*CN15/9000000 -> 0 | CR15: =CS$3*CS$4*216*24*60*CQ15/9000000 -> 0 | CU15: =CV$3*CV$4*216*24*60*CT15/9000000 -> 0 | CX15: =B15+E15+H15+K15+N15+Q15+T15+W15+Z15+AC15+AF15+AI15+AL15+AO15+AR15+AU15+AX15+BA15+BD15+BG15+BJ15+BM15+BP15+BS15+BV15+BY15+CB15+CE15+CH15+CK15+CN15+CQ15+CT15 -> 0
A16: 11 | C16: =D$3*D$4*216*24*60*B16/9000000 -> 0 | F16: =G$3*G$4*216*24*60*E16/9000000 -> 0 | I16: =J$3*J$4*216*24*60*H16/9000000 -> 0 | L16: =M$3*M$4*216*24*60*K16/9000000 -> 0 | O16: =P$3*P$4*216*24*60*N16/9000000 -> 0 | R16: =S$3*S$4*216*24*60*Q16/9000000 -> 0 | U16: =V$3*V$4*216*24*60*T16/9000000 -> 0 | X16: =Y$3*Y$4*216*24*60*W16/9000000 -> 0 | AA16: =AB$3*AB$4*216*24*60*Z16/9000000 -> 0 | AD16: =AE$3*AE$4*216*24*60*AC16/9000000 -> 0 | AG16: =AH$3*AH$4*216*24*60*AF16/9000000 -> 0 | AJ16: =AK$3*AK$4*216*24*60*AI16/9000000 -> 0 | AM16: =AN$3*AN$4*216*24*60*AL16/9000000 -> 0 | AP16: =AQ$3*AQ$4*216*24*60*AO16/9000000 -> 0 | AS16: =AT$3*AT$4*216*24*60*AR16/9000000 -> 0 | AV16: =AW$3*AW$4*216*24*60*AU16/9000000 -> 0 | AY16: =AZ$3*AZ$4*216*24*60*AX16/9000000 -> 0 | BB16: =BC$3*BC$4*216*24*60*BA16/9000000 -> 0 | BE16: =BF$3*BF$4*216*24*60*BD16/9000000 -> 0 | BH16: =BI$3*BI$4*216*24*60*BG16/9000000 -> 0 | BK16: =BL$3*BL$4*216*24*60*BJ16/9000000 -> 0 | BN16: =BO$3*BO$4*216*24*60*BM16/9000000 -> 0 | BQ16: =BR$3*BR$4*216*24*60*BP16/9000000 -> 0 | BT16: =BU$3*BU$4*216*24*60*BS16/9000000 -> 0 | BW16: =BX$3*BX$4*216*24*60*BV16/9000000 -> 0 | BZ16: =CA$3*CA$4*216*24*60*BY16/9000000 -> 0 | CC16: =CD$3*CD$4*216*24*60*CB16/9000000 -> 0 | CF16: =CG$3*CG$4*216*24*60*CE16/9000000 -> 0 | CI16: =CJ$3*CJ$4*216*24*60*CH16/9000000 -> 0 | CL16: =CM$3*CM$4*216*24*60*CK16/9000000 -> 0 | CO16: =CP$3*CP$4*216*24*60*CN16/9000000 -> 0 | CR16: =CS$3*CS$4*216*24*60*CQ16/9000000 -> 0 | CU16: =CV$3*CV$4*216*24*60*CT16/9000000 -> 0 | CX16: =B16+E16+H16+K16+N16+Q16+T16+W16+Z16+AC16+AF16+AI16+AL16+AO16+AR16+AU16+AX16+BA16+BD16+BG16+BJ16+BM16+BP16+BS16+BV16+BY16+CB16+CE16+CH16+CK16+CN16+CQ16+CT16 -> 0
A17: 12 | C17: =D$3*D$4*216*24*60*B17/9000000 -> 0 | F17: =G$3*G$4*216*24*60*E17/9000000 -> 0 | I17: =J$3*J$4*216*24*60*H17/9000000 -> 0 | L17: =M$3*M$4*216*24*60*K17/9000000 -> 0 | O17: =P$3*P$4*216*24*60*N17/9000000 -> 0 | R17: =S$3*S$4*216*24*60*Q17/9000000 -> 0 | U17: =V$3*V$4*216*24*60*T17/9000000 -> 0 | X17: =Y$3*Y$4*216*24*60*W17/9000000 -> 0 | AA17: =AB$3*AB$4*216*24*60*Z17/9000000 -> 0 | AD17: =AE$3*AE$4*216*24*60*AC17/9000000 -> 0 | AG17: =AH$3*AH$4*216*24*60*AF17/9000000 -> 0 | AJ17: =AK$3*AK$4*216*24*60*AI17/9000000 -> 0 | AM17: =AN$3*AN$4*216*24*60*AL17/9000000 -> 0 | AP17: =AQ$3*AQ$4*216*24*60*AO17/9000000 -> 0 | AS17: =AT$3*AT$4*216*24*60*AR17/9000000 -> 0 | AV17: =AW$3*AW$4*216*24*60*AU17/9000000 -> 0 | AY17: =AZ$3*AZ$4*216*24*60*AX17/9000000 -> 0 | BB17: =BC$3*BC$4*216*24*60*BA17/9000000 -> 0 | BE17: =BF$3*BF$4*216*24*60*BD17/9000000 -> 0 | BH17: =BI$3*BI$4*216*24*60*BG17/9000000 -> 0 | BK17: =BL$3*BL$4*216*24*60*BJ17/9000000 -> 0 | BN17: =BO$3*BO$4*216*24*60*BM17/9000000 -> 0 | BQ17: =BR$3*BR$4*216*24*60*BP17/9000000 -> 0 | BT17: =BU$3*BU$4*216*24*60*BS17/9000000 -> 0 | BW17: =BX$3*BX$4*216*24*60*BV17/9000000 -> 0 | BZ17: =CA$3*CA$4*216*24*60*BY17/9000000 -> 0 | CC17: =CD$3*CD$4*216*24*60*CB17/9000000 -> 0 | CF17: =CG$3*CG$4*216*24*60*CE17/9000000 -> 0 | CI17: =CJ$3*CJ$4*216*24*60*CH17/9000000 -> 0 | CL17: =CM$3*CM$4*216*24*60*CK17/9000000 -> 0 | CO17: =CP$3*CP$4*216*24*60*CN17/9000000 -> 0 | CR17: =CS$3*CS$4*216*24*60*CQ17/9000000 -> 0 | CU17: =CV$3*CV$4*216*24*60*CT17/9000000 -> 0 | CX17: =B17+E17+H17+K17+N17+Q17+T17+W17+Z17+AC17+AF17+AI17+AL17+AO17+AR17+AU17+AX17+BA17+BD17+BG17+BJ17+BM17+BP17+BS17+BV17+BY17+CB17+CE17+CH17+CK17+CN17+CQ17+CT17 -> 0
... A36: 31 | C36: =D$3*D$4*216*24*60*B36/9000000 -> 0 | F36: =G$3*G$4*216*24*60*E36/9000000 -> 0 | I36: =J$3*J$4*216*24*60*H36/9000000 -> 0 | L36: =M$3*M$4*216*24*60*K36/9000000 -> 0 | O36: =P$3*P$4*216*24*60*N36/9000000 -> 0 | R36: =S$3*S$4*216*24*60*Q36/9000000 -> 0 | U36: =V$3*V$4*216*24*60*T36/9000000 -> 0 | X36: =Y$3*Y$4*216*24*60*W36/9000000 -> 0 | AA36: =AB$3*AB$4*216*24*60*Z36/9000000 -> 0 | AD36: =AE$3*AE$4*216*24*60*AC36/9000000 -> 0 | AG36: =AH$3*AH$4*216*24*60*AF36/9000000 -> 0 | AJ36: =AK$3*AK$4*216*24*60*AI36/9000000 -> 0 | AM36: =AN$3*AN$4*216*24*60*AL36/9000000 -> 0 | AP36: =AQ$3*AQ$4*216*24*60*AO36/9000000 -> 0 | AS36: =AT$3*AT$4*216*24*60*AR36/9000000 -> 0 | AV36: =AW$3*AW$4*216*24*60*AU36/9000000 -> 0 | AY36: =AZ$3*AZ$4*216*24*60*AX36/9000000 -> 0 | BB36: =BC$3*BC$4*216*24*60*BA36/9000000 -> 0 | BE36: =BF$3*BF$4*216*24*60*BD36/9000000 -> 0 | BH36: =BI$3*BI$4*216*24*60*BG36/9000000 -> 0 | BK36: =BL$3*BL$4*216*24*60*BJ36/9000000 -> 0 | BN36: =BO$3*BO$4*216*24*60*BM36/9000000 -> 0 | BQ36: =BR$3*BR$4*216*24*60*BP36/9000000 -> 0 | BT36: =BU$3*BU$4*216*24*60*BS36/9000000 -> 0 | BW36: =BX$3*BX$4*216*24*60*BV36/9000000 -> 0 | BZ36: =CA$3*CA$4*216*24*60*BY36/9000000 -> 0 | CC36: =CD$3*CD$4*216*24*60*CB36/9000000 -> 0 | CF36: =CG$3*CG$4*216*24*60*CE36/9000000 -> 0 | CI36: =CJ$3*CJ$4*216*24*60*CH36/9000000 -> 0 | CL36: =CM$3*CM$4*216*24*60*CK36/9000000 -> 0 | CO36: =CP$3*CP$4*216*24*60*CN36/9000000 -> 0 | CR36: =CS$3*CS$4*216*24*60*CQ36/9000000 -> 0 | CU36: =CV$3*CV$4*216*24*60*CT36/9000000 -> 0 | CX36: =B36+E36+H36+K36+N36+Q36+T36+W36+Z36+AC36+AF36+AI36+AL36+AO36+AR36+AU36+AX36+BA36+BD36+BG36+BJ36+BM36+BP36+BS36+BV36+BY36+CB36+CE36+CH36+CK36+CN36+CQ36+CT36 -> 0
B37: =IF(B6="",0,AVERAGE(B6:B36)) -> 0 | C37: =SUM(C6:C36) -> 0 | D37: =SUM(D6:D36) -> 0 | E37: =IF(E6="",0,AVERAGE(E6:E36)) -> 0 | F37: =SUM(F6:F36) -> 0 | G37: =SUM(G6:G36) -> 0 | H37: =IF(H6="",0,AVERAGE(H6:H36)) -> 0 | I37: =SUM(I6:I36) -> 0 | J37: =SUM(J6:J36) -> 0 | K37: =IF(K6="",0,AVERAGE(K6:K36)) -> 0 | L37: =SUM(L6:L36) -> 0 | M37: =SUM(M6:M36) -> 0 | N37: =IF(N6="",0,AVERAGE(N6:N36)) -> 0 | O37: =SUM(O6:O36) -> 0 | P37: =SUM(P6:P36) -> 0 | Q37: =IF(Q6="",0,AVERAGE(Q6:Q36)) -> 0 | R37: =SUM(R6:R36) -> 0 | S37: =SUM(S6:S36) -> 0 | T37: 0 | U37: =SUM(U6:U36) -> 0 | V37: =SUM(V6:V36) -> 0 | W37: =IF(W6="",0,AVERAGE(W6:W36)) -> 0 | X37: =SUM(X6:X36) -> 0 | Y37: =SUM(Y6:Y36) -> 0 | Z37: =IF(Z6="",0,AVERAGE(Z6:Z36)) -> 0 | AA37: =SUM(AA6:AA36) -> 0 | AB37: =SUM(AB6:AB36) -> 0 | AC37: =IF(AC6="",0,AVERAGE(AC6:AC36)) -> 0 | AD37: =SUM(AD6:AD36) -> 0 | AE37: =SUM(AE6:AE36) -> 0 | AF37: =IF(AF6="",0,AVERAGE(AF6:AF36)) -> 0 | AG37: =SUM(AG6:AG36) -> 0 | AH37: =SUM(AH6:AH36) -> 0 | AI37: =IF(AI6="",0,AVERAGE(AI6:AI36)) -> 0 | AJ37: =SUM(AJ6:AJ36) -> 0 | AK37: =SUM(AK6:AK36) -> 0 | AL37: =IF(AL6="",0,AVERAGE(AL6:AL36)) -> 0 | AM37: =SUM(AM6:AM36) -> 0 | AN37: =SUM(AN6:AN36) -> 0 | AO37: =IF(AO6="",0,AVERAGE(AO6:AO36)) -> 0 | AP37: =SUM(AP6:AP36) -> 0 | AQ37: =SUM(AQ6:AQ36) -> 0 | AR37: =IF(AR6="",0,AVERAGE(AR6:AR36)) -> 0 | AS37: =SUM(AS6:AS36) -> 0 | AT37: =SUM(AT6:AT36) -> 0 | AU37: =IF(AU6="",0,AVERAGE(AU6:AU36)) -> 0 | AV37: =SUM(AV6:AV36) -> 0 | AW37: =SUM(AW6:AW36) -> 0 | AX37: =IF(AX6="",0,AVERAGE(AX6:AX36)) -> 0 | AY37: =SUM(AY6:AY36) -> 0 | AZ37: =SUM(AZ6:AZ36) -> 0 | BA37: =IF(BA6="",0,AVERAGE(BA6:BA36)) -> 0 | BB37: =SUM(BB6:BB36) -> 0 | BC37: =SUM(BC6:BC36) -> 0 | BD37: =IF(BD6="",0,AVERAGE(BD6:BD36)) -> 0 | BE37: =SUM(BE6:BE36) -> 0 | BF37: =SUM(BF6:BF36) -> 0 | BG37: =IF(BG6="",0,AVERAGE(BG6:BG36)) -> 0 | BH37: =SUM(BH6:BH36) -> 0 | BI37: =SUM(BI6:BI36) -> 0 | BJ37: =IF(BJ6="",0,AVERAGE(BJ6:BJ36)) -> 0 | BK37: =SUM(BK6:BK36) -> 0 | BL37: =SUM(BL6:BL36) -> 0 | BM37: =IF(BM6="",0,AVERAGE(BM6:BM36)) -> 0 | BN37: =SUM(BN6:BN36) -> 0 | BO37: =SUM(BO6:BO36)-BO41 -> 0 | BP37: =IF(BP6="",0,AVERAGE(BP6:BP36)) -> 0 | BQ37: =SUM(BQ6:BQ36) -> 0 | BR37: =SUM(BR6:BR36)-BR41 -> 0 | BS37: =IF(BS6="",0,AVERAGE(BS6:BS36)) -> 0 | BT37: =SUM(BT6:BT36) -> 0 | BU37: =SUM(BU6:BU36)-BU41 -> 0 | BV37: =IF(BV6="",0,AVERAGE(BV6:BV36)) -> 0 | BW37: =SUM(BW6:BW36) -> 0 | BX37: =SUM(BX6:BX36) -> 0 | BY37: =IF(BY6="",0,AVERAGE(BY6:BY36)) -> 0 | BZ37: =SUM(BZ6:BZ36) -> 0 | CA37: =SUM(CA6:CA36) -> 0 | CB37: =IF(CB6="",0,AVERAGE(CB6:CB36)) -> 0 | CC37: =SUM(CC6:CC36) -> 0 | CD37: =SUM(CD6:CD36) -> 0 | CE37: =IF(CE6="",0,AVERAGE(CE6:CE36)) -> 0 | CF37: =SUM(CF6:CF36) -> 0 | CG37: =SUM(CG6:CG36) -> 0 | CH37: =IF(CH6="",0,AVERAGE(CH6:CH36)) -> 0 | CI37: =SUM(CI6:CI36) -> 0 | CJ37: =SUM(CJ6:CJ36) -> 0 | CK37: =IF(CK6="",0,AVERAGE(CK6:CK36)) -> 0 | CL37: =SUM(CL6:CL36) -> 0 | CM37: =SUM(CM6:CM36) -> 0 | CN37: =IF(CN6="",0,AVERAGE(CN6:CN36)) -> 0 | CO37: =SUM(CO6:CO36) -> 0 | CP37: =SUM(CP6:CP36) -> 0 | CQ37: =IF(CQ6="",0,AVERAGE(CQ6:CQ36)) -> 0 | CR37: =SUM(CR6:CR36) -> 0 | CS37: =SUM(CS6:CS36) -> 0 | CT37: =IF(CT6="",0,AVERAGE(CT6:CT36)) -> 0 | CU37: =SUM(CU6:CU36) -> 0 | CV37: =SUM(CV6:CV36) -> 0 | CX37: =B37+E37+H37+K37+N37+Q37+T37+W37+Z37+AC37+AF37+AI37+AL37+AO37+AR37+AU37+AX37+BA37+BD37+BG37+BJ37+BM37+BP37+BS37+BV37+BY37+CB37+CE37+CH37+CK37+CN37+CQ37+CT37 -> 0
B41: =B38-B39-B60 -> 0 | E41: =E38-E39-E60 -> 0 | H41: =H38-H39-H60 -> 0 | K41: =K38-K39-K60 -> 0 | N41: =N38-N39-N60 -> 0 | Q41: =Q38-Q39-Q60 -> 0 | T41: =T38-T39-T60 -> 0 | W41: =W38-W39-W60 -> 0 | Z41: =Z38-Z39-Z60 -> 0 | AC41: =AC38-AC39-AC60 -> 0 | AF41: =AF38-AF39-AF60 -> 0 | AI41: =AI38-AI39-AI60 -> 0 | AL41: =AL38-AL39-AL60 -> 0 | AO41: =AO38-AO39-AO60 -> 0 | AR41: =AR38-AR39-AR60 -> 0 | AU41: =AU38-AU39-AU60 -> 0 | AX41: =AX38-AX39-AX60 -> 0 | BA41: =BA38-BA39-BA60 -> 0 | BD41: =BD38-BD39-BD60 -> 0 | BG41: =BG38-BG39-BG60 -> 0 | BJ41: =BJ38-BJ39-BJ60 -> 0 | BM41: =BM38-BM39-BM60 -> 0 | BP41: =BP38-BP39-BP60 -> 0 | BS41: =BS38-BS39-BS60 -> 0 | BV41: =BV38-BV39-BV60 -> 0 | BY41: =BY38-BY39-BY60 -> 0 | CB41: =CB38-CB39-CB60 -> 0 | CE41: =CE38-CE39-CE60 -> 0 | CH41: =CH38-CH39-CH60 -> 0 | CK41: =CK38-CK39-CK60 -> 0 | CN41: =CN38-CN39-CN60 -> 0 | CQ41: =CQ38-CQ39-CQ60 -> 0 | CT41: =CT38-CT39-CT60 -> 0
A45: 退庫 | B45: A+Aw | C45: Ao+Ax | D45: B | E45: A+Aw | F45: Ao+Ax | G45: B | H45: A+Aw | I45: Ao+Ax | J45: B | K45: A+Aw | L45: Ao+Ax | M45: B | N45: A+Aw | O45: Ao+Ax | P45: B | Q45: A+Aw | R45: Ao+Ax | S45: B | T45: A+Aw | U45: Ao+Ax | V45: B | W45: A+Aw | X45: Ao+Ax | Y45: B | Z45: A+Aw | AA45: Ao+Ax | AB45: B | AC45: A+Aw | AD45: Ao+Ax | AE45: B | AF45: A+Aw | AG45: Ao+Ax | AH45: B | AI45: A+Aw | AJ45: Ao+Ax | AK45: B | AL45: A+Aw | AM45: Ao+Ax | AN45: B | AO45: A+Aw | AP45: Ao+Ax | AQ45: B | AR45: A+Aw | AS45: Ao+Ax | AT45: B | AU45: A+Aw | AV45: Ao+Ax | AW45: B | AX45: A+Aw | AY45: Ao+Ax | AZ45: B | BA45: A+Aw | BB45: Ao+Ax | BC45: B | BD45: A+Aw | BE45: Ao+Ax | BF45: B | BG45: A+Aw | BH45: Ao+Ax | BI45: B | BJ45: A+Aw | BK45: Ao+Ax | BL45: B | BM45: A+Aw | BN45: Ao+Ax | BO45: B | BP45: A+Aw | BQ45: Ao+Ax | BR45: B | BS45: A+Aw | BT45: Ao+Ax | BU45: B | BV45: A+Aw | BW45: Ao+Ax | BX45: B | BY45: A+Aw | BZ45: Ao+Ax | CA45: B | CB45: A+Aw | CC45: Ao+Ax | CD45: B | CE45: A+Aw | CF45: Ao+Ax | CG45: B | CH45: A+Aw | CI45: Ao+Ax | CJ45: B | CK45: A+Aw | CL45: Ao+Ax | CM45: B | CN45: A+Aw | CO45: Ao+Ax | CP45: B | CQ45: A+Aw | CR45: Ao+Ax | CS45: B | CT45: A+Aw | CU45: Ao+Ax | CV45: B
B60: =SUM(B46:B59) -> 0 | C60: =SUM(C46:C59) -> 0 | D60: =SUM(D46:D59) -> 0 | E60: =SUM(E46:E59) -> 0 | F60: =SUM(F46:F59) -> 0 | G60: =SUM(G46:G59) -> 0 | H60: =SUM(H46:H59) -> 0 | I60: =SUM(I46:I59) -> 0 | ... CV60: =SUM(CV46:CV59) -> 0
B61: =SUM(B60:D60) -> 0 | E61: =SUM(E60:G60) -> 0 | H61: =SUM(H60:J60) -> 0 | K61: =SUM(K60:M60) -> 0 | N61: =SUM(N60:P60) -> 0 | Q61: =SUM(Q60:S60) -> 0 | T61: =SUM(T60:V60) -> 0 | W61: =SUM(W60:Y60) -> 0 | Z61: =SUM(Z60:AB60) -> 0 | AC61: =SUM(AC60:AE60) -> 0 | AF61: =SUM(AF60:AH60) -> 0 | AI61: =SUM(AI60:AK60) -> 0 | AL61: =SUM(AL60:AN60) -> 0 | AO61: =SUM(AO60:AQ60) -> 0 | AR61: =SUM(AR60:AT60) -> 0 | AU61: =SUM(AU60:AW60) -> 0 | AX61: =SUM(AX60:AZ60) -> 0 | BA61: =SUM(BA60:BC60) -> 0 | BD61: =SUM(BD60:BF60) -> 0 | BG61: =SUM(BG60:BI60) -> 0 | BJ61: =SUM(BJ60:BL60) -> 0 | BM61: =SUM(BM60:BO60) -> 0 | BP61: =SUM(BP60:BR60) -> 0 | BS61: =SUM(BS60:BU60) -> 0 | BV61: =SUM(BV60:BX60) -> 0 | BY61: =SUM(BY60:CA60) -> 0 | CB61: =SUM(CB60:CD60) -> 0 | CE61: =SUM(CE60:CG60) -> 0 | CH61: =SUM(CH60:CJ60) -> 0 | CK61: =SUM(CK60:CM60) -> 0 | CN61: =SUM(CN60:CP60) -> 0 | CQ61: =SUM(CQ60:CS60) -> 0 | CT61: =SUM(CT60:CV60) -> 0
B62: =SUM(B61:CV61) -> 0

Sheet AFK
A1: 自2010/11起原絲丹尼÷DR再×1.8% | H1: 侯主任指示：2025/12起，AFK & MPS機型併股紗，「台數」用實際值，「丹尼」用規格(不併股)，例：75/24/2SD→用75 | N1: 侯主任指示：2025/12起，AFK & MPS機型併股紗，「台數」用實際值，「丹尼」用規格(不併股)，例：75/24/2SD→用75 | GM1: ='實驗紗&非當月生產'!P2 -> 886641
B2: 4 | E2: 5 | H2: 6 | K2: 7 | N2: 8 | Q2: 9 | T2: 10 | W2: 11 | Z2: 12 | AC2: 13 | AF2: 14 | AI2: 15 | AL2: 16 | AO2: 17 | AR2: 18 | AU2: 19 | AX2: 20 | BA2: 21 | BD2: 22 | BG2: 23 | BJ2: 24 | BM2: 25 | BP2: 26 | BS2: 27 | BV2: 28 | BY2: 29 | CB2: 30 | CE2: 31 | CH2: 32 | CK2: 33 | CN2: 34 | CQ2: 35 | CT2: 36 | CW2: 37 | CZ2: 38 | DC2: 39 | DF2: 40 | DI2: 41 | DL2: 42 | DO2: 43 | DR2: 44 | DU2: 45 | DX2: 46 | EA2: 47 | ED2: 48 | EG2: 49 | EJ2: 50 | EM2: 51 | EP2: 52 | ES2: 53 | EV2: 54 | EY2: 55 | FB2: 56 | FE2: 57 | FH2: 58 | FK2: 59 | FN2: 60 | FQ2: 61 | FT2: 62 | FW2: 63 | FZ2: 64 | GC2: 65 | GF2: 66 | GI2: 67
A3: Lot no. | B3: 2F08R2 | D3: 48 | E3: 2F08S2 | G3: 46 | H3: 2F08T2 | K3: 2FA062 | M3: 70 | N3: 2FA072 | P3: 70 | Q3: 2FA092 | T3: 2F43P2 | V3: 143 | W3: 2F43R2 | Y3: 71 | Z3: 2F43S2 | AB3: 142 | AC3: 2F6IQ2 | AE3: 142 | AF3: 2F7E22 | AH3: 155 | AI3: 2F7E31 | AK3: 305
A4: Speed | B4: 50/72BSD3 | D4: 630 | E4: 50/36SDr | G4: 575 | H4: 50/72F2FC | K4: 75/72SRR5 | M4: 600 | N4: 75/72SRR5 | P4: 600 | Q4: 75/72F2FC | T4: 150/48CDR | V4: 600 | W4: 75/72/2SDr | Y4: 600 | Z4: 150/48SDr | AB4: 650 | AC4: 150/48/2CE | AE4: 550 | AF4: 165/48SR6 | AH4: 600 | AI4: 165/48/2SR6 | AK4: 550
A5: Date | B5: 台數 | C5: 理論 | D5: 實際 | E5: 台數 | F5: 理論 | G5: 實際 | H5: 台數 | I5: 理論 | J5: 實際 | K5: 台數 | L5: 理論 | M5: 實際 | N5: 台數 | O5: 理論 | P5: 實際 | Q5: 台數 | R5: 理論 | S5: 實際 | T5: 台數 | U5: 理論 | V5: 實際 | W5: 台數 | X5: 理論 | Y5: 實際 | Z5: 台數 | AA5: 理論 | AB5: 實際 | AC5: 台數 | AD5: 理論 | AE5: 實際 | AF5: 台數 | AG5: 理論 | AH5: 實際 | AI5: 台數 | AJ5: 理論 | AK5: 實際 | AL5: 台數 | AM5: 理論 | AN5: 實際 | AO5: 台數 | AP5: 理論 | AQ5: 實際 | AR5: 台數 | AS5: 理論 | AT5: 實際 | AU5: 台數 | AV5: 理論 | AW5: 實際 | AX5: 台數 | AY5: 理論 | AZ5: 實際 | BA5: 台數 | BB5: 理論 | BC5: 實際 | BD5: 台數 | BE5: 理論 | BF5: 實際 | BG5: 台數 | BH5: 理論 | BI5: 實際 | BJ5: 台數 | BK5: 理論 | BL5: 實際 | BM5: 台數 | BN5: 理論 | BO5: 實際 | BP5: 台數 | BQ5: 理論 | BR5: 實際 | BS5: 台數 | BT5: 理論 | BU5: 實際 | BV5: 台數 | BW5: 理論 | BX5: 實際 | BY5: 台數 | BZ5: 理論 | CA5: 實際 | CB5: 台數 | CC5: 理論 | CD5: 實際 | CE5: 台數 | CF5: 理論 | CG5: 實際 | CH5: 台數 | CI5: 理論 | CJ5: 實際 | CK5: 台數 | CL5: 理論 | CM5: 實際 | CN5: 台數 | CO5: 理論 | CP5: 實際 | CQ5: 台數 | CR5: 理論 | CS5: 實際 | CT5: 台數 | CU5: 理論 | CV5: 實際 | CW5: 台數 | CX5: 理論 | CY5: 實際 | CZ5: 台數 | DA5: 理論 | DB5: 實際 | DC5: 台數 | DD5: 理論 | DE5: 實際 | DF5: 台數 | DG5: 理論 | DH5: 實際 | DI5: 台數 | DJ5: 理論 | DK5: 實際 | DL5: 台數 | DM5: 理論 | DN5: 實際 | DO5: 台數 | DP5: 理論 | DQ5: 實際 | DR5: 台數 | DS5: 理論 | DT5: 實際 | DU5: 台數 | DV5: 理論 | DW5: 實際 | DX5: 台數 | DY5: 理論 | DZ5: 實際 | EA5: 台數 | EB5: 理論 | EC5: 實際 | ED5: 台數 | EE5: 理論 | EF5: 實際 | EG5: 台數 | EH5: 理論 | EI5: 實際 | EJ5: 台數 | EK5: 理論 | EL5: 實際 | EM5: 台數 | EN5: 理論 | EO5: 實際 | EP5: 台數 | EQ5: 理論 | ER5: 實際 | ES5: 台數 | ET5: 理論 | EU5: 實際 | EV5: 台數 | EW5: 理論 | EX5: 實際 | EY5: 台數 | EZ5: 理論 | FA5: 實際 | FB5: 台數 | FC5: 理論 | FD5: 實際 | FE5: 台數 | FF5: 理論 | FG5: 實際 | FH5: 台數 | FI5: 理論 | FJ5: 實際 | FK5: 台數 | FL5: 理論 | FM5: 實際 | FN5: 台數 | FO5: 理論 | FP5: 實際 | FQ5: 台數 | FR5: 理論 | FS5: 實際 | FT5: 台數 | FU5: 理論 | FV5: 實際 | FW5: 台數 | FX5: 理論 | FY5: 實際 | FZ5: 台數 | GA5: 理論 | GB5: 實際 | GC5: 台數 | GD5: 理論 | GE5: 實際 | GF5: 台數 | GG5: 理論 | GH5: 實際 | GI5: 台數 | GJ5: 理論 | GK5: 實際 | GM5: 全部開車台數
A6: 1 | B6: 1 | C6: =D$3*D$4*216*24*60*B6/9000000 -> 1045.0944 | E6: 0 | F6: =G$3*G$4*216*24*60*E6/9000000 -> 0 | I6: =J$3*J$4*216*24*60*H6/9000000 -> 0 | K6: 1 | L6: =M$3*M$4*216*24*60*K6/9000000 -> 1451.52 | N6: 0 | O6: =P$3*P$4*216*24*60*N6/9000000 -> 0 | R6: =S$3*S$4*216*24*60*Q6/9000000 -> 0 | T6: 1 | U6: =V$3*V$4*216*24*60*T6/9000000 -> 2965.248 | W6: 0 | X6: =Y$3*Y$4*216*24*60*W6/9000000 -> 0 | Z6: 0 | AA6: =AB$3*AB$4*216*24*60*Z6/9000000 -> 0 | AC6: 0 | AD6: =AE$3*AE$4*216*24*60*AC6/9000000 -> 0 | AF6: 0 | AG6: =AH$3*AH$4*216*24*60*AF6/9000000 -> 0 | AI6: 0 | AJ6: =AK$3*AK$4*216*24*60*AI6/9000000 -> 0 | AM6: =AN$3*AN$4*216*24*60*AL6/9000000 -> 0 | AP6: =AQ$3*AQ$4*216*24*60*AO6/9000000 -> 0 | AS6: =AT$3*AT$4*216*24*60*AR6/9000000 -> 0 | AV6: =AW$3*AW$4*216*24*60*AU6/9000000 -> 0 | AY6: =AZ$3*AZ$4*216*24*60*AX6/9000000 -> 0 | BB6: =BC$3*BC$4*216*24*60*BA6/9000000 -> 0 | BE6: =BF$3*BF$4*216*24*60*BD6/9000000 -> 0 | BH6: =BI$3*BI$4*216*24*60*BG6/9000000 -> 0 | BK6: =BL$3*BL$4*216*24*60*BJ6/9000000 -> 0 | BN6: =BO$3*BO$4*216*24*60*BM6/9000000 -> 0 | BQ6: =BR$3*BR$4*216*24*60*BP6/9000000 -> 0 | BT6: =BU$3*BU$4*216*24*60*BS6/9000000 -> 0 | BW6: =BX$3*BX$4*216*24*60*BV6/9000000 -> 0 | BZ6: =CA$3*CA$4*216*24*60*BY6/9000000 -> 0 | CC6: =CD$3*CD$4*216*24*60*CB6/9000000 -> 0 | CF6: =CG$3*CG$4*216*24*60*CE6/9000000 -> 0 | CI6: =CJ$3*CJ$4*216*24*60*CH6/9000000 -> 0 | CL6: =CM$3*CM$4*216*24*60*CK6/9000000 -> 0 | CO6: =CP$3*CP$4*216*24*60*CN6/9000000 -> 0 | CR6: =CS$3*CS$4*216*24*60*CQ6/9000000 -> 0 | CU6: =CV$3*CV$4*216*24*60*CT6/9000000 -> 0 | CX6: =CY$3*CY$4*216*24*60*CW6/9000000 -> 0 | DA6: =DB$3*DB$4*216*24*60*CZ6/9000000 -> 0 | DD6: =DE$3*DE$4*216*24*60*DC6/9000000 -> 0 | DG6: =DH$3*DH$4*216*24*60*DF6/9000000 -> 0 | DJ6: =DK$3*DK$4*216*24*60*DI6/9000000 -> 0 | DM6: =DN$3*DN$4*216*24*60*DL6/9000000 -> 0 | DP6: =DQ$3*DQ$4*216*24*60*DO6/9000000 -> 0 | DS6: =DT$3*DT$4*216*24*60*DR6/9000000 -> 0 | DV6: =DW$3*DW$4*216*24*60*DU6/9000000 -> 0 | DY6: =DZ$3*DZ$4*216*24*60*DX6/9000000 -> 0 | EB6: =EC$3*EC$4*216*24*60*EA6/9000000 -> 0 | EE6: =EF$3*EF$4*216*24*60*ED6/9000000 -> 0 | EH6: =EI$3*EI$4*216*24*60*EG6/9000000 -> 0 | EK6: =EL$3*EL$4*216*24*60*EJ6/9000000 -> 0 | EN6: =EO$3*EO$4*216*24*60*EM6/9000000 -> 0 | EQ6: =ER$3*ER$4*216*24*60*EP6/9000000 -> 0 | ET6: =EU$3*EU$4*216*24*60*ES6/9000000 -> 0 | EW6: =EX$3*EX$4*216*24*60*EV6/9000000 -> 0 | EZ6: =FA$3*FA$4*216*24*60*EY6/9000000 -> 0 | FC6: =FD$3*FD$4*216*24*60*FB6/9000000 -> 0 | FF6: =FG$3*FG$4*216*24*60*FE6/9000000 -> 0 | FI6: =FJ$3*FJ$4*216*24*60*FH6/9000000 -> 0 | FL6: =FM$3*FM$4*216*24*60*FK6/9000000 -> 0 | FO6: =FP$3*FP$4*216*24*60*FN6/9000000 -> 0 | FR6: =FS$3*FS$4*216*24*60*FQ6/9000000 -> 0 | FU6: =FV$3*FV$4*216*24*60*FT6/9000000 -> 0 | FX6: =FY$3*FY$4*216*24*60*FW6/9000000 -> 0 | GA6: =GB$3*GB$4*216*24*60*FZ6/9000000 -> 0 | GD6: =GE$3*GE$4*216*24*60*GC6/9000000 -> 0 | GG6: =GH$3*GH$4*216*24*60*GF6/9000000 -> 0 | GJ6: =GK$3*GK$4*216*24*60*GI6/9000000 -> 0 | GL6: =AC6+Z6+W6+T6+Q6+N6+K6+H6+E6+B6+AF6+AI6+AL6+AO6+AR6+AU6+AX6+BA6+BD6+BG6+BJ6+BM6+BP6+BS6+BV6+BY6+CB6+CE6+CH6+CK6+CN6+CQ6+CT6+CW6+CZ6+DC6+DL6+DF6+DI6+DO6+DR6+DU6+DX6+EA6+ED6+EG6+EJ6+EM6+EP6+ES6+EV6+EY6+FB6+FE6+FH6+FK6+FN6+FQ6+FT6+FW6+FZ6+GC6+GF6+GI6 -> 3 | GM6: =GL6+'33J'!BK6+'M80(20250122封存)'!CX6+MPS!AY6+TMT!CX6 -> 7.25
A7: 2 | B7: 1 | C7: =D$3*D$4*216*24*60*B7/9000000 -> 1045.0944 | D7: 3574 | E7: 0 | F7: =G$3*G$4*216*24*60*E7/9000000 -> 0 | I7: =J$3*J$4*216*24*60*H7/9000000 -> 0 | K7: 1 | L7: =M$3*M$4*216*24*60*K7/9000000 -> 1451.52 | M7: 4871 | N7: 0 | O7: =P$3*P$4*216*24*60*N7/9000000 -> 0 | R7: =S$3*S$4*216*24*60*Q7/9000000 -> 0 | T7: 1 | U7: =V$3*V$4*216*24*60*T7/9000000 -> 2965.248 | W7: 1 | X7: =Y$3*Y$4*216*24*60*W7/9000000 -> 1472.256 | Z7: 0 | AA7: =AB$3*AB$4*216*24*60*Z7/9000000 -> 0 | AC7: 0 | AD7: =AE$3*AE$4*216*24*60*AC7/9000000 -> 0 | AF7: 0 | AG7: =AH$3*AH$4*216*24*60*AF7/9000000 -> 0 | AI7: 0 | AJ7: =AK$3*AK$4*216*24*60*AI7/9000000 -> 0 | AM7: =AN$3*AN$4*216*24*60*AL7/9000000 -> 0 | AP7: =AQ$3*AQ$4*216*24*60*AO7/9000000 -> 0 | AS7: =AT$3*AT$4*216*24*60*AR7/9000000 -> 0 | AV7: =AW$3*AW$4*216*24*60*AU7/9000000 -> 0 | AY7: =AZ$3*AZ$4*216*24*60*AX7/9000000 -> 0 | BB7: =BC$3*BC$4*216*24*60*BA7/9000000 -> 0 | BE7: =BF$3*BF$4*216*24*60*BD7/9000000 -> 0 | BH7: =BI$3*BI$4*216*24*60*BG7/9000000 -> 0 | BK7: =BL$3*BL$4*216*24*60*BJ7/9000000 -> 0 | BN7: =BO$3*BO$4*216*24*60*BM7/9000000 -> 0 | BQ7: =BR$3*BR$4*216*24*60*BP7/9000000 -> 0 | BT7: =BU$3*BU$4*216*24*60*BS7/9000000 -> 0 | BW7: =BX$3*BX$4*216*24*60*BV7/9000000 -> 0 | BZ7: =CA$3*CA$4*216*24*60*BY7/9000000 -> 0 | CC7: =CD$3*CD$4*216*24*60*CB7/9000000 -> 0 | CF7: =CG$3*CG$4*216*24*60*CE7/9000000 -> 0 | CI7: =CJ$3*CJ$4*216*24*60*CH7/9000000 -> 0 | CL7: =CM$3*CM$4*216*24*60*CK7/9000000 -> 0 | CO7: =CP$3*CP$4*216*24*60*CN7/9000000 -> 0 | CR7: =CS$3*CS$4*216*24*60*CQ7/9000000 -> 0 | CU7: =CV$3*CV$4*216*24*60*CT7/9000000 -> 0 | CX7: =CY$3*CY$4*216*24*60*CW7/9000000 -> 0 | DA7: =DB$3*DB$4*216*24*60*CZ7/9000000 -> 0 | DD7: =DE$3*DE$4*216*24*60*DC7/9000000 -> 0 | DG7: =DH$3*DH$4*216*24*60*DF7/9000000 -> 0 | DJ7: =DK$3*DK$4*216*24*60*DI7/9000000 -> 0 | DM7: =DN$3*DN$4*216*24*60*DL7/9000000 -> 0 | DP7: =DQ$3*DQ$4*216*24*60*DO7/9000000 -> 0 | DS7: =DT$3*DT$4*216*24*60*DR7/9000000 -> 0 | DV7: =DW$3*DW$4*216*24*60*DU7/9000000 -> 0 | DY7: =DZ$3*DZ$4*216*24*60*DX7/9000000 -> 0 | EB7: =EC$3*EC$4*216*24*60*EA7/9000000 -> 0 | EE7: =EF$3*EF$4*216*24*60*ED7/9000000 -> 0 | EH7: =EI$3*EI$4*216*24*60*EG7/9000000 -> 0 | EK7: =EL$3*EL$4*216*24*60*EJ7/9000000 -> 0 | EN7: =EO$3*EO$4*216*24*60*EM7/9000000 -> 0 | EQ7: =ER$3*ER$4*216*24*60*EP7/9000000 -> 0 | ET7: =EU$3*EU$4*216*24*60*ES7/9000000 -> 0 | EW7: =EX$3*EX$4*216*24*60*EV7/9000000 -> 0 | EZ7: =FA$3*FA$4*216*24*60*EY7/9000000 -> 0 | FC7: =FD$3*FD$4*216*24*60*FB7/9000000 -> 0 | FF7: =FG$3*FG$4*216*24*60*FE7/9000000 -> 0 | FI7: =FJ$3*FJ$4*216*24*60*FH7/9000000 -> 0 | FL7: =FM$3*FM$4*216*24*60*FK7/9000000 -> 0 | FO7: =FP$3*FP$4*216*24*60*FN7/9000000 -> 0 | FR7: =FS$3*FS$4*216*24*60*FQ7/9000000 -> 0 | FU7: =FV$3*FV$4*216*24*60*FT7/9000000 -> 0 | FX7: =FY$3*FY$4*216*24*60*FW7/9000000 -> 0 | GA7: =GB$3*GB$4*216*24*60*FZ7/9000000 -> 0 | GD7: =GE$3*GE$4*216*24*60*GC7/9000000 -> 0 | GG7: =GH$3*GH$4*216*24*60*GF7/9000000 -> 0 | GJ7: =GK$3*GK$4*216*24*60*GI7/9000000 -> 0 | GL7: =AC7+Z7+W7+T7+Q7+N7+K7+H7+E7+B7+AF7+AI7+AL7+AO7+AR7+AU7+AX7+BA7+BD7+BG7+BJ7+BM7+BP7+BS7+BV7+BY7+CB7+CE7+CH7+CK7+CN7+CQ7+CT7+CW7+CZ7+DC7+DL7+DF7+DI7+DO7+DR7+DU7+DX7+EA7+ED7+EG7+EJ7+EM7+EP7+ES7+EV7+EY7+FB7+FE7+FH7+FK7+FN7+FQ7+FT7+FW7+FZ7+GC7+GF7+GI7 -> 4 | GM7: =GL7+'33J'!BK7+'M80(20250122封存)'!CX7+MPS!AY7+TMT!CX7 -> 7.75
A8: 3 | B8: 1 | C8: =D$3*D$4*216*24*60*B8/9000000 -> 1045.0944 | D8: 864 | E8: 1 | F8: =G$3*G$4*216*24*60*E8/9000000 -> 914.112 | I8: =J$3*J$4*216*24*60*H8/9000000 -> 0 | K8: 1 | L8: =M$3*M$4*216*24*60*K8/9000000 -> 1451.52 | M8: 1680 | N8: 0 | O8: =P$3*P$4*216*24*60*N8/9000000 -> 0 | R8: =S$3*S$4*216*24*60*Q8/9000000 -> 0 | T8: 1 | U8: =V$3*V$4*216*24*60*T8/9000000 -> 2965.248 | V8: 13050 | W8: 1 | X8: =Y$3*Y$4*216*24*60*W8/9000000 -> 1472.256 | Y8: 1500 | Z8: 1 | AA8: =AB$3*AB$4*216*24*60*Z8/9000000 -> 3189.888 | AB8: 750 | AC8: 0 | AD8: =AE$3*AE$4*216*24*60*AC8/9000000 -> 0 | AF8: 0 | AG8: =AH$3*AH$4*216*24*60*AF8/9000000 -> 0 | AI8: 0 | AJ8: =AK$3*AK$4*216*24*60*AI8/9000000 -> 0 | AM8: =AN$3*AN$4*216*24*60*AL8/9000000 -> 0 | AP8: =AQ$3*AQ$4*216*24*60*AO8/9000000 -> 0 | AS8: =AT$3*AT$4*216*24*60*AR8/9000000 -> 0 | AV8: =AW$3*AW$4*216*24*60*AU8/9000000 -> 0 | AY8: =AZ$3*AZ$4*216*24*60*AX8/9000000 -> 0 | BB8: =BC$3*BC$4*216*24*60*BA8/9000000 -> 0 | BE8: =BF$3*BF$4*216*24*60*BD8/9000000 -> 0 | BH8: =BI$3*BI$4*216*24*60*BG8/9000000 -> 0 | BK8: =BL$3*BL$4*216*24*60*BJ8/9000000 -> 0 | BN8: =BO$3*BO$4*216*24*60*BM8/9000000 -> 0 | BQ8: =BR$3*BR$4*216*24*60*BP8/9000000 -> 0 | BT8: =BU$3*BU$4*216*24*60*BS8/9000000 -> 0 | BW8: =BX$3*BX$4*216*24*60*BV8/9000000 -> 0 | BZ8: =CA$3*CA$4*216*24*60*BY8/9000000 -> 0 | CC8: =CD$3*CD$4*216*24*60*CB8/9000000 -> 0 | CF8: =CG$3*CG$4*216*24*60*CE8/9000000 -> 0 | CI8: =CJ$3*CJ$4*216*24*60*CH8/9000000 -> 0 | CL8: =CM$3*CM$4*216*24*60*CK8/9000000 -> 0 | CO8: =CP$3*CP$4*216*24*60*CN8/9000000 -> 0 | CR8: =CS$3*CS$4*216*24*60*CQ8/9000000 -> 0 | CU8: =CV$3*CV$4*216*24*60*CT8/9000000 -> 0 | CX8: =CY$3*CY$4*216*24*60*CW8/9000000 -> 0 | DA8: =DB$3*DB$4*216*24*60*CZ8/9000000 -> 0 | DD8: =DE$3*DE$4*216*24*60*DC8/9000000 -> 0 | DG8: =DH$3*DH$4*216*24*60*DF8/9000000 -> 0 | DJ8: =DK$3*DK$4*216*24*60*DI8/9000000 -> 0 | DM8: =DN$3*DN$4*216*24*60*DL8/9000000 -> 0 | DP8: =DQ$3*DQ$4*216*24*60*DO8/9000000 -> 0 | DS8: =DT$3*DT$4*216*24*60*DR8/9000000 -> 0 | DV8: =DW$3*DW$4*216*24*60*DU8/9000000 -> 0 | DY8: =DZ$3*DZ$4*216*24*60*DX8/9000000 -> 0 | EB8: =EC$3*EC$4*216*24*60*EA8/9000000 -> 0 | EE8: =EF$3*EF$4*216*24*60*ED8/9000000 -> 0 | EH8: =EI$3*EI$4*216*24*60*EG8/9000000 -> 0 | EK8: =EL$3*EL$4*216*24*60*EJ8/9000000 -> 0 | EN8: =EO$3*EO$4*216*24*60*EM8/9000000 -> 0 | EQ8: =ER$3*ER$4*216*24*60*EP8/9000000 -> 0 | ET8: =EU$3*EU$4*216*24*60*ES8/9000000 -> 0 | EW8: =EX$3*EX$4*216*24*60*EV8/9000000 -> 0 | EZ8: =FA$3*FA$4*216*24*60*EY8/9000000 -> 0 | FC8: =FD$3*FD$4*216*24*60*FB8/9000000 -> 0 | FF8: =FG$3*FG$4*216*24*60*FE8/9000000 -> 0 | FI8: =FJ$3*FJ$4*216*24*60*FH8/9000000 -> 0 | FL8: =FM$3*FM$4*216*24*60*FK8/9000000 -> 0 | FO8: =FP$3*FP$4*216*24*60*FN8/9000000 -> 0 | FR8: =FS$3*FS$4*216*24*60*FQ8/9000000 -> 0 | FU8: =FV$3*FV$4*216*24*60*FT8/9000000 -> 0 | FX8: =FY$3*FY$4*216*24*60*FW8/9000000 -> 0 | GA8: =GB$3*GB$4*216*24*60*FZ8/9000000 -> 0 | GD8: =GE$3*GE$4*216*24*60*GC8/9000000 -> 0 | GG8: =GH$3*GH$4*216*24*60*GF8/9000000 -> 0 | GJ8: =GK$3*GK$4*216*24*60*GI8/9000000 -> 0 | GL8: =AC8+Z8+W8+T8+Q8+N8+K8+H8+E8+B8+AF8+AI8+AL8+AO8+AR8+AU8+AX8+BA8+BD8+BG8+BJ8+BM8+BP8+BS8+BV8+BY8+CB8+CE8+CH8+CK8+CN8+CQ8+CT8+CW8+CZ8+DC8+DL8+DF8+DI8+DO8+DR8+DU8+DX8+EA8+ED8+EG8+EJ8+EM8+EP8+ES8+EV8+EY8+FB8+FE8+FH8+FK8+FN8+FQ8+FT8+FW8+FZ8+GC8+GF8+GI8 -> 6 | GM8: =GL8+'33J'!BK8+'M80(20250122封存)'!CX8+MPS!AY8+TMT!CX8 -> 11.75
A9: 4 | B9: 1 | C9: =D$3*D$4*216*24*60*B9/9000000 -> 1045.0944 | D9: 600 | E9: 1 | F9: =G$3*G$4*216*24*60*E9/9000000 -> 914.112 | I9: =J$3*J$4*216*24*60*H9/9000000 -> 0 | K9: 1 | L9: =M$3*M$4*216*24*60*K9/9000000 -> 1451.52 | M9: 1626 | N9: 0 | O9: =P$3*P$4*216*24*60*N9/9000000 -> 0 | R9: =S$3*S$4*216*24*60*Q9/9000000 -> 0 | T9: 1 | U9: =V$3*V$4*216*24*60*T9/9000000 -> 2965.248 | V9: 2997 | W9: 1 | X9: =Y$3*Y$4*216*24*60*W9/9000000 -> 1472.256 | Y9: 1500 | Z9: 1 | AA9: =AB$3*AB$4*216*24*60*Z9/9000000 -> 3189.888 | AB9: 3689 | AC9: 0 | AD9: =AE$3*AE$4*216*24*60*AC9/9000000 -> 0 | AF9: 0 | AG9: =AH$3*AH$4*216*24*60*AF9/9000000 -> 0 | AI9: 0 | AJ9: =AK$3*AK$4*216*24*60*AI9/9000000 -> 0 | AM9: =AN$3*AN$4*216*24*60*AL9/9000000 -> 0 | AP9: =AQ$3*AQ$4*216*24*60*AO9/9000000 -> 0 | AS9: =AT$3*AT$4*216*24*60*AR9/9000000 -> 0 | AV9: =AW$3*AW$4*216*24*60*AU9/9000000 -> 0 | AY9: =AZ$3*AZ$4*216*24*60*AX9/9000000 -> 0 | BB9: =BC$3*BC$4*216*24*60*BA9/9000000 -> 0 | BE9: =BF$3*BF$4*216*24*60*BD9/9000000 -> 0 | BH9: =BI$3*BI$4*216*24*60*BG9/9000000 -> 0 | BK9: =BL$3*BL$4*216*24*60*BJ9/9000000 -> 0 | BN9: =BO$3*BO$4*216*24*60*BM9/9000000 -> 0 | BQ9: =BR$3*BR$4*216*24*60*BP9/9000000 -> 0 | BT9: =BU$3*BU$4*216*24*60*BS9/9000000 -> 0 | BW9: =BX$3*BX$4*216*24*60*BV9/9000000 -> 0 | BZ9: =CA$3*CA$4*216*24*60*BY9/9000000 -> 0 | CC9: =CD$3*CD$4*216*24*60*CB9/9000000 -> 0 | CF9: =CG$3*CG$4*216*24*60*CE9/9000000 -> 0 | CI9: =CJ$3*CJ$4*216*24*60*CH9/9000000 -> 0 | CL9: =CM$3*CM$4*216*24*60*CK9/9000000 -> 0 | CO9: =CP$3*CP$4*216*24*60*CN9/9000000 -> 0 | CR9: =CS$3*CS$4*216*24*60*CQ9/9000000 -> 0 | CU9: =CV$3*CV$4*216*24*60*CT9/9000000 -> 0 | CX9: =CY$3*CY$4*216*24*60*CW9/9000000 -> 0 | DA9: =DB$3*DB$4*216*24*60*CZ9/9000000 -> 0 | DD9: =DE$3*DE$4*216*24*60*DC9/9000000 -> 0 | DG9: =DH$3*DH$4*216*24*60*DF9/9000000 -> 0 | DJ9: =DK$3*DK$4*216*24*60*DI9/9000000 -> 0 | DM9: =DN$3*DN$4*216*24*60*DL9/9000000 -> 0 | DP9: =DQ$3*DQ$4*216*24*60*DO9/9000000 -> 0 | DS9: =DT$3*DT$4*216*24*60*DR9/9000000 -> 0 | DV9: =DW$3*DW$4*216*24*60*DU9/9000000 -> 0 | DY9: =DZ$3*DZ$4*216*24*60*DX9/9000000 -> 0 | EB9: =EC$3*EC$4*216*24*60*EA9/9000000 -> 0 | EE9: =EF$3*EF$4*216*24*60*ED9/9000000 -> 0 | EH9: =EI$3*EI$4*216*24*60*EG9/9000000 -> 0 | EK9: =EL$3*EL$4*216*24*60*EJ9/9000000 -> 0 | EN9: =EO$3*EO$4*216*24*60*EM9/9000000 -> 0 | EQ9: =ER$3*ER$4*216*24*60*EP9/9000000 -> 0 | ET9: =EU$3*EU$4*216*24*60*ES9/9000000 -> 0 | EW9: =EX$3*EX$4*216*24*60*EV9/9000000 -> 0 | EZ9: =FA$3*FA$4*216*24*60*EY9/9000000 -> 0 | FC9: =FD$3*FD$4*216*24*60*FB9/9000000 -> 0 | FF9: =FG$3*FG$4*216*24*60*FE9/9000000 -> 0 | FI9: =FJ$3*FJ$4*216*24*60*FH9/9000000 -> 0 | FL9: =FM$3*FM$4*216*24*60*FK9/9000000 -> 0 | FO9: =FP$3*FP$4*216*24*60*FN9/9000000 -> 0 | FR9: =FS$3*FS$4*216*24*60*FQ9/9000000 -> 0 | FU9: =FV$3*FV$4*216*24*60*FT9/9000000 -> 0 | FX9: =FY$3*FY$4*216*24*60*FW9/9000000 -> 0 | GA9: =GB$3*GB$4*216*24*60*FZ9/9000000 -> 0 | GD9: =GE$3*GE$4*216*24*60*GC9/9000000 -> 0 | GG9: =GH$3*GH$4*216*24*60*GF9/9000000 -> 0 | GJ9: =GK$3*GK$4*216*24*60*GI9/9000000 -> 0 | GL9: =AC9+Z9+W9+T9+Q9+N9+K9+H9+E9+B9+AF9+AI9+AL9+AO9+AR9+AU9+AX9+BA9+BD9+BG9+BJ9+BM9+BP9+BS9+BV9+BY9+CB9+CE9+CH9+CK9+CN9+CQ9+CT9+CW9+CZ9+DC9+DL9+DF9+DI9+DO9+DR9+DU9+DX9+EA9+ED9+EG9+EJ9+EM9+EP9+ES9+EV9+EY9+FB9+FE9+FH9+FK9+FN9+FQ9+FT9+FW9+FZ9+GC9+GF9+GI9 -> 6 | GM9: =GL9+'33J'!BK9+'M80(20250122封存)'!CX9+MPS!AY9+TMT!CX9 -> 12.75
A10: 5 | B10: 1 | C10: =D$3*D$4*216*24*60*B10/9000000 -> 1045.0944 | D10: 840 | E10: 1 | F10: =G$3*G$4*216*24*60*E10/9000000 -> 914.112 | G10: 1200 | I10: =J$3*J$4*216*24*60*H10/9000000 -> 0 | K10: 1 | L10: =M$3*M$4*216*24*60*K10/9000000 -> 1451.52 | N10: 0 | O10: =P$3*P$4*216*24*60*N10/9000000 -> 0 | R10: =S$3*S$4*216*24*60*Q10/9000000 -> 0 | T10: 1 | U10: =V$3*V$4*216*24*60*T10/9000000 -> 2965.248 | V10: 2822 | W10: 1 | X10: =Y$3*Y$4*216*24*60*W10/9000000 -> 1472.256 | Y10: 1500 | Z10: 1 | AA10: =AB$3*AB$4*216*24*60*Z10/9000000 -> 3189.888 | AB10: 2850 | AC10: 0 | AD10: =AE$3*AE$4*216*24*60*AC10/9000000 -> 0 | AF10: 0 | AG10: =AH$3*AH$4*216*24*60*AF10/9000000 -> 0 | AI10: 0 | AJ10: =AK$3*AK$4*216*24*60*AI10/9000000 -> 0 | AM10: =AN$3*AN$4*216*24*60*AL10/9000000 -> 0 | AP10: =AQ$3*AQ$4*216*24*60*AO10/9000000 -> 0 | AS10: =AT$3*AT$4*216*24*60*AR10/9000000 -> 0 | AV10: =AW$3*AW$4*216*24*60*AU10/9000000 -> 0 | AY10: =AZ$3*AZ$4*216*24*60*AX10/9000000 -> 0 | BB10: =BC$3*BC$4*216*24*60*BA10/9000000 -> 0 | BE10: =BF$3*BF$4*216*24*60*BD10/9000000 -> 0 | BH10: =BI$3*BI$4*216*24*60*BG10/9000000 -> 0 | BK10: =BL$3*BL$4*216*24*60*BJ10/9000000 -> 0 | BN10: =BO$3*BO$4*216*24*60*BM10/9000000 -> 0 | BQ10: =BR$3*BR$4*216*24*60*BP10/9000000 -> 0 | BT10: =BU$3*BU$4*216*24*60*BS10/9000000 -> 0 | BW10: =BX$3*BX$4*216*24*60*BV10/9000000 -> 0 | BZ10: =CA$3*CA$4*216*24*60*BY10/9000000 -> 0 | CC10: =CD$3*CD$4*216*24*60*CB10/9000000 -> 0 | CF10: =CG$3*CG$4*216*24*60*CE10/9000000 -> 0 | CI10: =CJ$3*CJ$4*216*24*60*CH10/9000000 -> 0 | CL10: =CM$3*CM$4*216*24*60*CK10/9000000 -> 0 | CO10: =CP$3*CP$4*216*24*60*CN10/9000000 -> 0 | CR10: =CS$3*CS$4*216*24*60*CQ10/9000000 -> 0 | CU10: =CV$3*CV$4*216*24*60*CT10/9000000 -> 0 | CX10: =CY$3*CY$4*216*24*60*CW10/9000000 -> 0 | DA10: =DB$3*DB$4*216*24*60*CZ10/9000000 -> 0 | DD10: =DE$3*DE$4*216*24*60*DC10/9000000 -> 0 | DG10: =DH$3*DH$4*216*24*60*DF10/9000000 -> 0 | DJ10: =DK$3*DK$4*216*24*60*DI10/9000000 -> 0 | DM10: =DN$3*DN$4*216*24*60*DL10/9000000 -> 0 | DP10: =DQ$3*DQ$4*216*24*60*DO10/9000000 -> 0 | DS10: =DT$3*DT$4*216*24*60*DR10/9000000 -> 0 | DV10: =DW$3*DW$4*216*24*60*DU10/9000000 -> 0 | DY10: =DZ$3*DZ$4*216*24*60*DX10/9000000 -> 0 | EB10: =EC$3*EC$4*216*24*60*EA10/9000000 -> 0 | EE10: =EF$3*EF$4*216*24*60*ED10/9000000 -> 0 | EH10: =EI$3*EI$4*216*24*60*EG10/9000000 -> 0 | EK10: =EL$3*EL$4*216*24*60*EJ10/9000000 -> 0 | EN10: =EO$3*EO$4*216*24*60*EM10/9000000 -> 0 | EQ10: =ER$3*ER$4*216*24*60*EP10/9000000 -> 0 | ET10: =EU$3*EU$4*216*24*60*ES10/9000000 -> 0 | EW10: =EX$3*EX$4*216*24*60*EV10/9000000 -> 0 | EZ10: =FA$3*FA$4*216*24*60*EY10/9000000 -> 0 | FC10: =FD$3*FD$4*216*24*60*FB10/9000000 -> 0 | FF10: =FG$3*FG$4*216*24*60*FE10/9000000 -> 0 | FI10: =FJ$3*FJ$4*216*24*60*FH10/9000000 -> 0 | FL10: =FM$3*FM$4*216*24*60*FK10/9000000 -> 0 | FO10: =FP$3*FP$4*216*24*60*FN10/9000000 -> 0 | FR10: =FS$3*FS$4*216*24*60*FQ10/9000000 -> 0 | FU10: =FV$3*FV$4*216*24*60*FT10/9000000 -> 0 | FX10: =FY$3*FY$4*216*24*60*FW10/9000000 -> 0 | GA10: =GB$3*GB$4*216*24*60*FZ10/9000000 -> 0 | GD10: =GE$3*GE$4*216*24*60*GC10/9000000 -> 0 | GG10: =GH$3*GH$4*216*24*60*GF10/9000000 -> 0 | GJ10: =GK$3*GK$4*216*24*60*GI10/9000000 -> 0 | GL10: =AC10+Z10+W10+T10+Q10+N10+K10+H10+E10+B10+AF10+AI10+AL10+AO10+AR10+AU10+AX10+BA10+BD10+BG10+BJ10+BM10+BP10+BS10+BV10+BY10+CB10+CE10+CH10+CK10+CN10+CQ10+CT10+CW10+CZ10+DC10+DL10+DF10+DI10+DO10+DR10+DU10+DX10+EA10+ED10+EG10+EJ10+EM10+EP10+ES10+EV10+EY10+FB10+FE10+FH10+FK10+FN10+FQ10+FT10+FW10+FZ10+GC10+GF10+GI10 -> 6 | GM10: =GL10+'33J'!BK10+'M80(20250122封存)'!CX10+MPS!AY10+TMT!CX10 -> 12.75
A11: 6 | B11: 1 | C11: =D$3*D$4*216*24*60*B11/9000000 -> 1045.0944 | E11: 1 | F11: =G$3*G$4*216*24*60*E11/9000000 -> 914.112 | I11: =J$3*J$4*216*24*60*H11/9000000 -> 0 | K11: 1 | L11: =M$3*M$4*216*24*60*K11/9000000 -> 1451.52 | M11: 1920 | N11: 0 | O11: =P$3*P$4*216*24*60*N11/9000000 -> 0 | R11: =S$3*S$4*216*24*60*Q11/9000000 -> 0 | T11: 1 | U11: =V$3*V$4*216*24*60*T11/9000000 -> 2965.248 | V11: 2250 | W11: 1 | X11: =Y$3*Y$4*216*24*60*W11/9000000 -> 1472.256 | Y11: 600 | Z11: 1 | AA11: =AB$3*AB$4*216*24*60*Z11/9000000 -> 3189.888 | AB11: 1500 | AC11: 0 | AD11: =AE$3*AE$4*216*24*60*AC11/9000000 -> 0 | AF11: 0 | AG11: =AH$3*AH$4*216*24*60*AF11/9000000 -> 0 | AI11: 0 | AJ11: =AK$3*AK$4*216*24*60*AI11/9000000 -> 0 | AM11: =AN$3*AN$4*216*24*60*AL11/9000000 -> 0 | AP11: =AQ$3*AQ$4*216*24*60*AO11/9000000 -> 0 | AS11: =AT$3*AT$4*216*24*60*AR11/9000000 -> 0 | AV11: =AW$3*AW$4*216*24*60*AU11/9000000 -> 0 | AY11: =AZ$3*AZ$4*216*24*60*AX11/9000000 -> 0 | BB11: =BC$3*BC$4*216*24*60*BA11/9000000 -> 0 | BE11: =BF$3*BF$4*216*24*60*BD11/9000000 -> 0 | BH11: =BI$3*BI$4*216*24*60*BG11/9000000 -> 0 | BK11: =BL$3*BL$4*216*24*60*BJ11/9000000 -> 0 | BN11: =BO$3*BO$4*216*24*60*BM11/9000000 -> 0 | BQ11: =BR$3*BR$4*216*24*60*BP11/9000000 -> 0 | BT11: =BU$3*BU$4*216*24*60*BS11/9000000 -> 0 | BW11: =BX$3*BX$4*216*24*60*BV11/9000000 -> 0 | BZ11: =CA$3*CA$4*216*24*60*BY11/9000000 -> 0 | CC11: =CD$3*CD$4*216*24*60*CB11/9000000 -> 0 | CF11: =CG$3*CG$4*216*24*60*CE11/9000000 -> 0 | CI11: =CJ$3*CJ$4*216*24*60*CH11/9000000 -> 0 | CL11: =CM$3*CM$4*216*24*60*CK11/9000000 -> 0 | CO11: =CP$3*CP$4*216*24*60*CN11/9000000 -> 0 | CR11: =CS$3*CS$4*216*24*60*CQ11/9000000 -> 0 | CU11: =CV$3*CV$4*216*24*60*CT11/9000000 -> 0 | CX11: =CY$3*CY$4*216*24*60*CW11/9000000 -> 0 | DA11: =DB$3*DB$4*216*24*60*CZ11/9000000 -> 0 | DD11: =DE$3*DE$4*216*24*60*DC11/9000000 -> 0 | DG11: =DH$3*DH$4*216*24*60*DF11/9000000 -> 0 | DJ11: =DK$3*DK$4*216*24*60*DI11/9000000 -> 0 | DM11: =DN$3*DN$4*216*24*60*DL11/9000000 -> 0 | DP11: =DQ$3*DQ$4*216*24*60*DO11/9000000 -> 0 | DS11: =DT$3*DT$4*216*24*60*DR11/9000000 -> 0 | DV11: =DW$3*DW$4*216*24*60*DU11/9000000 -> 0 | DY11: =DZ$3*DZ$4*216*24*60*DX11/9000000 -> 0 | EB11: =EC$3*EC$4*216*24*60*EA11/9000000 -> 0 | EE11: =EF$3*EF$4*216*24*60*ED11/9000000 -> 0 | EH11: =EI$3*EI$4*216*24*60*EG11/9000000 -> 0 | EK11: =EL$3*EL$4*216*24*60*EJ11/9000000 -> 0 | EN11: =EO$3*EO$4*216*24*60*EM11/9000000 -> 0 | EQ11: =ER$3*ER$4*216*24*60*EP11/9000000 -> 0 | ET11: =EU$3*EU$4*216*24*60*ES11/9000000 -> 0 | EW11: =EX$3*EX$4*216*24*60*EV11/9000000 -> 0 | EZ11: =FA$3*FA$4*216*24*60*EY11/9000000 -> 0 | FC11: =FD$3*FD$4*216*24*60*FB11/9000000 -> 0 | FF11: =FG$3*FG$4*216*24*60*FE11/9000000 -> 0 | FI11: =FJ$3*FJ$4*216*24*60*FH11/9000000 -> 0 | FL11: =FM$3*FM$4*216*24*60*FK11/9000000 -> 0 | FO11: =FP$3*FP$4*216*24*60*FN11/9000000 -> 0 | FR11: =FS$3*FS$4*216*24*60*FQ11/9000000 -> 0 | FU11: =FV$3*FV$4*216*24*60*FT11/9000000 -> 0 | FX11: =FY$3*FY$4*216*24*60*FW11/9000000 -> 0 | GA11: =GB$3*GB$4*216*24*60*FZ11/9000000 -> 0 | GD11: =GE$3*GE$4*216*24*60*GC11/9000000 -> 0 | GG11: =GH$3*GH$4*216*24*60*GF11/9000000 -> 0 | GJ11: =GK$3*GK$4*216*24*60*GI11/9000000 -> 0 | GL11: =AC11+Z11+W11+T11+Q11+N11+K11+H11+E11+B11+AF11+AI11+AL11+AO11+AR11+AU11+AX11+BA11+BD11+BG11+BJ11+BM11+BP11+BS11+BV11+BY11+CB11+CE11+CH11+CK11+CN11+CQ11+CT11+CW11+CZ11+DC11+DL11+DF11+DI11+DO11+DR11+DU11+DX11+EA11+ED11+EG11+EJ11+EM11+EP11+ES11+EV11+EY11+FB11+FE11+FH11+FK11+FN11+FQ11+FT11+FW11+FZ11+GC11+GF11+GI11 -> 6 | GM11: =GL11+'33J'!BK11+'M80(20250122封存)'!CX11+MPS!AY11+TMT!CX11 -> 12.75
A12: 7 | B12: 1 | C12: =D$3*D$4*216*24*60*B12/9000000 -> 1045.0944 | D12: 2147 | E12: 1 | F12: =G$3*G$4*216*24*60*E12/9000000 -> 914.112 | G12: 1680 | I12: =J$3*J$4*216*24*60*H12/9000000 -> 0 | K12: 1 | L12: =M$3*M$4*216*24*60*K12/9000000 -> 1451.52 | M12: 1308 | N12: 0 | O12: =P$3*P$4*216*24*60*N12/9000000 -> 0 | R12: =S$3*S$4*216*24*60*Q12/9000000 -> 0 | T12: 1 | U12: =V$3*V$4*216*24*60*T12/9000000 -> 2965.248 | V12: 2850 | W12: 1 | X12: =Y$3*Y$4*216*24*60*W12/9000000 -> 1472.256 | Y12: 750 | Z12: 1 | AA12: =AB$3*AB$4*216*24*60*Z12/9000000 -> 3189.888 | AB12: 3750 | AC12: 0 | AD12: =AE$3*AE$4*216*24*60*AC12/9000000 -> 0 | AF12: 0 | AG12: =AH$3*AH$4*216*24*60*AF12/9000000 -> 0 | AI12: 0 | AJ12: =AK$3*AK$4*216*24*60*AI12/9000000 -> 0 | AM12: =AN$3*AN$4*216*24*60*AL12/9000000 -> 0 | AP12: =AQ$3*AQ$4*216*24*60*AO12/9000000 -> 0 | AS12: =AT$3*AT$4*216*24*60*AR12/9000000 -> 0 | AV12: =AW$3*AW$4*216*24*60*AU12/9000000 -> 0 | AY12: =AZ$3*AZ$4*216*24*60*AX12/9000000 -> 0 | BB12: =BC$3*BC$4*216*24*60*BA12/9000000 -> 0 | BE12: =BF$3*BF$4*216*24*60*BD12/9000000 -> 0 | BH12: =BI$3*BI$4*216*24*60*BG12/9000000 -> 0 | BK12: =BL$3*BL$4*216*24*60*BJ12/9000000 -> 0 | BN12: =BO$3*BO$4*216*24*60*BM12/9000000 -> 0 | BQ12: =BR$3*BR$4*216*24*60*BP12/9000000 -> 0 | BT12: =BU$3*BU$4*216*24*60*BS12/9000000 -> 0 | BW12: =BX$3*BX$4*216*24*60*BV12/9000000 -> 0 | BZ12: =CA$3*CA$4*216*24*60*BY12/9000000 -> 0 | CC12: =CD$3*CD$4*216*24*60*CB12/9000000 -> 0 | CF12: =CG$3*CG$4*216*24*60*CE12/9000000 -> 0 | CI12: =CJ$3*CJ$4*216*24*60*CH12/9000000 -> 0 | CL12: =CM$3*CM$4*216*24*60*CK12/9000000 -> 0 | CO12: =CP$3*CP$4*216*24*60*CN12/9000000 -> 0 | CR12: =CS$3*CS$4*216*24*60*CQ12/9000000 -> 0 | CU12: =CV$3*CV$4*216*24*60*CT12/9000000 -> 0 | CX12: =CY$3*CY$4*216*24*60*CW12/9000000 -> 0 | DA12: =DB$3*DB$4*216*24*60*CZ12/9000000 -> 0 | DD12: =DE$3*DE$4*216*24*60*DC12/9000000 -> 0 | DG12: =DH$3*DH$4*216*24*60*DF12/9000000 -> 0 | DJ12: =DK$3*DK$4*216*24*60*DI12/9000000 -> 0 | DM12: =DN$3*DN$4*216*24*60*DL12/9000000 -> 0 | DP12: =DQ$3*DQ$4*216*24*60*DO12/9000000 -> 0 | DS12: =DT$3*DT$4*216*24*60*DR12/9000000 -> 0 | DV12: =DW$3*DW$4*216*24*60*DU12/9000000 -> 0 | DY12: =DZ$3*DZ$4*216*24*60*DX12/9000000 -> 0 | EB12: =EC$3*EC$4*216*24*60*EA12/9000000 -> 0 | EE12: =EF$3*EF$4*216*24*60*ED12/9000000 -> 0 | EH12: =EI$3*EI$4*216*24*60*EG12/9000000 -> 0 | EK12: =EL$3*EL$4*216*24*60*EJ12/9000000 -> 0 | EN12: =EO$3*EO$4*216*24*60*EM12/9000000 -> 0 | EQ12: =ER$3*ER$4*216*24*60*EP12/9000000 -> 0 | ET12: =EU$3*EU$4*216*24*60*ES12/9000000 -> 0 | EW12: =EX$3*EX$4*216*24*60*EV12/9000000 -> 0 | EZ12: =FA$3*FA$4*216*24*60*EY12/9000000 -> 0 | FC12: =FD$3*FD$4*216*24*60*FB12/9000000 -> 0 | FF12: =FG$3*FG$4*216*24*60*FE12/9000000 -> 0 | FI12: =FJ$3*FJ$4*216*24*60*FH12/9000000 -> 0 | FL12: =FM$3*FM$4*216*24*60*FK12/9000000 -> 0 | FO12: =FP$3*FP$4*216*24*60*FN12/9000000 -> 0 | FR12: =FS$3*FS$4*216*24*60*FQ12/9000000 -> 0 | FU12: =FV$3*FV$4*216*24*60*FT12/9000000 -> 0 | FX12: =FY$3*FY$4*216*24*60*FW12/9000000 -> 0 | GA12: =GB$3*GB$4*216*24*60*FZ12/9000000 -> 0 | GD12: =GE$3*GE$4*216*24*60*GC12/9000000 -> 0 | GG12: =GH$3*GH$4*216*24*60*GF12/9000000 -> 0 | GJ12: =GK$3*GK$4*216*24*60*GI12/9000000 -> 0 | GL12: =AC12+Z12+W12+T12+Q12+N12+K12+H12+E12+B12+AF12+AI12+AL12+AO12+AR12+AU12+AX12+BA12+BD12+BG12+BJ12+BM12+BP12+BS12+BV12+BY12+CB12+CE12+CH12+CK12+CN12+CQ12+CT12+CW12+CZ12+DC12+DL12+DF12+DI12+DO12+DR12+DU12+DX12+EA12+ED12+EG12+EJ12+EM12+EP12+ES12+EV12+EY12+FB12+FE12+FH12+FK12+FN12+FQ12+FT12+FW12+FZ12+GC12+GF12+GI12 -> 6 | GM12: =GL12+'33J'!BK12+'M80(20250122封存)'!CX12+MPS!AY12+TMT!CX12 -> 12.5
